Workbook
Name Print_Titles: Ввод!$4:$5
Name БазоваяПапка: Справочники!$N$1

Sheet Ввод
A2: Дата отчёта: | C2: 46280
E4: ПОРТФЕЛЬ | G4: ПРОСРОЧКА | K4: ДОЗВОНИЛИСЬ / ОБЕЩАЛИ | Q4: НЕ ДОЗВОНИЛИСЬ / ОБЪЕЗД | Y4: ОПЛАЧЕНО ОБЩЕЕ ЗА ДЕНЬ | AA4: ЭФФЕКТИВНОСТЬ И НАГРУЗКА
A5: № | B5: Область | C5: Ответственный | D5: Сотруд- ников | E5: Портфель, сум | F5: Портфель, шт | G5: Просрочка, сум | H5: Просрочка, шт | I5: % к портфелю | J5: % к кол-ву | K5: Дозвон, сум | L5: Дозвон, шт | M5: Обещали, сум | N5: Обещали, шт | O5: Оплатил, сум | P5: Оплатил, шт | Q5: Не дозв., сум | R5: Не дозв., шт | S5: Объезд: обещал, сум | T5: Объезд: обещал, шт | U5: Объезд: оплатил, сум | V5: Объезд: оплатил, шт | W5: Оплатил, сум | X5: Оплатил, шт | Y5: Оплачено, сум | Z5: Оплачено, шт | AA5: % дозвона (шт) | AB5: % обещаний (от дозвона) | AC5: Просрочка на 1 сотр. | AD5: Дозвон на 1 сотр. | AG5: служ. (для сортировки)
A6: 1 | B6: АНДИЖОН ВИЛОЯТИ | C6: =IFERROR(INDEX(Справочники!$D$4:$D$21,MATCH($B6,Справочники!$B$4:$B$21,0)),"") | D6: =SUMIF(Справочники!$H$4:$H$21,$B6,Справочники!$E$4:$E$21) -> 0 | E6: 2.1670184e+10 | F6: 445 | G6: =$K6+$Q6 -> 2.1699731e+08 | H6: =$L6+$R6 -> 32 | I6: =IFERROR($G6/$E6,"") -> 0.010013635 | J6: =IFERROR($H6/$F6,"") -> 0.071910112 | K6: 0 | L6: 0 | M6: 0 | N6: 0 | O6: 0 | P6: 0 | Q6: 5.4204674e+08 | R6: 126 | S6: 0 | T6: 0 | U6: 0 | V6: 0 | W6: 0 | X6: 0 | Y6: 0 | Z6: 0 | AA6: =IFERROR($L6/$H6,"") -> 0 | AB6: =IFERROR($N6/$L6,"") | AC6: =IFERROR($H6/$D6,"") | AD6: =IFERROR($L6/$D6,"") | AG6: =IFERROR($AA6,0)+ROW()/1000000 -> 6e-06
A7: 2 | B7: БУХОРО ВИЛОЯТИ | C7: =IFERROR(INDEX(Справочники!$D$4:$D$21,MATCH($B7,Справочники!$B$4:$B$21,0)),"") | D7: =SUMIF(Справочники!$H$4:$H$21,$B7,Справочники!$E$4:$E$21) -> 0 | E7: 5.1231734e+09 | F7: 167 | G7: =$K7+$Q7 -> 2.0266951e+08 | H7: =$L7+$R7 -> 18 | I7: =IFERROR($G7/$E7,"") -> 0.03955937 | J7: =IFERROR($H7/$F7,"") -> 0.10778443 | K7: 95285619 | L7: 39 | M7: 70433470 | N7: 31 | O7: 24852149 | P7: 8 | Q7: 1.7555188e+08 | R7: 13 | S7: 5579415.3 | T7: 3 | U7: 2968080.1 | V7: 1 | W7: 0 | X7: 0 | Y7: 27820230 | Z7: 9 | AA7: =IFERROR($L7/$H7,"") -> 0 | AB7: =IFERROR($N7/$L7,"") | AC7: =IFERROR($H7/$D7,"") | AD7: =IFERROR($L7/$D7,"") | AG7: =IFERROR($AA7,0)+ROW()/1000000 -> 7e-06
A8: 3 | B8: ЖИЗЗАХ ВИЛОЯТИ | C8: =IFERROR(INDEX(Справочники!$D$4:$D$21,MATCH($B8,Справочники!$B$4:$B$21,0)),"") | D8: =SUMIF(Справочники!$H$4:$H$21,$B8,Справочники!$E$4:$E$21) -> 0 | E8: 1.3904205e+10 | F8: 493 | G8: =$K8+$Q8 -> 2.498528e+08 | H8: =$L8+$R8 -> 51 | I8: =IFERROR($G8/$E8,"") -> 0.017969585 | J8: =IFERROR($H8/$F8,"") -> 0.10344828 | K8: 1.7985286e+08 | L8: 54 | M8: 1.4792243e+08 | N8: 39 | O8: 31930431 | P8: 15 | Q8: 1.8132605e+08 | R8: 44 | S8: 38493366 | T8: 7 | U8: 6829564.9 | V8: 1 | W8: 0 | X8: 0 | Y8: 38759996 | Z8: 16 | AA8: =IFERROR($L8/$H8,"") -> 0.39215686 | AB8: =IFERROR($N8/$L8,"") -> 0.95 | AC8: =IFERROR($H8/$D8,"") | AD8: =IFERROR($L8/$D8,"") | AG8: =IFERROR($AA8,0)+ROW()/1000000 -> 0.39216486
A9: 4 | B9: КАШКАДАРЁ ВИЛОЯТИ | C9: =IFERROR(INDEX(Справочники!$D$4:$D$21,MATCH($B9,Справочники!$B$4:$B$21,0)),"") | D9: =SUMIF(Справочники!$H$4:$H$21,$B9,Справочники!$E$4:$E$21) -> 0 | E9: 1.2186569e+10 | F9: 418 | G9: =$K9+$Q9 -> 2.0555796e+08 | H9: =$L9+$R9 -> 33 | I9: =IFERROR($G9/$E9,"") -> 0.016867583 | J9: =IFERROR($H9/$F9,"") -> 0.078947368 | K9: 1.1066281e+08 | L9: 30 | M9: 99913911 | N9: 25 | O9: 4598852.4 | P9: 4 | Q9: 3.1010541e+08 | R9: 91 | S9: 43293472 | T9: 13 | U9: 8357865.7 | V9: 4 | W9: 0 | X9: 0 | Y9: 12956718 | Z9: 8 | AA9: =IFERROR($L9/$H9,"") -> 0.87878788 | AB9: =IFERROR($N9/$L9,"") -> 0.62068966 | AC9: =IFERROR($H9/$D9,"") | AD9: =IFERROR($L9/$D9,"") | AG9: =IFERROR($AA9,0)+ROW()/1000000 -> 0.87879688
A10: 5 | B10: КОРАКАЛПОГИСТОН РЕСПУБЛИКАСИ | C10: =IFERROR(INDEX(Справочники!$D$4:$D$21,MATCH($B10,Справочники!$B$4:$B$21,0)),"") | D10: =SUMIF(Справочники!$H$4:$H$21,$B10,Справочники!$E$4:$E$21) -> 0 | E10: 1.1119545e+10 | F10: 269 | G10: =$K10+$Q10 -> 2.5963958e+08 | H10: =$L10+$R10 -> 26 | I10: =IFERROR($G10/$E10,"") -> 0.023349839 | J10: =IFERROR($H10/$F10,"") -> 0.096654275 | K10: 1.6080593e+08 | L10: 41 | M10: 1.0925662e+08 | N10: 27 | O10: 12226022 | P10: 4 | Q10: 1.4325956e+08 | R10: 25 | S10: 98869394 | T10: 14 | U10: 0 | V10: 0 | W10: 0 | X10: 0 | Y10: 12226022 | Z10: 4 | AA10: =IFERROR($L10/$H10,"") -> 0.76923077 | AB10: =IFERROR($N10/$L10,"") -> 0.2 | AC10: =IFERROR($H10/$D10,"") | AD10: =IFERROR($L10/$D10,"") | AG10: =IFERROR($AA10,0)+ROW()/1000000 -> 0.76924077
A11: 6 | B11: НАВОИЙ ВИЛОЯТИ | C11: =IFERROR(INDEX(Справочники!$D$4:$D$21,MATCH($B11,Справочники!$B$4:$B$21,0)),"") | D11: =SUMIF(Справочники!$H$4:$H$21,$B11,Справочники!$E$4:$E$21) -> 0 | E11: 6.476845e+09 | F11: 209 | G11: =$K11+$Q11 -> 1.0708535e+08 | H11: =$L11+$R11 -> 18 | I11: =IFERROR($G11/$E11,"") -> 0.016533567 | J11: =IFERROR($H11/$F11,"") -> 0.086124402 | K11: 56491064 | L11: 14 | M11: 18594377 | N11: 4 | O11: 21230024 | P11: 6 | Q11: 1.8946783e+08 | R11: 54 | S11: 0 | T11: 0 | U11: 0 | V11: 0 | W11: 0 | X11: 0 | Y11: 21230024 | Z11: 6 | AA11: =IFERROR($L11/$H11,"") -> 0.055555556 | AB11: =IFERROR($N11/$L11,"") -> 1 | AC11: =IFERROR($H11/$D11,"") | AD11: =IFERROR($L11/$D11,"") | AG11: =IFERROR($AA11,0)+ROW()/1000000 -> 0.055566556
A12: 7 | B12: НАМАНГАН ВИЛОЯТИ | C12: =IFERROR(INDEX(Справочники!$D$4:$D$21,MATCH($B12,Справочники!$B$4:$B$21,0)),"") | D12: =SUMIF(Справочники!$H$4:$H$21,$B12,Справочники!$E$4:$E$21) -> 0 | E12: 1.4729616e+10 | F12: 438 | G12: =$K12+$Q12 -> 5.9799851e+08 | H12: =$L12+$R12 -> 62 | I12: =IFERROR($G12/$E12,"") -> 0.040598377 | J12: =IFERROR($H12/$F12,"") -> 0.14155251 | K12: 3.3091676e+08 | L12: 57 | M12: 19229763 | N12: 9 | O12: 1832838.7 | P12: 1 | Q12: 6.2396477e+08 | R12: 104 | S12: 22291379 | T12: 7 | U12: 0 | V12: 0 | W12: 0 | X12: 0 | Y12: 1832838.7 | Z12: 1 | AA12: =IFERROR($L12/$H12,"") -> 0.48387097 | AB12: =IFERROR($N12/$L12,"") -> 1 | AC12: =IFERROR($H12/$D12,"") | AD12: =IFERROR($L12/$D12,"") | AG12: =IFERROR($AA12,0)+ROW()/1000000 -> 0.48388297
A13: 8 | B13: САМАРКАНД ВИЛОЯТИ | C13: =IFERROR(INDEX(Справочники!$D$4:$D$21,MATCH($B13,Справочники!$B$4:$B$21,0)),"") | D13: =SUMIF(Справочники!$H$4:$H$21,$B13,Справочники!$E$4:$E$21) -> 0 | E13: 1.6007859e+10 | F13: 549 | G13: =$K13+$Q13 -> 2.6721243e+08 | H13: =$L13+$R13 -> 61 | I13: =IFERROR($G13/$E13,"") -> 0.016692577 | J13: =IFERROR($H13/$F13,"") -> 0.11111111 | K13: 75847567 | L13: 26 | M13: 66850720 | N13: 20 | O13: 5817515.7 | P13: 5 | Q13: 5.2037017e+08 | R13: 134 | S13: 28936132 | T13: 12 | U13: 18691648 | V13: 7 | W13: 0 | X13: 0 | Y13: 24509164 | Z13: 12 | AA13: =IFERROR($L13/$H13,"") -> 0.24590164 | AB13: =IFERROR($N13/$L13,"") -> 1 | AC13: =IFERROR($H13/$D13,"") | AD13: =IFERROR($L13/$D13,"") | AG13: =IFERROR($AA13,0)+ROW()/1000000 -> 0.24591464
A14: 9 | B14: СИРДАРЁ ВИЛОЯТИ | C14: =IFERROR(INDEX(Справочники!$D$4:$D$21,MATCH($B14,Справочники!$B$4:$B$21,0)),"") | D14: =SUMIF(Справочники!$H$4:$H$21,$B14,Справочники!$E$4:$E$21) -> 0 | E14: 7.1897605e+09 | F14: 151 | G14: =$K14+$Q14 -> 97690450 | H14: =$L14+$R14 -> 17 | I14: =IFERROR($G14/$E14,"") -> 0.013587441 | J14: =IFERROR($H14/$F14,"") -> 0.11258278 | K14: 0 | L14: 0 | M14: 0 | N14: 0 | O14: 0 | P14: 0 | Q14: 2.0944622e+08 | R14: 51 | S14: 0 | T14: 0 | U14: 0 | V14: 0 | W14: 0 | X14: 0 | Y14: 0 | Z14: 0 | AA14: =IFERROR($L14/$H14,"") -> 0.58823529 | AB14: =IFERROR($N14/$L14,"") -> 0.1 | AC14: =IFERROR($H14/$D14,"") | AD14: =IFERROR($L14/$D14,"") | AG14: =IFERROR($AA14,0)+ROW()/1000000 -> 0.58824929
A15: 10 | B15: СУРХОНДАРЁ ВИЛОЯТИ | C15: =IFERROR(INDEX(Справочники!$D$4:$D$21,MATCH($B15,Справочники!$B$4:$B$21,0)),"") | D15: =SUMIF(Справочники!$H$4:$H$21,$B15,Справочники!$E$4:$E$21) -> 0 | E15: 1.6585229e+10 | F15: 558 | G15: =$K15+$Q15 -> 1.0837511e+09 | H15: =$L15+$R15 -> 97 | I15: =IFERROR($G15/$E15,"") -> 0.065344354 | J15: =IFERROR($H15/$F15,"") -> 0.17383513 | K15: 1.3909364e+08 | L15: 44 | M15: 1.3907186e+08 | N15: 43 | O15: 21786.19 | P15: 1 | Q15: 1.3763867e+09 | R15: 187 | S15: 14102688 | T15: 8 | U15: 6495805.8 | V15: 3 | W15: 0 | X15: 0 | Y15: 6517592 | Z15: 4 | AA15: =IFERROR($L15/$H15,"") -> 0.18556701 | AB15: =IFERROR($N15/$L15,"") -> 0.11111111 | AC15: =IFERROR($H15/$D15,"") | AD15: =IFERROR($L15/$D15,"") | AG15: =IFERROR($AA15,0)+ROW()/1000000 -> 0.18558201
A16: 11 | B16: ТОШКЕНТ ВИЛОЯТИ | C16: =IFERROR(INDEX(Справочники!$D$4:$D$21,MATCH($B16,Справочники!$B$4:$B$21,0)),"") | D16: =SUMIF(Справочники!$H$4:$H$21,$B16,Справочники!$E$4:$E$21) -> 0 | E16: 3.6871387e+10 | F16: 842 | G16: =$K16+$Q16 -> 8.8698663e+08 | H16: =$L16+$R16 -> 93 | I16: =IFERROR($G16/$E16,"") -> 0.024056232 | J16: =IFERROR($H16/$F16,"") -> 0.11045131 | K16: 0 | L16: 0 | M16: 0 | N16: 0 | O16: 0 | P16: 0 | Q16: 1.3924235e+09 | R16: 245 | S16: 0 | T16: 0 | U16: 0 | V16: 0 | W16: 0 | X16: 0 | Y16: 0 | Z16: 0 | AA16: =IFERROR($L16/$H16,"") -> 0 | AB16: =IFERROR($N16/$L16,"") | AC16: =IFERROR($H16/$D16,"") | AD16: =IFERROR($L16/$D16,"") | AG16: =IFERROR($AA16,0)+ROW()/1000000 -> 1.6e-05
A17: 12 | B17: ТОШКЕНТ ШАХРИ | C17: =IFERROR(INDEX(Справочники!$D$4:$D$21,MATCH($B17,Справочники!$B$4:$B$21,0)),"") | D17: =SUMIF(Справочники!$H$4:$H$21,$B17,Справочники!$E$4:$E$21) -> 0 | E17: 4.3531855e+10 | F17: 908 | G17: =$K17+$Q17 -> 1.6257267e+09 | H17: =$L17+$R17 -> 115 | I17: =IFERROR($G17/$E17,"") -> 0.037345679 | J17: =IFERROR($H17/$F17,"") -> 0.12665198 | K17: 58642688 | L17: 14 | M17: 56137552 | N17: 13 | O17: 2505136.5 | P17: 1 | Q17: 1.7336808e+09 | R17: 214 | S17: 97012424 | T17: 10 | U17: 14652137 | V17: 5 | W17: 0 | X17: 0 | Y17: 17157273 | Z17: 6 | AA17: =IFERROR($L17/$H17,"") -> 0 | AB17: =IFERROR($N17/$L17,"") | AC17: =IFERROR($H17/$D17,"") | AD17: =IFERROR($L17/$D17,"") | AG17: =IFERROR($AA17,0)+ROW()/1000000 -> 1.7e-05
... A19: 14 | B19: ХОРАЗМ ВИЛОЯТИ | C19: =IFERROR(INDEX(Справочники!$D$4:$D$21,MATCH($B19,Справочники!$B$4:$B$21,0)),"") | D19: =SUMIF(Справочники!$H$4:$H$21,$B19,Справочники!$E$4:$E$21) -> 0 | E19: 2.0499096e+10 | F19: 504 | G19: =$K19+$Q19 -> 2.9345986e+08 | H19: =$L19+$R19 -> 49 | I19: =IFERROR($G19/$E19,"") -> 0.014315746 | J19: =IFERROR($H19/$F19,"") -> 0.097222222 | K19: 1.6805918e+08 | L19: 50 | M19: 1.4938058e+08 | N19: 44 | O19: 17082325 | P19: 5 | Q19: 4.6508188e+08 | R19: 95 | S19: 27724170 | T19: 7 | U19: 0 | V19: 0 | W19: 0 | X19: 0 | Y19: 17082325 | Z19: 5 | AA19: =IFERROR($L19/$H19,"") -> 0.46938776 | AB19: =IFERROR($N19/$L19,"") -> 0.26086957 | AC19: =IFERROR($H19/$D19,"") | AD19: =IFERROR($L19/$D19,"") | AG19: =IFERROR($AA19,0)+ROW()/1000000 -> 0.46940676
B20: ИТОГО | D20: =SUM(D6:D19) -> 0 | E20: =SUM(E6:E19) -> 2.4329876e+11 | F20: =SUM(F6:F19) -> 6312 | G20: =SUM(G6:G19) -> 6.9014395e+09 | H20: =SUM(H6:H19) -> 725 | I20: =IFERROR($G20/$E20,"") -> 0.02836611 | J20: =IFERROR($H20/$F20,"") -> 0.11486058 | K20: =SUM(K6:K19) -> 1.1882477e+09 | L20: =SUM(L6:L19) -> 166 | M20: =SUM(M6:M19) -> 7.4828599e+08 | N20: =SUM(N6:N19) -> 96 | O20: =SUM(O6:O19) -> 0 | P20: =SUM(P6:P19) -> 0 | Q20: =SUM(Q6:Q19) -> 5.7131919e+09 | R20: =SUM(R6:R19) -> 559 | ... Z20: =SUM(Z6:Z19) -> 28 | AA20: =IFERROR($L20/$H20,"") -> 0.22896552 | AB20: =IFERROR($N20/$L20,"") -> 0.57831325 | AC20: =IFERROR($H20/$D20,"") | AD20: =IFERROR($L20/$D20,"")
B23: ОТКРЫТЬ СПИСОК КЛИЕНТОВ
B24: Область | C24: Дозв. | D24: Обещ. | E24: Опл. | F24: Не дозв. | G24: Объезд | H24: Опл. без разг. | I24: Всего
B25: АНДИЖОН ВИЛОЯТИ | F25: ▸
B26: БУХОРО ВИЛОЯТИ | C26: ▸ | D26: ▸ | E26: ▸ | F26: ▸ | G26: ▸ | I26: ▸
B27: ЖИЗЗАХ ВИЛОЯТИ | C27: ▸ | D27: ▸ | E27: ▸ | F27: ▸ | G27: ▸ | I27: ▸
B28: КАШКАДАРЁ ВИЛОЯТИ | C28: ▸ | D28: ▸ | E28: ▸ | F28: ▸ | G28: ▸ | I28: ▸
B29: КОРАКАЛПОГИСТОН РЕСПУБЛИКАСИ | C29: ▸ | D29: ▸ | E29: ▸ | F29: ▸ | G29: ▸ | I29: ▸
B30: НАВОИЙ ВИЛОЯТИ | C30: ▸ | D30: ▸ | E30: ▸ | F30: ▸ | I30: ▸
B31: НАМАНГАН ВИЛОЯТИ | C31: ▸ | D31: ▸ | E31: ▸ | F31: ▸ | G31: ▸ | I31: ▸
B32: САМАРКАНД ВИЛОЯТИ | C32: ▸ | D32: ▸ | E32: ▸ | F32: ▸ | G32: ▸ | I32: ▸
B33: СИРДАРЁ ВИЛОЯТИ | F33: ▸
B34: СУРХОНДАРЁ ВИЛОЯТИ | C34: ▸ | D34: ▸ | E34: ▸ | F34: ▸ | G34: ▸ | I34: ▸
B35: ТОШКЕНТ ВИЛОЯТИ | F35: ▸
B36: ТОШКЕНТ ШАХРИ | C36: ▸ | D36: ▸ | E36: ▸ | F36: ▸ | G36: ▸ | I36: ▸
B37: ФАРГОНА ВИЛОЯТИ | C37: ▸ | D37: ▸ | E37: ▸ | F37: ▸ | G37: ▸ | I37: ▸
B38: ХОРАЗМ ВИЛОЯТИ | C38: ▸ | D38: ▸ | E38: ▸ | F38: ▸ | G38: ▸ | I38: ▸

Sheet Отчёт_дня
A3: Дата отчёта: | C3: =Ввод!$C$2 -> 46272
A6: 1. ПОКАЗАТЕЛИ ДНЯ
A7: Портфель, сум | D7: =Ввод!$E$20 -> 2.4329876e+11
A8: Просрочка, сум | D8: =Ввод!$G$20 -> 6.9014395e+09
A9: % просрочки к портфелю | D9: =Ввод!$I$20 -> 0.02836611
A10: Просрочка, шт | D10: =Ввод!$H$20 -> 725
A11: Дозвонились, шт | D11: =Ввод!$L$20 -> 166
A12: % дозвона | D12: =Ввод!$AA$20 -> 0.22896552
A13: Обещали оплату, шт | D13: =Ввод!$N$20 -> 96
A14: Не дозвонились, шт | D14: =Ввод!$R$20 -> 559
A15: Объезд, шт | D15: =Ввод!$T$20 -> 2
A16: Оплачено за день, сум | D16: =Ввод!$Y$20 -> 0
A19: 2. ДЕТАЛИЗАЦИЯ ПО ОБЛАСТЯМ
A21: Область | B21: Ответственный | C21: Сотруд- ников | D21: % дозвона | E21: Просрочка на 1 сотр. | F21: Оплачено, сум | G21: Оценка
A22: =Ввод!$B$6 -> АНДИЖОН ВИЛОЯТИ | B22: =Ввод!$C$6 | C22: =Ввод!$D$6 -> 0 | D22: =IFERROR(Ввод!$AA$6,0) -> 0 | E22: =IFERROR(Ввод!$AC$6,0) | F22: =Ввод!$Y$6 -> 0 | G22: =IF(Ввод!$H$6=0,"Нет данных",IF($D22>=0.8,"Отлично",IF($D22>=0.5,"Хорошо","Требует внимания"))) -> Требует внимания
A23: =Ввод!$B$7 -> БУХОРО ВИЛОЯТИ | B23: =Ввод!$C$7 | C23: =Ввод!$D$7 -> 0 | D23: =IFERROR(Ввод!$AA$7,0) -> 0 | E23: =IFERROR(Ввод!$AC$7,0) | F23: =Ввод!$Y$7 -> 0 | G23: =IF(Ввод!$H$7=0,"Нет данных",IF($D23>=0.8,"Отлично",IF($D23>=0.5,"Хорошо","Требует внимания"))) -> Требует внимания
A24: =Ввод!$B$8 -> ЖИЗЗАХ ВИЛОЯТИ | B24: =Ввод!$C$8 | C24: =Ввод!$D$8 -> 0 | D24: =IFERROR(Ввод!$AA$8,0) -> 0.39215686 | E24: =IFERROR(Ввод!$AC$8,0) | F24: =Ввод!$Y$8 -> 0 | G24: =IF(Ввод!$H$8=0,"Нет данных",IF($D24>=0.8,"Отлично",IF($D24>=0.5,"Хорошо","Требует внимания"))) -> Требует внимания
A25: =Ввод!$B$9 -> КАШКАДАРЁ ВИЛОЯТИ | B25: =Ввод!$C$9 | C25: =Ввод!$D$9 -> 0 | D25: =IFERROR(Ввод!$AA$9,0) -> 0.87878788 | E25: =IFERROR(Ввод!$AC$9,0) | F25: =Ввод!$Y$9 -> 0 | G25: =IF(Ввод!$H$9=0,"Нет данных",IF($D25>=0.8,"Отлично",IF($D25>=0.5,"Хорошо","Требует внимания"))) -> Отлично
A26: =Ввод!$B$10 -> КОРАКАЛПОГИСТОН РЕСПУБЛИКАСИ | B26: =Ввод!$C$10 | C26: =Ввод!$D$10 -> 0 | D26: =IFERROR(Ввод!$AA$10,0) -> 0.76923077 | E26: =IFERROR(Ввод!$AC$10,0) | F26: =Ввод!$Y$10 -> 0 | G26: =IF(Ввод!$H$10=0,"Нет данных",IF($D26>=0.8,"Отлично",IF($D26>=0.5,"Хорошо","Требует внимания"))) -> Хорошо
A27: =Ввод!$B$11 -> НАВОИЙ ВИЛОЯТИ | B27: =Ввод!$C$11 | C27: =Ввод!$D$11 -> 0 | D27: =IFERROR(Ввод!$AA$11,0) -> 0.055555556 | E27: =IFERROR(Ввод!$AC$11,0) | F27: =Ввод!$Y$11 -> 0 | G27: =IF(Ввод!$H$11=0,"Нет данных",IF($D27>=0.8,"Отлично",IF($D27>=0.5,"Хорошо","Требует внимания"))) -> Требует внимания
A28: =Ввод!$B$12 -> НАМАНГАН ВИЛОЯТИ | B28: =Ввод!$C$12 | C28: =Ввод!$D$12 -> 0 | D28: =IFERROR(Ввод!$AA$12,0) -> 0.48387097 | E28: =IFERROR(Ввод!$AC$12,0) | F28: =Ввод!$Y$12 -> 0 | G28: =IF(Ввод!$H$12=0,"Нет данных",IF($D28>=0.8,"Отлично",IF($D28>=0.5,"Хорошо","Требует внимания"))) -> Требует внимания
A29: =Ввод!$B$13 -> САМАРКАНД ВИЛОЯТИ | B29: =Ввод!$C$13 | C29: =Ввод!$D$13 -> 0 | D29: =IFERROR(Ввод!$AA$13,0) -> 0.24590164 | E29: =IFERROR(Ввод!$AC$13,0) | F29: =Ввод!$Y$13 -> 0 | G29: =IF(Ввод!$H$13=0,"Нет данных",IF($D29>=0.8,"Отлично",IF($D29>=0.5,"Хорошо","Требует внимания"))) -> Требует внимания
A30: =Ввод!$B$14 -> СИРДАРЁ ВИЛОЯТИ | B30: =Ввод!$C$14 | C30: =Ввод!$D$14 -> 0 | D30: =IFERROR(Ввод!$AA$14,0) -> 0.58823529 | E30: =IFERROR(Ввод!$AC$14,0) | F30: =Ввод!$Y$14 -> 0 | G30: =IF(Ввод!$H$14=0,"Нет данных",IF($D30>=0.8,"Отлично",IF($D30>=0.5,"Хорошо","Требует внимания"))) -> Хорошо
A31: =Ввод!$B$15 -> СУРХОНДАРЁ ВИЛОЯТИ | B31: =Ввод!$C$15 | C31: =Ввод!$D$15 -> 0 | D31: =IFERROR(Ввод!$AA$15,0) -> 0.18556701 | E31: =IFERROR(Ввод!$AC$15,0) | F31: =Ввод!$Y$15 -> 0 | G31: =IF(Ввод!$H$15=0,"Нет данных",IF($D31>=0.8,"Отлично",IF($D31>=0.5,"Хорошо","Требует внимания"))) -> Требует внимания
A32: =Ввод!$B$16 -> ТОШКЕНТ ВИЛОЯТИ | B32: =Ввод!$C$16 | C32: =Ввод!$D$16 -> 0 | D32: =IFERROR(Ввод!$AA$16,0) -> 0 | E32: =IFERROR(Ввод!$AC$16,0) | F32: =Ввод!$Y$16 -> 0 | G32: =IF(Ввод!$H$16=0,"Нет данных",IF($D32>=0.8,"Отлично",IF($D32>=0.5,"Хорошо","Требует внимания"))) -> Требует внимания
A33: =Ввод!$B$17 -> ТОШКЕНТ ШАХРИ | B33: =Ввод!$C$17 | C33: =Ввод!$D$17 -> 0 | D33: =IFERROR(Ввод!$AA$17,0) -> 0 | E33: =IFERROR(Ввод!$AC$17,0) | F33: =Ввод!$Y$17 -> 0 | G33: =IF(Ввод!$H$17=0,"Нет данных",IF($D33>=0.8,"Отлично",IF($D33>=0.5,"Хорошо","Требует внимания"))) -> Требует внимания
A34: =Ввод!$B$18 -> ФАРГОНА ВИЛОЯТИ | B34: =Ввод!$C$18 | C34: =Ввод!$D$18 -> 0 | D34: =IFERROR(Ввод!$AA$18,0) -> 0 | E34: =IFERROR(Ввод!$AC$18,0) | F34: =Ввод!$Y$18 -> 0 | G34: =IF(Ввод!$H$18=0,"Нет данных",IF($D34>=0.8,"Отлично",IF($D34>=0.5,"Хорошо","Требует внимания"))) -> Требует внимания
A35: =Ввод!$B$19 -> ХОРАЗМ ВИЛОЯТИ | B35: =Ввод!$C$19 | C35: =Ввод!$D$19 -> 0 | D35: =IFERROR(Ввод!$AA$19,0) -> 0.46938776 | E35: =IFERROR(Ввод!$AC$19,0) | F35: =Ввод!$Y$19 -> 0 | G35: =IF(Ввод!$H$19=0,"Нет данных",IF($D35>=0.8,"Отлично",IF($D35>=0.5,"Хорошо","Требует внимания"))) -> Требует внимания
A41: 6. ЛИДЕРЫ И ОТСТАЮЩИЕ ПО % ДОЗВОНА (по областям)
A42: Лидеры | C42: % дозвона | E42: Требуют внимания | H42: % дозвона
A43: =IFERROR(INDEX(Ввод!$B$6:$B$19,MATCH(LARGE(Ввод!$AG$6:$AG$19,1),Ввод!$AG$6:$AG$19,0)),"") -> КАШКАДАРЁ ВИЛОЯТИ | C43: =IFERROR(INDEX(Ввод!$AA$6:$AA$19,MATCH(LARGE(Ввод!$AG$6:$AG$19,1),Ввод!$AG$6:$AG$19,0)),"") -> 0.87878788 | E43: =IFERROR(INDEX(Ввод!$B$6:$B$19,MATCH(SMALL(Ввод!$AG$6:$AG$19,1),Ввод!$AG$6:$AG$19,0)),"") -> АНДИЖОН ВИЛОЯТИ | H43: =IFERROR(INDEX(Ввод!$AA$6:$AA$19,MATCH(SMALL(Ввод!$AG$6:$AG$19,1),Ввод!$AG$6:$AG$19,0)),"") -> 0
A44: =IFERROR(INDEX(Ввод!$B$6:$B$19,MATCH(LARGE(Ввод!$AG$6:$AG$19,2),Ввод!$AG$6:$AG$19,0)),"") -> КОРАКАЛПОГИСТОН РЕСПУБЛИКАСИ | C44: =IFERROR(INDEX(Ввод!$AA$6:$AA$19,MATCH(LARGE(Ввод!$AG$6:$AG$19,2),Ввод!$AG$6:$AG$19,0)),"") -> 0.76923077 | E44: =IFERROR(INDEX(Ввод!$B$6:$B$19,MATCH(SMALL(Ввод!$AG$6:$AG$19,2),Ввод!$AG$6:$AG$19,0)),"") -> БУХОРО ВИЛОЯТИ | H44: =IFERROR(INDEX(Ввод!$AA$6:$AA$19,MATCH(SMALL(Ввод!$AG$6:$AG$19,2),Ввод!$AG$6:$AG$19,0)),"") -> 0
A45: =IFERROR(INDEX(Ввод!$B$6:$B$19,MATCH(LARGE(Ввод!$AG$6:$AG$19,3),Ввод!$AG$6:$AG$19,0)),"") -> СИРДАРЁ ВИЛОЯТИ | C45: =IFERROR(INDEX(Ввод!$AA$6:$AA$19,MATCH(LARGE(Ввод!$AG$6:$AG$19,3),Ввод!$AG$6:$AG$19,0)),"") -> 0.58823529 | E45: =IFERROR(INDEX(Ввод!$B$6:$B$19,MATCH(SMALL(Ввод!$AG$6:$AG$19,3),Ввод!$AG$6:$AG$19,0)),"") -> ТОШКЕНТ ВИЛОЯТИ | H45: =IFERROR(INDEX(Ввод!$AA$6:$AA$19,MATCH(SMALL(Ввод!$AG$6:$AG$19,3),Ввод!$AG$6:$AG$19,0)),"") -> 0

Sheet Дашборд
A3: Дата отчёта: | C3: =Ввод!$C$2 -> 46272 | E3: Просрочка, сум | H3: =Ввод!$G$20 -> 6.9014395e+09
E4: Оплачено за день, сум | H4: =Ввод!$Y$20 -> 0
E5: Просрочка на 1 сотрудника, шт | H5: =IFERROR(Ввод!$H$20/Ввод!$D$20,0) -> 0
A7: СВОД ПО ОБЛАСТЯМ
A8: Область | B8: Тип | C8: Сотруд- ников | D8: Портфель, сум | E8: Просрочка, сум | F8: % просрочки | G8: Просрочка, шт | H8: Дозвон, шт | I8: % дозвона | J8: Просрочка на 1 сотр. | K8: Обещали, шт | L8: Оплачено, сум | M8: Оценка | N8: Область
A9: =Ввод!$B$6 -> АНДИЖОН ВИЛОЯТИ | C9: =Ввод!$D$6 -> 0 | D9: =Ввод!$E$6 -> 2.1670184e+10 | E9: =Ввод!$G$6 -> 2.1699731e+08 | F9: =IFERROR($E9/$D9,0) -> 0.010013635 | G9: =Ввод!$H$6 -> 32 | H9: =Ввод!$L$6 -> 0 | I9: =IFERROR($H9/$G9,0) -> 0 | J9: =IFERROR($G9/$C9,0) -> 0 | K9: =Ввод!$N$6 -> 0 | L9: =Ввод!$Y$6 -> 0 | M9: =IF($G9=0,"Нет данных",IF($I9>=0.8,"Отлично",IF($I9>=0.5,"Хорошо","Требует внимания"))) -> Требует внимания | N9: =IFERROR(INDEX(Справочники!$H$4:$H$21,MATCH($A9,Справочники!$B$4:$B$21,0)),"")
A10: =Ввод!$B$7 -> БУХОРО ВИЛОЯТИ | C10: =Ввод!$D$7 -> 0 | D10: =Ввод!$E$7 -> 5.1231734e+09 | E10: =Ввод!$G$7 -> 2.0266951e+08 | F10: =IFERROR($E10/$D10,0) -> 0.03955937 | G10: =Ввод!$H$7 -> 18 | H10: =Ввод!$L$7 -> 0 | I10: =IFERROR($H10/$G10,0) -> 0 | J10: =IFERROR($G10/$C10,0) -> 0 | K10: =Ввод!$N$7 -> 0 | L10: =Ввод!$Y$7 -> 0 | M10: =IF($G10=0,"Нет данных",IF($I10>=0.8,"Отлично",IF($I10>=0.5,"Хорошо","Требует внимания"))) -> Требует внимания | N10: =IFERROR(INDEX(Справочники!$H$4:$H$21,MATCH($A10,Справочники!$B$4:$B$21,0)),"")
A11: =Ввод!$B$8 -> ЖИЗЗАХ ВИЛОЯТИ | C11: =Ввод!$D$8 -> 0 | D11: =Ввод!$E$8 -> 1.3904205e+10 | E11: =Ввод!$G$8 -> 2.498528e+08 | F11: =IFERROR($E11/$D11,0) -> 0.017969585 | G11: =Ввод!$H$8 -> 51 | H11: =Ввод!$L$8 -> 20 | I11: =IFERROR($H11/$G11,0) -> 0.39215686 | J11: =IFERROR($G11/$C11,0) -> 0 | K11: =Ввод!$N$8 -> 19 | L11: =Ввод!$Y$8 -> 0 | M11: =IF($G11=0,"Нет данных",IF($I11>=0.8,"Отлично",IF($I11>=0.5,"Хорошо","Требует внимания"))) -> Требует внимания | N11: =IFERROR(INDEX(Справочники!$H$4:$H$21,MATCH($A11,Справочники!$B$4:$B$21,0)),"")
A12: =Ввод!$B$9 -> КАШКАДАРЁ ВИЛОЯТИ | C12: =Ввод!$D$9 -> 0 | D12: =Ввод!$E$9 -> 1.2186569e+10 | E12: =Ввод!$G$9 -> 2.0555796e+08 | F12: =IFERROR($E12/$D12,0) -> 0.016867583 | G12: =Ввод!$H$9 -> 33 | H12: =Ввод!$L$9 -> 29 | I12: =IFERROR($H12/$G12,0) -> 0.87878788 | J12: =IFERROR($G12/$C12,0) -> 0 | K12: =Ввод!$N$9 -> 18 | L12: =Ввод!$Y$9 -> 0 | M12: =IF($G12=0,"Нет данных",IF($I12>=0.8,"Отлично",IF($I12>=0.5,"Хорошо","Требует внимания"))) -> Отлично | N12: =IFERROR(INDEX(Справочники!$H$4:$H$21,MATCH($A12,Справочники!$B$4:$B$21,0)),"")
A13: =Ввод!$B$10 -> КОРАКАЛПОГИСТОН РЕСПУБЛИКАСИ | C13: =Ввод!$D$10 -> 0 | D13: =Ввод!$E$10 -> 1.1119545e+10 | E13: =Ввод!$G$10 -> 2.5963958e+08 | F13: =IFERROR($E13/$D13,0) -> 0.023349839 | G13: =Ввод!$H$10 -> 26 | H13: =Ввод!$L$10 -> 20 | I13: =IFERROR($H13/$G13,0) -> 0.76923077 | J13: =IFERROR($G13/$C13,0) -> 0 | K13: =Ввод!$N$10 -> 4 | L13: =Ввод!$Y$10 -> 0 | M13: =IF($G13=0,"Нет данных",IF($I13>=0.8,"Отлично",IF($I13>=0.5,"Хорошо","Требует внимания"))) -> Хорошо | N13: =IFERROR(INDEX(Справочники!$H$4:$H$21,MATCH($A13,Справочники!$B$4:$B$21,0)),"")
A14: =Ввод!$B$11 -> НАВОИЙ ВИЛОЯТИ | C14: =Ввод!$D$11 -> 0 | D14: =Ввод!$E$11 -> 6.476845e+09 | E14: =Ввод!$G$11 -> 1.0708535e+08 | F14: =IFERROR($E14/$D14,0) -> 0.016533567 | G14: =Ввод!$H$11 -> 18 | H14: =Ввод!$L$11 -> 1 | I14: =IFERROR($H14/$G14,0) -> 0.055555556 | J14: =IFERROR($G14/$C14,0) -> 0 | K14: =Ввод!$N$11 -> 1 | L14: =Ввод!$Y$11 -> 0 | M14: =IF($G14=0,"Нет данных",IF($I14>=0.8,"Отлично",IF($I14>=0.5,"Хорошо","Требует внимания"))) -> Требует внимания | N14: =IFERROR(INDEX(Справочники!$H$4:$H$21,MATCH($A14,Справочники!$B$4:$B$21,0)),"")
A15: =Ввод!$B$12 -> НАМАНГАН ВИЛОЯТИ | C15: =Ввод!$D$12 -> 0 | D15: =Ввод!$E$12 -> 1.4729616e+10 | E15: =Ввод!$G$12 -> 5.9799851e+08 | F15: =IFERROR($E15/$D15,0) -> 0.040598377 | G15: =Ввод!$H$12 -> 62 | H15: =Ввод!$L$12 -> 30 | I15: =IFERROR($H15/$G15,0) -> 0.48387097 | J15: =IFERROR($G15/$C15,0) -> 0 | K15: =Ввод!$N$12 -> 30 | L15: =Ввод!$Y$12 -> 0 | M15: =IF($G15=0,"Нет данных",IF($I15>=0.8,"Отлично",IF($I15>=0.5,"Хорошо","Требует внимания"))) -> Требует внимания | N15: =IFERROR(INDEX(Справочники!$H$4:$H$21,MATCH($A15,Справочники!$B$4:$B$21,0)),"")
A16: =Ввод!$B$13 -> САМАРКАНД ВИЛОЯТИ | C16: =Ввод!$D$13 -> 0 | D16: =Ввод!$E$13 -> 1.6007859e+10 | E16: =Ввод!$G$13 -> 2.6721243e+08 | F16: =IFERROR($E16/$D16,0) -> 0.016692577 | G16: =Ввод!$H$13 -> 61 | H16: =Ввод!$L$13 -> 15 | I16: =IFERROR($H16/$G16,0) -> 0.24590164 | J16: =IFERROR($G16/$C16,0) -> 0 | K16: =Ввод!$N$13 -> 15 | L16: =Ввод!$Y$13 -> 0 | M16: =IF($G16=0,"Нет данных",IF($I16>=0.8,"Отлично",IF($I16>=0.5,"Хорошо","Требует внимания"))) -> Требует внимания | N16: =IFERROR(INDEX(Справочники!$H$4:$H$21,MATCH($A16,Справочники!$B$4:$B$21,0)),"")
A17: =Ввод!$B$14 -> СИРДАРЁ ВИЛОЯТИ | C17: =Ввод!$D$14 -> 0 | D17: =Ввод!$E$14 -> 7.1897605e+09 | E17: =Ввод!$G$14 -> 97690450 | F17: =IFERROR($E17/$D17,0) -> 0.013587441 | G17: =Ввод!$H$14 -> 17 | H17: =Ввод!$L$14 -> 10 | I17: =IFERROR($H17/$G17,0) -> 0.58823529 | J17: =IFERROR($G17/$C17,0) -> 0 | K17: =Ввод!$N$14 -> 1 | L17: =Ввод!$Y$14 -> 0 | M17: =IF($G17=0,"Нет данных",IF($I17>=0.8,"Отлично",IF($I17>=0.5,"Хорошо","Требует внимания"))) -> Хорошо | N17: =IFERROR(INDEX(Справочники!$H$4:$H$21,MATCH($A17,Справочники!$B$4:$B$21,0)),"")
A18: =Ввод!$B$15 -> СУРХОНДАРЁ ВИЛОЯТИ | C18: =Ввод!$D$15 -> 0 | D18: =Ввод!$E$15 -> 1.6585229e+10 | E18: =Ввод!$G$15 -> 1.0837511e+09 | F18: =IFERROR($E18/$D18,0) -> 0.065344354 | G18: =Ввод!$H$15 -> 97 | H18: =Ввод!$L$15 -> 18 | I18: =IFERROR($H18/$G18,0) -> 0.18556701 | J18: =IFERROR($G18/$C18,0) -> 0 | K18: =Ввод!$N$15 -> 2 | L18: =Ввод!$Y$15 -> 0 | M18: =IF($G18=0,"Нет данных",IF($I18>=0.8,"Отлично",IF($I18>=0.5,"Хорошо","Требует внимания"))) -> Требует внимания | N18: =IFERROR(INDEX(Справочники!$H$4:$H$21,MATCH($A18,Справочники!$B$4:$B$21,0)),"")
A19: =Ввод!$B$16 -> ТОШКЕНТ ВИЛОЯТИ | C19: =Ввод!$D$16 -> 0 | D19: =Ввод!$E$16 -> 3.6871387e+10 | E19: =Ввод!$G$16 -> 8.8698663e+08 | F19: =IFERROR($E19/$D19,0) -> 0.024056232 | G19: =Ввод!$H$16 -> 93 | H19: =Ввод!$L$16 -> 0 | I19: =IFERROR($H19/$G19,0) -> 0 | J19: =IFERROR($G19/$C19,0) -> 0 | K19: =Ввод!$N$16 -> 0 | L19: =Ввод!$Y$16 -> 0 | M19: =IF($G19=0,"Нет данных",IF($I19>=0.8,"Отлично",IF($I19>=0.5,"Хорошо","Требует внимания"))) -> Требует внимания | N19: =IFERROR(INDEX(Справочники!$H$4:$H$21,MATCH($A19,Справочники!$B$4:$B$21,0)),"")
A20: =Ввод!$B$17 -> ТОШКЕНТ ШАХРИ | C20: =Ввод!$D$17 -> 0 | D20: =Ввод!$E$17 -> 4.3531855e+10 | E20: =Ввод!$G$17 -> 1.6257267e+09 | F20: =IFERROR($E20/$D20,0) -> 0.037345679 | G20: =Ввод!$H$17 -> 115 | H20: =Ввод!$L$17 -> 0 | I20: =IFERROR($H20/$G20,0) -> 0 | J20: =IFERROR($G20/$C20,0) -> 0 | K20: =Ввод!$N$17 -> 0 | L20: =Ввод!$Y$17 -> 0 | M20: =IF($G20=0,"Нет данных",IF($I20>=0.8,"Отлично",IF($I20>=0.5,"Хорошо","Требует внимания"))) -> Требует внимания | N20: =IFERROR(INDEX(Справочники!$H$4:$H$21,MATCH($A20,Справочники!$B$4:$B$21,0)),"")
A21: =Ввод!$B$18 -> ФАРГОНА ВИЛОЯТИ | C21: =Ввод!$D$18 -> 0 | D21: =Ввод!$E$18 -> 1.7403439e+10 | E21: =Ввод!$G$18 -> 806811380 | F21: =IFERROR($E21/$D21,0) -> 0.046359308 | G21: =Ввод!$H$18 -> 53 | H21: =Ввод!$L$18 -> 0 | I21: =IFERROR($H21/$G21,0) -> 0 | J21: =IFERROR($G21/$C21,0) -> 0 | K21: =Ввод!$N$18 -> 0 | L21: =Ввод!$Y$18 -> 0 | M21: =IF($G21=0,"Нет данных",IF($I21>=0.8,"Отлично",IF($I21>=0.5,"Хорошо","Требует внимания"))) -> Требует внимания | N21: =IFERROR(INDEX(Справочники!$H$4:$H$21,MATCH($A21,Справочники!$B$4:$B$21,0)),"")
A22: =Ввод!$B$19 -> ХОРАЗМ ВИЛОЯТИ | C22: =Ввод!$D$19 -> 0 | D22: =Ввод!$E$19 -> 2.0499096e+10 | E22: =Ввод!$G$19 -> 2.9345986e+08 | F22: =IFERROR($E22/$D22,0) -> 0.014315746 | G22: =Ввод!$H$19 -> 49 | H22: =Ввод!$L$19 -> 23 | I22: =IFERROR($H22/$G22,0) -> 0.46938776 | J22: =IFERROR($G22/$C22,0) -> 0 | K22: =Ввод!$N$19 -> 6 | L22: =Ввод!$Y$19 -> 0 | M22: =IF($G22=0,"Нет данных",IF($I22>=0.8,"Отлично",IF($I22>=0.5,"Хорошо","Требует внимания"))) -> Требует внимания | N22: =IFERROR(INDEX(Справочники!$H$4:$H$21,MATCH($A22,Справочники!$B$4:$B$21,0)),"")
A27: ИТОГО | C27: =SUM(C9:C26) -> 0 | D27: =SUM(D9:D26) -> 2.4329876e+11 | E27: =SUM(E9:E26) -> 6.9014395e+09 | F27: =IFERROR($E27/$D27,0) -> 0.02836611 | G27: =SUM(G9:G26) -> 725 | H27: =SUM(H9:H26) -> 166 | I27: =IFERROR($H27/$G27,0) -> 0.22896552 | J27: =IFERROR($G27/$C27,0) -> 0 | K27: =SUM(K9:K26) -> 96 | L27: =SUM(L9:L26) -> 0 | M27: =IF($I27>=0.8,"Отлично",IF($I27>=0.5,"Хорошо","Требует внимания")) -> Требует внимания

Sheet Справочники
A3: № | B3: Филиал (точно как в файлах) | C3: Тип | D3: Ответственный (Ф.И.О.) | E3: Кол-во сотрудников | F3: Телефон | G3: Норматив % просрочки | H3: Область | K3: Оценка эффективности | N3: Статус проверки
A4: 1 | B4: Урганч филиали | C4: Регион | D4: — впишите — | E4: 0 | F4: +998 __ ___ __ __ | G4: 0.05 | H4: ХОРАЗМ ВИЛОЯТИ | K4: Отлично (≥80% дозвона) | N4: Не проверено
A5: 2 | B5: Самарқанд филиали | C5: Регион | D5: — впишите — | E5: 0 | F5: +998 __ ___ __ __ | G5: 0.05 | H5: САМАРКАНД ВИЛОЯТИ | K5: Хорошо (50–79%) | N5: Проверено куратором
A6: 3 | B6: Денов филиали | C6: Регион | D6: — впишите — | E6: 0 | F6: +998 __ ___ __ __ | G6: 0.05 | H6: СУРХОНДАРЁ ВИЛОЯТИ | K6: Требует внимания (<50%)
A7: 4 | B7: Жиззах филиали | C7: Регион | D7: — впишите — | E7: 0 | F7: +998 __ ___ __ __ | G7: 0.05 | H7: ЖИЗЗАХ ВИЛОЯТИ | K7: Нет данных
A8: 5 | B8: Андижон филиали | C8: Регион | D8: — впишите — | E8: 0 | F8: +998 __ ___ __ __ | G8: 0.05 | H8: АНДИЖОН ВИЛОЯТИ
A9: 6 | B9: Наманган филиали | C9: Регион | D9: — впишите — | E9: 0 | F9: +998 __ ___ __ __ | G9: 0.05 | H9: НАМАНГАН ВИЛОЯТИ
A10: 7 | B10: Фарғона филиали | C10: Регион | D10: — впишите — | E10: 0 | F10: +998 __ ___ __ __ | G10: 0.05 | H10: ФАРГОНА ВИЛОЯТИ
A11: 8 | B11: Қарши филиали | C11: Регион | D11: — впишите — | E11: 0 | F11: +998 __ ___ __ __ | G11: 0.05 | H11: КАШКАДАРЁ ВИЛОЯТИ
A12: 9 | B12: Нукус филиали | C12: Регион | D12: — впишите — | E12: 0 | F12: +998 __ ___ __ __ | G12: 0.05 | H12: КОРАКАЛПОГИСТОН РЕСПУБЛИКАСИ
A13: 10 | B13: Навоий филиали | C13: Регион | D13: — впишите — | E13: 0 | F13: +998 __ ___ __ __ | G13: 0.05 | H13: НАВОИЙ ВИЛОЯТИ
A14: 11 | B14: Бухоро филиали | C14: Регион | D14: — впишите — | E14: 0 | F14: +998 __ ___ __ __ | G14: 0.05 | H14: БУХОРО ВИЛОЯТИ
A15: 12 | B15: Термиз филиали | C15: Регион | D15: — впишите — | E15: 0 | F15: +998 __ ___ __ __ | G15: 0.05 | H15: СУРХОНДАРЁ ВИЛОЯТИ
A16: 13 | B16: Гулистон филиали | C16: Регион | D16: — впишите — | E16: 0 | F16: +998 __ ___ __ __ | G16: 0.05 | H16: СИРДАРЁ ВИЛОЯТИ
A17: 14 | B17: Олмалиқ филиали | C17: Регион | D17: — впишите — | E17: 0 | F17: +998 __ ___ __ __ | G17: 0.05 | H17: ТОШКЕНТ ВИЛОЯТИ
A18: 15 | B18: Чирчик филиали | C18: Регион | D18: — впишите — | E18: 0 | F18: +998 __ ___ __ __ | G18: 0.05 | H18: ТОШКЕНТ ВИЛОЯТИ
A19: 16 | B19: Янги Йул филиали | C19: Регион | D19: — впишите — | E19: 0 | F19: +998 __ ___ __ __ | G19: 0.05 | H19: ТОШКЕНТ ВИЛОЯТИ
... A21: 18 | B21: BOSH OFIS | C21: Центральное | D21: — впишите — | E21: 0 | F21: +998 __ ___ __ __ | G21: 0.05 | H21: ТОШКЕНТ ШАХРИ
B22: ИТОГО | E22: =SUM(E4:E21) -> 0

Sheet Дозвонились
A1: ← Вернуться в отчёт
A2: Область | B2: Филиал | C2: Группа | D2: Код клиента | E2: Клиент | F2: Номер телефона | G2: Адрес | H2: Кол-во просроченных дней | I2: Итого просрочка | J2: Оплата | K2: Izoh
A3: БУХОРО ВИЛОЯТИ | C3: Дозвон | D3: Кр-99063147-1 | E3: YUSUPOV TALGAT RAVILEVICH | F3: +998934589950 SMS O’ZI, 998504052350 SMS AYOLI, 998936202480 SMS QIZI, 998936560151 SMS ONASI, | G3: 5-СОН ГАФУР ГУЛОМ НОМЛИ МФЙ, ИФТИХОР КУЧАСИ, 32-UY | H3: 8 | I3: 8437576.4 | J3: 8437576.4 | K3: To'ladi
A4: БУХОРО ВИЛОЯТИ | C4: Дозвон | D4: Кр-99038186-1 | E4: SA’DULLAYEVA ROXILLA SADULLO QIZI | F4: 998933094290 SMS OZI, 998993803457 SMS QUDASI, 998990943457 SMS SINGLISI, | G4: BUXORO VILOYATI BUXORO TUMANI, QALQO QISHLOG'I, 4-MUYILISH, 8-UY | H4: 1 | I4: 7600197.6 | J4: 7600197.6 | K4: To'ladi
A5: БУХОРО ВИЛОЯТИ | C5: Обещал | D5: Кр-99036711-1 | E5: ERGASHOV ALISHER NARZULLAYEVICH | F5: 998934784464 SMS O’ZI, 998939569626 SMS OTASI, 998931571911 SMS ONASI, 998930052290 SMS SINGLISI , | G5: BUXORO VILOYATI, QORAKO'L TUMANI, ISTIQLOL MFY, YANGI QISHLOQ KO'CHASI, 15-UY | H5: 1 | I5: 5020948.3 | K5: Va'da berdi | ertaga anq tulaydi
A6: БУХОРО ВИЛОЯТИ | C6: Обещал | D6: Кр-99028153-4 | E6: GOIPOV EL’BRUS RAXMADOVICH | F6: 94-120-61-31 SMS OZI, 94-219-60-83 SMS AYOLI, 94-782-03-28 OGLI (бегана), 94-382-28-11 SMS QIZI, | G6: BUXORO VILOYATI OLOT TUMANI XIDREYLI MFY 141-UY | H6: 8 | I6: 4961647.2 | K6: Va'da berdi
A7: БУХОРО ВИЛОЯТИ | C7: Обещал | D7: Кр-99034426-1 | E7: AZIZOV ILXOM BAXTIYAROVICH | F7: 998905146560 SMS OZI, 998907121044 SMS AYOLI, 998938741010 SMS OTASI, 998936421010 SMS ONASI, 998936421010 толовчичи шодиёр, | G7: BUXORO VILOYATI BUXORO SHAHAR TOJIQARAYEV MFY 61-UY | H7: 1 | I7: 4692523.7 | K7: Va'da berdi | ertaga
A8: БУХОРО ВИЛОЯТИ | C8: Обещал | D8: Кр-99062677-2 | E8: POCHCHOYEVA ZULAYXO TOLIBJONOVNA | F8: +998932594485 SMS O’ZI, 998952224447 SMS ERI, 998992304600 SMS QAYNONASI, 998995554600 SMS QAYNOTA, 998939564485 узи 2, | G8: BUXORO VILOYAT JONDOR TUMAN IBN SINO MFY ASBOBSOZ KO’CHA 130-UY | H8: 8 | I8: 4269476.9 | K8: Va'da berdi | JUMA KUNI TOLOV QLAMN OYLI TUWADI DEDI
A9: БУХОРО ВИЛОЯТИ | C9: Обещал | D9: Кр-99018891-5 | E9: FAXILLOYEVA MOXINUR FOZILOVNA | F9: 97-306-16-10 SMS OZI, 90-513-05-03 SMS ERI, 97-854-75-48 SMS QAYNONA, 91-411-91-88 SMS QAYNOTA, 50-578-16-10 SMS UZI2, | G9: BUXORO VILOYATI BUXORO TUMANI NOVMETAN QFY | H9: 8 | I9: 4132073.3 | K9: Va'da berdi | bugun tolov qladi 5 gaca filialga borb
A10: БУХОРО ВИЛОЯТИ | C10: Обещал | D10: Кр-99033022-1 | E10: ASKAROV SHOHBOZ ULUG’BEKOVICH | F10: 998944219181 SMS OIZ, 998796441812 SMS OZI 2, 998931971731 SMS AYOLI, | G10: TOSHKENT SHAHAR, YANGIHAYOT TUMANI, YANGI DARXON MFY, NAVRO'Z KOCHASI 16-UY | H10: 8 | I10: 3155149.2 | K10: Va'da berdi | JUMA KUNI TOLOV QLAMN OYLI TUWADI DEDI
A11: БУХОРО ВИЛОЯТИ | C11: Дозвон | D11: Кр-99040789-2 | E11: DJURAYEVA SHAXINABONU ERKIN QIZI | F11: +998882100226 SMS O’ZI, 998772011384 SMS ONASI, 998991035070 SMS OTASI, 998997982977 SMS ZALAGADATEL, | G11: Уртачул МФЙ, Урта-Чул қишлоғи, 26-уй | H11: 8 | I11: 3150032.5 | J11: 3150032.5 | K11: To'ladi
A12: БУХОРО ВИЛОЯТИ | C12: Обещал | D12: Кр-99038162-1 | E12: DJAMOLOV BOBIR BAHRIDDINOVICH | F12: 998914174488 SMS OZI, 998914182244 SMS OZI, 998934225600 SMS O’G’LI Бехруз шу номерга қилинсин, 998930807508 SMS O’G’LI, | G12: BUXORO VILOYATI, VOBKENT TUMANI, ROZMOZ MFY, ELACH KO'CHASI, 4-UY | H12: 1 | I12: 2825554.5 | K12: Va'da berdi | bugun tulaydi
A13: БУХОРО ВИЛОЯТИ | C13: Обещал | D13: Кр-99037180-2 | E13: YULDASHEVA DILNOZA FAXRIDINOVNA | F13: 998914076943 SMS OZI, 998907441349 SMS ERI , 998941250707 SMS JIYANI, 998507056161 SMS AMAKISI, +998914076943 SMS O’ZI, | G13: ИСТИКБОЛ МФЙ, ШУРОБОД, 67-УЙ | H13: 8 | I13: 2736915.4 | K13: Va'da berdi | bugun tulaydi
A14: БУХОРО ВИЛОЯТИ | C14: Обещал | D14: Кр-99033611-1 | E14: ELMURODOVA ZEBINISO ODILOVNA | F14: 998939904907 SMS O’ZI, 998939983008 SMS ERI, 998943754907 SMS OTASI, 998931374907 SMS O’G’LI, 998501888730 SMS ERI 2, 998501204758 to'lovchi, | G14: BUXORO VILOYATI SHOFIRKON TUMANI PATTAXON MFY, YANGIOBOD q-q, 18-UY | H14: 1 | I14: 2701930.7 | K14: Va'da berdi | 18 sida tolaydi
A15: БУХОРО ВИЛОЯТИ | C15: Обещал | D15: Кр-99048166-1 | E15: KURBANOV DILMUROD TUYMURADOVICH | F15: +998936859009 SMS O’ZI, 998505100034 SMS QIZI, 998931361133 SMS O’G’LI, 998956001133 SMS AYOLI, | G15: BUXORO VILOYATI, BUXORO SHAHAR, IBN SINO MFY, BAHOUDDIN NAQSH BAND KO’CHASI,197-UY, 91-XONADON | H15: 8 | I15: 2505488 | K15: Va'da berdi
A16: БУХОРО ВИЛОЯТИ | C16: Обещал | D16: Кр-99039939-1 | E16: TUXTAYEVA NARGIZA JURAYEVNA | F16: 998918365488 SMS OZI, 998903407973 SMS ONASI, 998331951802 SMS ERI, 998994452534 SMS UY, | G16: BUXORO VILOYATI BUXORO SHAHAR FOSHUN MFY ALPOMISH KO'CHASI, 17/3 UY, 10-XONADON | H16: 8 | I16: 2408716.9 | K16: Va'da berdi
A17: БУХОРО ВИЛОЯТИ | C17: Обещал | D17: Кр-99033006-2 | E17: AMIRQULOV AZIZBEK FARXOD O’G’LI | F17: 998943206655 SMS O’ZI , 998930065166 SMS AKASI, 998940514494 SMS UKASI, | G17: BUXORO VILOYATI KORAKO’L TUMANI DARG’ALI MFY OQG’UN QISHLOG’I 22-UY | H17: 13 | I17: 2230158.7 | K17: Va'da berdi | ozi kotarmadi akasi ozm toliman 2 kunda dedi
A18: БУХОРО ВИЛОЯТИ | C18: Обещал | D18: Кр-99062595-1 | E18: NORQULOV HAYOT XODJIYEVICH | F18: 998907109550 SMS OZI, 998907119550 SMS AYOLI, 998902980454 SMS DOSTI, 998919369550 SMS UY, | G18: BUXORO VILOYATI BUXORO SHAHAR 19-SONLI FAYZULLA XO'JAYEV NOMLI MFY, SHODLIK KO'CHASI | H18: 8 | I18: 2213446.4 | K18: Va'da berdi | ertaga anq tolov qladi filialga borb
A19: БУХОРО ВИЛОЯТИ | C19: Обещал | D19: Кр-99019690-5 | E19: HAYDAROV FURQAT RAXMATILLOYEVICH | F19: 97-488-07-66 SMS O'ZI, 88-301-90-93 SMS AKASI, 97-296-06-93 SMS UY, 93-841-53-50 SMS AYOLI, 998505999203 SMS O'ZI2, | G19: BUXORO VILOYAT BUXORO SHAHRI BESHKAPPA KO'CHASI 106 UY | H19: 8 | I19: 2186873.8 | K19: Va'da berdi | OZI KOTARMADI UYDIGILANI TELI UCHGAN TGDAN YOZDM BUGUN TOLOV QLAMAN FILIALDAGI NMIRON BN GAPLAWGANMAN DEDI
A20: БУХОРО ВИЛОЯТИ | C20: Дозвон | D20: Кр-99062944-1 | E20: SAMIYEV DOSTONBEK TAVAKKALZODA | F20: +998882814800 SMS O’ZI, 998505068777 SMS UKASI, 998883064800 SMS UKASI, 998883440311 SMS ONASI, | G20: BUXORO VILOYATI SHOFIRKON TUMANI G’ULOMTE MFY G’ULOMTE QISHLOG’I | H20: 8 | I20: 2105616.6 | J20: 2105616.6 | K20: To'ladi | filialga naxt tolangan
A21: БУХОРО ВИЛОЯТИ | C21: Обещал | D21: Кр-99041320-3 | E21: SHODIYEV ULUG’BEK SALIMOVICH | F21: +998914431901 sms o’zi, 998907119935 sms onasi, 998912408206 sms ayoli, 998914471901 sms o’zi 2, | G21: Бухарская область, Гиждуванский район, Соктари МСГ, Соктари, дом 239 | H21: 8 | I21: 2084856 | K21: Va'da berdi | avans tuwadi 2kunda toliman dedi
A22: БУХОРО ВИЛОЯТИ | C22: Обещал | D22: Кр-99063975-1 | E22: QUZIYEV MAQSUD HIKMATULLOYEVICH | F22: 998912463904 SINGLISI, 998933147491 AYOLI, 998996229992 O’ZI, | G22: SDFC | H22: 8 | I22: 2059464.5 | K22: Va'da berdi
A23: БУХОРО ВИЛОЯТИ | C23: Обещал | D23: Кр-99040399-1 | E23: FATULLOYEV RIXSILLO SAYFULLA O’G’LI | F23: +998933163138 SMS O’ZI, 998933019922 SMS AKASI, 998934553785 SMS OTASI, 998943129933 SMS YANGASI, | G23: Бухарская область, Жондоpский район, Жамият МСГ, Шамширгарон, дом 309/1 | H23: 8 | I23: 1856810.5 | K23: Va'da berdi
A24: БУХОРО ВИЛОЯТИ | C24: Обещал | D24: Кр-99057620-1 | E24: SADRIDDINOV SAVRIDDIN HUSNIDDIN O’G’LI | F24: 998997027515 SMS UZI, 998906367515 SMS OTASI, 998997077515 SMS ONASI, 998918087515 SMS AKASI, | G24: BUXORO VILOYATI VOBKENT TUMANI KO'LXATIB MFY, NAVOIY KO'CHASI, 4-UY | H24: 8 | I24: 1845061.8 | K24: Va'da berdi | 16 SIDA OYLI TUWAD
A25: БУХОРО ВИЛОЯТИ | C25: Обещал | D25: Кр-99047434-2 | E25: UMRZOQOV FAXRIDDIN AXMEDJONOVICH | F25: 998959754272 O`ZI, 998941220757 AYOLI, 998945457562 DO`STI, 998959754272 uzi, 998941220757 ayoli, 998945457562 dosti, | G25: Бухоро шахар коракул тумани Мустакиллик 50 уй | H25: 8 | I25: 1815275.3 | K25: Va'da berdi
A26: БУХОРО ВИЛОЯТИ | C26: Обещал | D26: Кр-99038109-1 | E26: QO’YLIYEV SARDOR SATTOR O’G’LI | F26: 998885546677 SMS OZI, 998954741616 SMS AKASI, 998990748047 SMS OPASI, 998883041232 SMS UYI, | G26: BUXORO VILOYATI KOGON TUMANI, NIYOZ HOJI MFY, VADAN QISHLOG'I 88-UY | H26: 1 | I26: 1763754.3 | K26: Va'da berdi | sewanba kun oylik tuwadi tolov qlaman dedi
A27: БУХОРО ВИЛОЯТИ | C27: Обещал | D27: Кр-99041716-1 | E27: ODINAYEV ASLON AZIMOVICH | F27: +998872504057 SMS O’ZI, 998905122625 SMS DO’STI, 998912479697 SMS O’G’LI, 998978588778 SMS O’G’LI 2, 998882802662 yangi nomer o'zi, | G27: Убачули МФЙ, Мевазор кучаси, 96-уй | H27: 8 | I27: 1724153.7 | K27: Va'da berdi
A28: БУХОРО ВИЛОЯТИ | C28: Обещал | D28: Кр-99031584-1 | E28: NOROVA IRODA NE’MATOVNA | F28: 90-809-45-45 SMS O'ZI, 93-372-19-81 SMS QIZI MAFTUNA, 50-758-04-06 SMS QIZI MAHSUDA tanimidi, 91-016-68-42 SMS ONASI, 950378185 opchasi, 998774080081 узи , | G28: BUXORO VILOYATI QORAKO’L TUMANI TASHABBUS MFY ADXAM / YUNUSOBOD TUMANI 2-MAVZE 31-UY 45-XONADON | H28: 8 | I28: 1670536.4 | K28: Va'da berdi
A29: БУХОРО ВИЛОЯТИ | C29: Обещал | D29: Кр-99063280-1 | E29: QURBONOV XUSHVAQT G’ULOMOVICH | F29: +998914177518 SMS O’ZI, 998990454555 SMS AYOLI, 998993454441 SMS DO’STI, | G29: OLOT TUMANI | H29: 8 | I29: 1535825 | K29: Va'da berdi | BUGUN TOLAYDI
A30: БУХОРО ВИЛОЯТИ | C30: Обещал | D30: Кр-99062864-1 | E30: MAXMUDOV ALIAKBAR SAIDJONOVICH | F30: +998900650514 SMS, 998507103377 SMS UY, 998905128669 SMS AYOLI, | G30: BUXORO VILOYATI BUXORO SHAHAR AVSHORMAHALLA MFY 77-UY | H30: 8 | I30: 1516902 | K30: Va'da berdi | BUGUN TOLAYDI
A31: БУХОРО ВИЛОЯТИ | C31: Дозвон | D31: Кр-99040456-1 | E31: TEMIROV NODIRBEK G’OLIBJON OG’LI | F31: 998902981307 SMS OZI, 998995556077 SMS AMAKISI, 998918381398 SMS OTASI, 998906110811 SMS ONASI, | G31: BUXORO VILOYATI G'IJDUVON TUMANI ZARANGARI MFY, BO'LAKIYON QISHLOG'I 36-UY | H31: 8 | I31: 1432784.8 | J31: 1432784.8 | K31: To'ladi | filialga
A32: БУХОРО ВИЛОЯТИ | C32: Обещал | D32: Кр-99032591-1 | E32: BOZOROV DILSHOD OLIM O’G’LI | F32: 998995853782 SMS O’G’LI, 998940186667 SMS AYOLI(BEGONA), 998938997077 SMS ONASI, 998930831515 SMS HAMKASBI бегона , | G32: BUXORO VILOYATI ROMITAN TUMANI O'TABEK MFY, PITMON q-q, 6-uy | I32: 1298935.7 | K32: Va'da berdi | erta tolov qladi
A33: БУХОРО ВИЛОЯТИ | C33: Обещал | D33: Кр-99019690-4 | E33: HAYDAROV FURQAT RAXMATILLOYEVICH | F33: 97-488-07-66 SMS O'ZI, 88-301-90-93 SMS AKASI, 97-296-06-93 SMS UY, 93-841-53-50 SMS AYOLI, 998505999203 SMS O'ZI2, | G33: BUXORO VILOYAT BUXORO SHAHRI BESHKAPPA KO'CHASI 106 UY | H33: 11 | I33: 1212298.9 | K33: Va'da berdi | OZI KOTARMADI UYDIGILANI TELI UCHGAN TGDAN YOZDM BUGUN TOLOV QLAMAN FILIALDAGI NMIRON BN GAPLAWGANMAN DEDI
A34: БУХОРО ВИЛОЯТИ | C34: Обещал | D34: Кр-99019690-6 | E34: HAYDAROV FURQAT RAXMATILLOYEVICH | F34: 97-488-07-66 SMS O'ZI, 88-301-90-93 SMS AKASI, 97-296-06-93 SMS UY, 93-841-53-50 SMS AYOLI, 998505999203 SMS O'ZI2, | G34: BUXORO VILOYAT BUXORO SHAHRI BESHKAPPA KO'CHASI 106 UY | H34: 8 | I34: 1137499.2 | K34: Va'da berdi | OZI KOTARMADI UYDIGILANI TELI UCHGAN TGDAN YOZDM BUGUN TOLOV QLAMAN FILIALDAGI NMIRON BN GAPLAWGANMAN DEDI
A35: БУХОРО ВИЛОЯТИ | C35: Дозвон | D35: Кр-99049403-1 | E35: NAVRO’ZOV AZIZBEK HAYDAROVICH | F35: +998882827877 SMS O’ZI, 998914030464 SMS ONASI, 998936515100 SMS AKASI, 998973056003 SMS AKASI, | G35: BUXORO VILOYATI BUXORO TUMANI RABOTAK MFY YANGIOBOD KO’CHASI 118-UY | H35: 8 | I35: 1118758.3 | J35: 1118758.3 | K35: To'ladi
A36: БУХОРО ВИЛОЯТИ | C36: Обещал | D36: Кр-99036367-2 | E36: BEHBUDOV ASLBEK RIZAMATOVICH | F36: +998947812907 SMS O’ZI, 998914462869 SMS OTASI, 998948795777 SMS JIYANI, 998997034797 SMS ONASI, | G36: BUXORO VILOYATI QORAKO’L TUMANI KUYI JANPAR 101-UY | H36: 8 | I36: 1113123.3 | K36: Va'da berdi | 20 09 CIDA TOLIDI
A37: БУХОРО ВИЛОЯТИ | C37: Дозвон | D37: Кр-99057614-1 | E37: RASULOV XAKIM RO’ZIYEVICH | F37: 998914413241 SMS UZI, 998943434898 SMS UGLI, 998914158714 SMS TURMUSH O'RTOG'I, 998919256826 ozi2, | G37: NAVOIY VILOYATI,KOMNIMEX TUMANI,YUKSALISH MFY,CHORDARA QISHLOG'I,37 UY | H37: 8 | I37: 1007128.8 | J37: 1007128.8 | K37: To'ladi
A38: БУХОРО ВИЛОЯТИ | C38: Обещал | D38: Кр-99049211-1 | E38: ADIZOV AZAMAT SHOYIMOVICH | F38: 998940642993 SMS JIYANI, 998942218131 SMS O’ZI, 998978055824 SMS UKASI, 998999767786 SMS AYOLI, | G38: GULISTON, DOM 56 | H38: 8 | I38: 721276.55 | K38: Va'da berdi | filial bilan gaplawdim dedi
A39: БУХОРО ВИЛОЯТИ | C39: Обещал | D39: Кр-99044175-1 | E39: MURODOV MUROD UMAR O’G’LI | F39: +998995624067 SMS O’ZI, 998914450878 SMS DO’STI, 998918384026 SMS ONASI, 998948893111 SMS DO’STI, | G39: Паноб МФЙ, Янги ҳаёт қишлоғи, 138-уй | I39: 559713.31 | K39: Va'da berdi | bugun
A40: БУХОРО ВИЛОЯТИ | C40: Обещал | D40: Кр-99062840-2 | E40: DAVRONOV SOBIR KAMOLOVICH | F40: 998934608944 UKASI, 998936850790 AYOLI, 998945177590 O’ZI 2 NOMERI, 998935690790 uzi new SMS, | G40: G’IJDUVON TUMANI | H40: 8 | I40: 477080.45 | K40: Va'da berdi | bu navoiy viloyati
...

Sheet Обещали
A1: ← Вернуться в отчёт
A2: Область | B2: Филиал | C2: Группа | D2: Код клиента | E2: Клиент | F2: Номер телефона | G2: Адрес | H2: Кол-во просроченных дней | I2: Итого просрочка | J2: Оплата | K2: Izoh
A3: БУХОРО ВИЛОЯТИ | C3: Обещал | D3: Кр-99036711-1 | E3: ERGASHOV ALISHER NARZULLAYEVICH | F3: 998934784464 SMS O’ZI, 998939569626 SMS OTASI, 998931571911 SMS ONASI, 998930052290 SMS SINGLISI , | G3: BUXORO VILOYATI, QORAKO'L TUMANI, ISTIQLOL MFY, YANGI QISHLOQ KO'CHASI, 15-UY | H3: 1 | I3: 5020948.3 | K3: Va'da berdi | ertaga anq tulaydi
A4: БУХОРО ВИЛОЯТИ | C4: Обещал | D4: Кр-99028153-4 | E4: GOIPOV EL’BRUS RAXMADOVICH | F4: 94-120-61-31 SMS OZI, 94-219-60-83 SMS AYOLI, 94-782-03-28 OGLI (бегана), 94-382-28-11 SMS QIZI, | G4: BUXORO VILOYATI OLOT TUMANI XIDREYLI MFY 141-UY | H4: 8 | I4: 4961647.2 | K4: Va'da berdi
A5: БУХОРО ВИЛОЯТИ | C5: Обещал | D5: Кр-99034426-1 | E5: AZIZOV ILXOM BAXTIYAROVICH | F5: 998905146560 SMS OZI, 998907121044 SMS AYOLI, 998938741010 SMS OTASI, 998936421010 SMS ONASI, 998936421010 толовчичи шодиёр, | G5: BUXORO VILOYATI BUXORO SHAHAR TOJIQARAYEV MFY 61-UY | H5: 1 | I5: 4692523.7 | K5: Va'da berdi | ertaga
A6: БУХОРО ВИЛОЯТИ | C6: Обещал | D6: Кр-99062677-2 | E6: POCHCHOYEVA ZULAYXO TOLIBJONOVNA | F6: +998932594485 SMS O’ZI, 998952224447 SMS ERI, 998992304600 SMS QAYNONASI, 998995554600 SMS QAYNOTA, 998939564485 узи 2, | G6: BUXORO VILOYAT JONDOR TUMAN IBN SINO MFY ASBOBSOZ KO’CHA 130-UY | H6: 8 | I6: 4269476.9 | K6: Va'da berdi | JUMA KUNI TOLOV QLAMN OYLI TUWADI DEDI
A7: БУХОРО ВИЛОЯТИ | C7: Обещал | D7: Кр-99018891-5 | E7: FAXILLOYEVA MOXINUR FOZILOVNA | F7: 97-306-16-10 SMS OZI, 90-513-05-03 SMS ERI, 97-854-75-48 SMS QAYNONA, 91-411-91-88 SMS QAYNOTA, 50-578-16-10 SMS UZI2, | G7: BUXORO VILOYATI BUXORO TUMANI NOVMETAN QFY | H7: 8 | I7: 4132073.3 | K7: Va'da berdi | bugun tolov qladi 5 gaca filialga borb
A8: БУХОРО ВИЛОЯТИ | C8: Обещал | D8: Кр-99033022-1 | E8: ASKAROV SHOHBOZ ULUG’BEKOVICH | F8: 998944219181 SMS OIZ, 998796441812 SMS OZI 2, 998931971731 SMS AYOLI, | G8: TOSHKENT SHAHAR, YANGIHAYOT TUMANI, YANGI DARXON MFY, NAVRO'Z KOCHASI 16-UY | H8: 8 | I8: 3155149.2 | K8: Va'da berdi | JUMA KUNI TOLOV QLAMN OYLI TUWADI DEDI
A9: БУХОРО ВИЛОЯТИ | C9: Обещал | D9: Кр-99038162-1 | E9: DJAMOLOV BOBIR BAHRIDDINOVICH | F9: 998914174488 SMS OZI, 998914182244 SMS OZI, 998934225600 SMS O’G’LI Бехруз шу номерга қилинсин, 998930807508 SMS O’G’LI, | G9: BUXORO VILOYATI, VOBKENT TUMANI, ROZMOZ MFY, ELACH KO'CHASI, 4-UY | H9: 1 | I9: 2825554.5 | K9: Va'da berdi | bugun tulaydi
A10: БУХОРО ВИЛОЯТИ | C10: Обещал | D10: Кр-99037180-2 | E10: YULDASHEVA DILNOZA FAXRIDINOVNA | F10: 998914076943 SMS OZI, 998907441349 SMS ERI , 998941250707 SMS JIYANI, 998507056161 SMS AMAKISI, +998914076943 SMS O’ZI, | G10: ИСТИКБОЛ МФЙ, ШУРОБОД, 67-УЙ | H10: 8 | I10: 2736915.4 | K10: Va'da berdi | bugun tulaydi
A11: БУХОРО ВИЛОЯТИ | C11: Обещал | D11: Кр-99033611-1 | E11: ELMURODOVA ZEBINISO ODILOVNA | F11: 998939904907 SMS O’ZI, 998939983008 SMS ERI, 998943754907 SMS OTASI, 998931374907 SMS O’G’LI, 998501888730 SMS ERI 2, 998501204758 to'lovchi, | G11: BUXORO VILOYATI SHOFIRKON TUMANI PATTAXON MFY, YANGIOBOD q-q, 18-UY | H11: 1 | I11: 2701930.7 | K11: Va'da berdi | 18 sida tolaydi
A12: БУХОРО ВИЛОЯТИ | C12: Обещал | D12: Кр-99048166-1 | E12: KURBANOV DILMUROD TUYMURADOVICH | F12: +998936859009 SMS O’ZI, 998505100034 SMS QIZI, 998931361133 SMS O’G’LI, 998956001133 SMS AYOLI, | G12: BUXORO VILOYATI, BUXORO SHAHAR, IBN SINO MFY, BAHOUDDIN NAQSH BAND KO’CHASI,197-UY, 91-XONADON | H12: 8 | I12: 2505488 | K12: Va'da berdi
A13: БУХОРО ВИЛОЯТИ | C13: Обещал | D13: Кр-99039939-1 | E13: TUXTAYEVA NARGIZA JURAYEVNA | F13: 998918365488 SMS OZI, 998903407973 SMS ONASI, 998331951802 SMS ERI, 998994452534 SMS UY, | G13: BUXORO VILOYATI BUXORO SHAHAR FOSHUN MFY ALPOMISH KO'CHASI, 17/3 UY, 10-XONADON | H13: 8 | I13: 2408716.9 | K13: Va'da berdi
A14: БУХОРО ВИЛОЯТИ | C14: Обещал | D14: Кр-99033006-2 | E14: AMIRQULOV AZIZBEK FARXOD O’G’LI | F14: 998943206655 SMS O’ZI , 998930065166 SMS AKASI, 998940514494 SMS UKASI, | G14: BUXORO VILOYATI KORAKO’L TUMANI DARG’ALI MFY OQG’UN QISHLOG’I 22-UY | H14: 13 | I14: 2230158.7 | K14: Va'da berdi | ozi kotarmadi akasi ozm toliman 2 kunda dedi
... A26: БУХОРО ВИЛОЯТИ | C26: Обещал | D26: Кр-99062864-1 | E26: MAXMUDOV ALIAKBAR SAIDJONOVICH | F26: +998900650514 SMS, 998507103377 SMS UY, 998905128669 SMS AYOLI, | G26: BUXORO VILOYATI BUXORO SHAHAR AVSHORMAHALLA MFY 77-UY | H26: 8 | I26: 1516902 | K26: Va'da berdi | BUGUN TOLAYDI
A27: БУХОРО ВИЛОЯТИ | C27: Обещал | D27: Кр-99032591-1 | E27: BOZOROV DILSHOD OLIM O’G’LI | F27: 998995853782 SMS O’G’LI, 998940186667 SMS AYOLI(BEGONA), 998938997077 SMS ONASI, 998930831515 SMS HAMKASBI бегона , | G27: BUXORO VILOYATI ROMITAN TUMANI O'TABEK MFY, PITMON q-q, 6-uy | I27: 1298935.7 | K27: Va'da berdi | erta tolov qladi
A28: БУХОРО ВИЛОЯТИ | C28: Обещал | D28: Кр-99019690-4 | E28: HAYDAROV FURQAT RAXMATILLOYEVICH | F28: 97-488-07-66 SMS O'ZI, 88-301-90-93 SMS AKASI, 97-296-06-93 SMS UY, 93-841-53-50 SMS AYOLI, 998505999203 SMS O'ZI2, | G28: BUXORO VILOYAT BUXORO SHAHRI BESHKAPPA KO'CHASI 106 UY | H28: 11 | I28: 1212298.9 | K28: Va'da berdi | OZI KOTARMADI UYDIGILANI TELI UCHGAN TGDAN YOZDM BUGUN TOLOV QLAMAN FILIALDAGI NMIRON BN GAPLAWGANMAN DEDI
A29: БУХОРО ВИЛОЯТИ | C29: Обещал | D29: Кр-99019690-6 | E29: HAYDAROV FURQAT RAXMATILLOYEVICH | F29: 97-488-07-66 SMS O'ZI, 88-301-90-93 SMS AKASI, 97-296-06-93 SMS UY, 93-841-53-50 SMS AYOLI, 998505999203 SMS O'ZI2, | G29: BUXORO VILOYAT BUXORO SHAHRI BESHKAPPA KO'CHASI 106 UY | H29: 8 | I29: 1137499.2 | K29: Va'da berdi | OZI KOTARMADI UYDIGILANI TELI UCHGAN TGDAN YOZDM BUGUN TOLOV QLAMAN FILIALDAGI NMIRON BN GAPLAWGANMAN DEDI
A30: БУХОРО ВИЛОЯТИ | C30: Обещал | D30: Кр-99036367-2 | E30: BEHBUDOV ASLBEK RIZAMATOVICH | F30: +998947812907 SMS O’ZI, 998914462869 SMS OTASI, 998948795777 SMS JIYANI, 998997034797 SMS ONASI, | G30: BUXORO VILOYATI QORAKO’L TUMANI KUYI JANPAR 101-UY | H30: 8 | I30: 1113123.3 | K30: Va'da berdi | 20 09 CIDA TOLIDI
A31: БУХОРО ВИЛОЯТИ | C31: Обещал | D31: Кр-99049211-1 | E31: ADIZOV AZAMAT SHOYIMOVICH | F31: 998940642993 SMS JIYANI, 998942218131 SMS O’ZI, 998978055824 SMS UKASI, 998999767786 SMS AYOLI, | G31: GULISTON, DOM 56 | H31: 8 | I31: 721276.55 | K31: Va'da berdi | filial bilan gaplawdim dedi
A32: БУХОРО ВИЛОЯТИ | C32: Обещал | D32: Кр-99044175-1 | E32: MURODOV MUROD UMAR O’G’LI | F32: +998995624067 SMS O’ZI, 998914450878 SMS DO’STI, 998918384026 SMS ONASI, 998948893111 SMS DO’STI, | G32: Паноб МФЙ, Янги ҳаёт қишлоғи, 138-уй | I32: 559713.31 | K32: Va'da berdi | bugun
A33: БУХОРО ВИЛОЯТИ | C33: Обещал | D33: Кр-99062840-2 | E33: DAVRONOV SOBIR KAMOLOVICH | F33: 998934608944 UKASI, 998936850790 AYOLI, 998945177590 O’ZI 2 NOMERI, 998935690790 uzi new SMS, | G33: G’IJDUVON TUMANI | H33: 8 | I33: 477080.45 | K33: Va'da berdi | bu navoiy viloyati
A34: ЖИЗЗАХ ВИЛОЯТИ | C34: Обещал | D34: Кр-99047637-1 | E34: AZIMOV ASADBEK OTABEK O’G’LI | F34: +998905382222 SMS NOMER, 998971120007 SMS O’ZI, 998991937773 begonA EKAN, | G34: JIZZAX VILOYATI JIZZAX SHAHRI TURON MFY SAYILJOYI KUCHASI 21-UY | H34: 71 | I34: 19927076 | K34: Va'da berdi | ertaga yopadi
A35: ЖИЗЗАХ ВИЛОЯТИ | C35: Обещал | D35: Кр-99060448-1 | E35: MAMIROVA ZEBO ZOIROVNA | F35: 998779762227 SMS OZI, 998938244230 SMS AYOLI, 998906432211 SMS UKASI, | G35: JIZZAX VILOYATI SHAROF RASHIDOV TUMANI YAXTANLIK MFY GUZAL KOCHASI 52-UY | H35: 11 | I35: 11697427 | K35: Va'da berdi | wu hafta tolaydi
A36: ЖИЗЗАХ ВИЛОЯТИ | C36: Обещал | D36: Кр-99027165-3 | E36: DJABBAROVA PULATOY SAYFIDDINNOVNA | F36: 91-941-83-83 SMS UZI , 93-393-79-09 SMS UZI 2, 94-977-84-58 SMS QAYNONASI , 93-449-77-15 SMS OGLI, 99-079-20-10 SMS UZI new, | G36: JIZZAX VILOYATI JIZZAX TUMANI QANGLI MFY CHAVANDOZLAR KUCHASI 13-UY | H36: 11 | I36: 8369851.8 | K36: Va'da berdi | kecgaca tolaydi
A37: ЖИЗЗАХ ВИЛОЯТИ | C37: Обещал | D37: Кр-99056937-2 | E37: RASHIDOVA NASIBA YAKUBOVNA | F37: 998889541771 SMS OZI, 998843817712 SMS OZI2, 998974390219 SMS KELINI, | G37: JIZZAX VILOYATI JIZZAX SHAHAR MIRZO ULUG'BEK MAHALLASI 2-UY 10-XONADON | H37: 11 | I37: 8235139.5 | K37: Va'da berdi | bugun tulaydi
A38: ЖИЗЗАХ ВИЛОЯТИ | C38: Обещал | D38: Кр-99028729-1 | E38: AMANOV BUNYOD MUMIN O’G’LI | F38: 998991791177 SMS OZI, 998902642879 SMS OPASI, 998509979579 SMS TOLOVCHISI, 998996790117 SMS AYOLI, 998881591177 AYOLI, 998944449556 ONASI, | G38: МУЗБУЛОК МФЙ, МУЗБУЛОК МФЙ, ЛОЙИХАДАГИ, uy:Р.С | H38: 4 | I38: 6850779.4 | K38: Va'da berdi | kecgaca tolaydi
A39: ЖИЗЗАХ ВИЛОЯТИ | C39: Обещал | D39: Кр-99062344-1 | E39: ALIMOV BAXROM YETMISHOVICH | F39: 998959098681 O`ZI, 998959108681 AYOLI, 998956261810 QIZI, | G39: JIZZAX VILOYATI ZARBDOR TUMANI RAVOT MFY PILLAKOR KUCHASI 1-UYI | H39: 8 | I39: 6616631.7 | K39: Va'da berdi | 2kunda tolimn filyaldagilar blan gaplawdm dedi
A40: ЖИЗЗАХ ВИЛОЯТИ | C40: Обещал | D40: Кр-99028038-1 | E40: XAZRATKULOVA RAYXON TURSUNBAYEVNA | F40: 998772725500 SMS OZI, 998951307770 SMS UKASI, 998904928594 SMS ZOLOGATEL, | G40: JIZZAX VILOYATI JIZZAX SHAHRI OBOD MFY XALQLAR DUSTLIGI KUCHASI 101-A UY 23-XONADON | H40: 6 | I40: 5897133.6 | K40: Va'da berdi | ukasi temur bilan gaplawganman dedi
A41: ЖИЗЗАХ ВИЛОЯТИ | C41: Обещал | D41: Кр-99021925-1 | E41: ISMOILOVA NARGIZA ABDUSALIYEVNA | F41: 998938567000 SMS O’ZI, 998501040408 SMS ERI, 998943437777 SMS ERI , 998905160057 SMS ERINI UKASI, 998931070408 tolovchi eri , 998971299092 sms tulovchi, 998508043200 FARUX TULOVCHISI, | G41: JIZZAX VILOYATI SHAROF RASHIDOV TUMANI QANG'LI QFY ARISHLI MAHALLASI ZIYOKOR KUCHASI 4-UY | H41: 1 | I41: 5112052.5 | K41: Va'da berdi | ertaga tulaydi
A42: ЖИЗЗАХ ВИЛОЯТИ | C42: Обещал | D42: Кр-99042115-1 | E42: MIRZAYEV OYBEK SUNATILLAYEVICH | F42: +998902659695 SMS, 998915909006 SMS, 998974559695 SMS, | G42: JIZZAX VILOYATI SH.RASHIDOV TUMANI TOKCHILIK MFY ZARGARLIK KUCHASI 2-UY | H42: 8 | I42: 4443964.3 | K42: Va'da berdi | bugun kecgaca yopadi
A43: ЖИЗЗАХ ВИЛОЯТИ | C43: Обещал | D43: Кр-99063504-1 | E43: MIRZAYEVA LOBARXON ERGASHEVNA | F43: 998933556974 UZI, 998934026974 ERI, 998958832266 TO’LOVCHI, | G43: ТОШКЕСГАН КФЙ, ЛОЙИХАДАГИ КЎЧА, uy:РАКАМСИЗ | H43: 8 | I43: 4415942.1 | K43: Va'da berdi | ertaga tolaydi
A44: ЖИЗЗАХ ВИЛОЯТИ | C44: Обещал | D44: Кр-99062963-2 | E44: RAJABOV BAXODIR BOZARBOYEVICH | F44: 998941996644 AYOLI, | G44: Саройлик МФЙ, Эркинлик кучаси, 45-уй | H44: 8 | I44: 4084124.4 | K44: Va'da berdi | erta abetgaca tolaydi
... A69: ЖИЗЗАХ ВИЛОЯТИ | C69: Обещал | D69: Кр-99033516-1 | E69: MIRZAMAXMUDOV ODILJON ALLAYOR O’G’LI | F69: 998997449700 SMS O’ZI, 998912084455 SMS O’ZI, 998338382297 SMS DO’STI, 998991332871 SMS ONASI, 998950702444 SMS AKASI, 998336669700 SMS OZI YANGI, 998932947066 SMS ABDUNABI ORTOGI, | G69: JIZZAX VILOYATI BAXMAL TUMANI UDAMALI QISHLOG’I 63-UY | H69: 1 | I69: 1079691.8 | K69: Va'da berdi | ertaga abetgaca tolaydi
A70: ЖИЗЗАХ ВИЛОЯТИ | C70: Обещал | D70: Кр-99045121-1 | E70: ISLAMOVA GO’ZAL ZOIR QIZI | F70: 998774512156 SMS, 998950414100 SMS, 998958824000 SMS, | G70: ОСМОНСОЙ ҚФЙ, ОСМОНСОЙ ҚФЙ, УРТАКИШЛОК КИШЛОГИ, uy:РАКАМСИЗ | I70: 452412.95 | K70: Va'da berdi | bugun kecgaca yopadi
A71: ЖИЗЗАХ ВИЛОЯТИ | C71: Обещал | D71: Кр-99034148-3 | E71: SAYFUTDINOVA GAVXAR SHUXRATOVNA | F71: 998903111016 SMS OZI, 998976480208 SMS ERI TOLOVCHI, 998912093311 SMS HAMKASBI, 998712267815 SMS UY, | G71: JIZZAX VILOYATI SH.RASHIDOV TUMANI ZIYOKOR QFY M.ESHONQULOV KUCHASI 125-UY | H71: 8 | I71: 397223.7 | K71: Va'da berdi | bugun tulaydi
A72: ЖИЗЗАХ ВИЛОЯТИ | C72: Обещал | D72: Кр-99025940-2 | E72: XAYRULLAYEV MUXAMMAD FAYZULLAYEVICH | F72: 97-129-10-83 SMS UZI, 99-566-22-10 SMS UZI 2, 98-561-10-12 SMS TULOVCHI, 998995610220 SMS O’ZI SHUNGA QILINSIN, | G72: КУЛАМА ҚФЙ, МУЛКАНЛИК МФЙ, ЛОЙИХАДАГИ КЎЧА, uy:60 | I72: 285394.68 | K72: Va'da berdi | 7gaca yopadi
A73: КАШКАДАРЁ ВИЛОЯТИ | B73: SUPER BRANCH | C73: Обещал | D73: Кр-99036435-3 | E73: JO’RAQULOV MANSUR QULMUROT O’G’LI | F73: 998997330311 SMS O’ZI, 998333400311 SMS AYOLI, 998942976783 SMS O’ZI 2, 998881365522 SMS UKASI , | G73: ЧИРОКЧИ МФЙ, ЧИРОКЧИ, uy:Р/С | H73: 11 | I73: 17370593 | K73: Va'da berdi | 20 da to'lov qiladi
A74: КАШКАДАРЁ ВИЛОЯТИ | B74: SUPER BRANCH | C74: Обещал | D74: Кр-99060317-1 | E74: NAFASOV ASADBEK VALIJON O’G’LI | F74: 998973852277 SMS OZI, 998886191100 SMS AYOLI, 998770994440 SMS DADASI, 998886195000 SMS ONASI, | G74: QASHQADARYO VILOYATI YAKKABOG’ TUMANI ISTIQLOL MFY OLAQARG’A QISHLOG’I | H74: 11 | I74: 11559193 | K74: Va'da berdi | payshanba kuni
A75: КАШКАДАРЁ ВИЛОЯТИ | B75: SUPER BRANCH | C75: Обещал | D75: Кр-99059908-1 | E75: MURODOV BEGZOD ZOIDOVICH | F75: 998500721265 SMS OZI, 998509098588 SMS ONASI (BEGONA), 998976194411 SMS OTASI, 998977088588 SMS ASKASI, 998509098525 SMS UZI NEW, | G75: QASHQADARYO VILOYATI KITOB TUMANI CHARMGAR MFY SAYILGOH KO’CHASI 3-UY | H75: 11 | I75: 7888733.5 | K75: Va'da berdi | bugun
...

Sheet Оплатили
A1: ← Вернуться в отчёт
A2: Область | B2: Филиал | C2: Группа | D2: Код клиента | E2: Клиент | F2: Номер телефона | G2: Адрес | H2: Кол-во просроченных дней | I2: Итого просрочка | J2: Оплата | K2: Izoh
A3: БУХОРО ВИЛОЯТИ | C3: Дозвон | D3: Кр-99063147-1 | E3: YUSUPOV TALGAT RAVILEVICH | F3: +998934589950 SMS O’ZI, 998504052350 SMS AYOLI, 998936202480 SMS QIZI, 998936560151 SMS ONASI, | G3: 5-СОН ГАФУР ГУЛОМ НОМЛИ МФЙ, ИФТИХОР КУЧАСИ, 32-UY | H3: 8 | I3: 8437576.4 | J3: 8437576.4 | K3: To'ladi
A4: БУХОРО ВИЛОЯТИ | C4: Дозвон | D4: Кр-99038186-1 | E4: SA’DULLAYEVA ROXILLA SADULLO QIZI | F4: 998933094290 SMS OZI, 998993803457 SMS QUDASI, 998990943457 SMS SINGLISI, | G4: BUXORO VILOYATI BUXORO TUMANI, QALQO QISHLOG'I, 4-MUYILISH, 8-UY | H4: 1 | I4: 7600197.6 | J4: 7600197.6 | K4: To'ladi
A5: БУХОРО ВИЛОЯТИ | C5: Дозвон | D5: Кр-99040789-2 | E5: DJURAYEVA SHAXINABONU ERKIN QIZI | F5: +998882100226 SMS O’ZI, 998772011384 SMS ONASI, 998991035070 SMS OTASI, 998997982977 SMS ZALAGADATEL, | G5: Уртачул МФЙ, Урта-Чул қишлоғи, 26-уй | H5: 8 | I5: 3150032.5 | J5: 3150032.5 | K5: To'ladi
A6: БУХОРО ВИЛОЯТИ | C6: Объезд | D6: Кр-99027688-2 | E6: HUSENOV BARNO HASANOVICH | F6: 94-003-53-53 sms O'ZI begana, 93-211-44-49 sms AYOLI, 93-558-53-33 sms O'G'LI, 50-720-12-44 sms QIZI, +998949965353 SMS O’ZI, 998507201244 SMS QIZI, 998932114449 SMS AYOLI, | G6: АРАБХОНА МФЙ, АРАБХОНА, | H6: 8 | I6: 2968080.1 | J6: 2968080.1 | K6: Uyiga borildi - to'ladi
A7: БУХОРО ВИЛОЯТИ | C7: Дозвон | D7: Кр-99062944-1 | E7: SAMIYEV DOSTONBEK TAVAKKALZODA | F7: +998882814800 SMS O’ZI, 998505068777 SMS UKASI, 998883064800 SMS UKASI, 998883440311 SMS ONASI, | G7: BUXORO VILOYATI SHOFIRKON TUMANI G’ULOMTE MFY G’ULOMTE QISHLOG’I | H7: 8 | I7: 2105616.6 | J7: 2105616.6 | K7: To'ladi | filialga naxt tolangan
A8: БУХОРО ВИЛОЯТИ | C8: Дозвон | D8: Кр-99040456-1 | E8: TEMIROV NODIRBEK G’OLIBJON OG’LI | F8: 998902981307 SMS OZI, 998995556077 SMS AMAKISI, 998918381398 SMS OTASI, 998906110811 SMS ONASI, | G8: BUXORO VILOYATI G'IJDUVON TUMANI ZARANGARI MFY, BO'LAKIYON QISHLOG'I 36-UY | H8: 8 | I8: 1432784.8 | J8: 1432784.8 | K8: To'ladi | filialga
A9: БУХОРО ВИЛОЯТИ | C9: Дозвон | D9: Кр-99049403-1 | E9: NAVRO’ZOV AZIZBEK HAYDAROVICH | F9: +998882827877 SMS O’ZI, 998914030464 SMS ONASI, 998936515100 SMS AKASI, 998973056003 SMS AKASI, | G9: BUXORO VILOYATI BUXORO TUMANI RABOTAK MFY YANGIOBOD KO’CHASI 118-UY | H9: 8 | I9: 1118758.3 | J9: 1118758.3 | K9: To'ladi
A10: БУХОРО ВИЛОЯТИ | C10: Дозвон | D10: Кр-99057614-1 | E10: RASULOV XAKIM RO’ZIYEVICH | F10: 998914413241 SMS UZI, 998943434898 SMS UGLI, 998914158714 SMS TURMUSH O'RTOG'I, 998919256826 ozi2, | G10: NAVOIY VILOYATI,KOMNIMEX TUMANI,YUKSALISH MFY,CHORDARA QISHLOG'I,37 UY | H10: 8 | I10: 1007128.8 | J10: 1007128.8 | K10: To'ladi
A11: БУХОРО ВИЛОЯТИ | C11: Дозвон | D11: Кр-99035271-1 | E11: ERGASHEV MADAT MAXMUDOVICH | F11: 998951410082 SMS O’ZI begona, 998883078283 SMS AYOLI, 998939756160 SMS ONASI, 998880830140 SMS UY, 998882854888 узи, 998879650920 кизи, | G11: BUXORO VILOYATI SHOFIRKON TUMANI, XO'JA ORIF MFY, XO'JA ORIF KO'CHASI, 201-UY | H11: 1 | I11: 54.48 | J11: 54.48 | K11: To'ladi
A12: ЖИЗЗАХ ВИЛОЯТИ | C12: Объезд | D12: Кр-99036112-1 | E12: O’TASHEV RAVSHAN BOXTIYOR O’G’LI | F12: 998991037766 SMS OZI, 998946525295 SMS AKA TOLOVCHI, 998946738436 SMS AYOLI TOLOVCHI, 998944973835 SMS AYOLI, 998958735995 SMS TOLOVCHI, | G12: JIZZAX VILOYATI MIRZACHUL TUMANI PAXTAZOR SHFY BUNYODKOR KUCHASI 38-UY 2-XONADON | H12: 42 | I12: 6829564.9 | J12: 6829564.9 | K12: Uyiga borildi - to'ladi | mowin olingan
A13: ЖИЗЗАХ ВИЛОЯТИ | C13: Дозвон | D13: Кр-99028616-4 | E13: MALLAYEV SHUXRAT BOSIMOVICH | F13: 93-301-00-66 SMS O'ZI, 93-301-07-54 SMS AYOLI, 93-301-06-96 SMS SIN, 99-245-90-99 SMS SIN 2, 998945450550 Eldor ogli , 998992169079 tulovchi, 998997563446 tulovchi, | G13: JIZZAX VILOYATI JIZZAX TUMANI QANGLI MFY TARAQLI KUCHASI 13-UY | H13: 8 | I13: 6576640.7 | J13: 6576640.7 | K13: To'ladi
A14: ЖИЗЗАХ ВИЛОЯТИ | C14: Дозвон | D14: Кр-99033288-1 | E14: KENJAYEVA MUHABBAT XOLQUZIYEVNA | F14: 998995277527 SMS O’ZI, 998932993392 SMS QIZI, 990982993399 SMS KUYOVI, | G14: JIZZAX VILOYATI SH RASHIDOV TUMANI QAHRAMON MFY TURKISTON KUCHASI 42-UY | H14: 11 | I14: 4835015.5 | J14: 4835015.5 | K14: To'ladi
