Workbook
Name Print_Titles: Ввод!$4:$5
Name БазоваяПапка: Справочники!$N$1

Sheet Ввод
A2: Дата отчёта: | C2: 46282
E4: ПОРТФЕЛЬ | G4: ПРОСРОЧКА | K4: ДОЗВОНИЛИСЬ / ОБЕЩАЛИ | O4: НЕ ДОЗВОНИЛИСЬ / ОБЪЕЗД | S4: ОПЛАЧЕНО ЗА ДЕНЬ | Y4: ЭФФЕКТИВНОСТЬ И НАГРУЗКА
A5: № | B5: Область | C5: Ответственный | D5: Сотруд- ников | E5: Портфель, сум | F5: Портфель, шт | G5: Просрочка, сум | H5: Просрочка, шт | I5: % к портфелю | J5: % к кол-ву | K5: Дозвон, сум | L5: Дозвон, шт | M5: Обещали, сум | N5: Обещали, шт | O5: Не дозв., сум | P5: Не дозв., шт | Q5: Объезд, сум | R5: Объезд, шт | S5: Оплатил дозвон, сум | T5: Оплатил дозвон, шт | U5: Объезд оплатил, сум | V5: Объезд оплатил, шт | W5: Оплачено, сум | X5: Оплачено, шт | Y5: % дозвона (шт) | Z5: % обещаний (от дозвона) | AA5: Просрочка на 1 сотр. | AB5: Дозвон на 1 сотр. | AE5: служ. (для сортировки)
A6: 1 | B6: АНДИЖОН ВИЛОЯТИ | C6: =IFERROR(INDEX(Справочники!$D$4:$D$21,MATCH($B6,Справочники!$B$4:$B$21,0)),"") | D6: =SUMIF(Справочники!$H$4:$H$21,$B6,Справочники!$E$4:$E$21) -> 0 | E6: 2.1670184e+10 | F6: 445 | G6: =$K6+$O6 -> 2.1699731e+08 | H6: =$L6+$P6 -> 32 | I6: =IFERROR($G6/$E6,"") -> 0.010013635 | J6: =IFERROR($H6/$F6,"") -> 0.071910112 | K6: 5.2922391e+08 | L6: 87 | M6: 5.130247e+08 | N6: 84 | O6: 2.4056174e+08 | P6: 28 | Q6: 84857504 | R6: 13 | S6: 4657532 | T6: 3 | U6: 6438354 | V6: 3 | W6: 11095886 | X6: 6 | Y6: =IFERROR($L6/$H6,"") -> 0 | Z6: =IFERROR($N6/$L6,"") | AA6: =IFERROR($H6/$D6,"") | AB6: =IFERROR($L6/$D6,"") | AE6: =IFERROR($Y6,0)+ROW()/1000000 -> 6e-06
A7: 2 | B7: БУХОРО ВИЛОЯТИ | C7: =IFERROR(INDEX(Справочники!$D$4:$D$21,MATCH($B7,Справочники!$B$4:$B$21,0)),"") | D7: =SUMIF(Справочники!$H$4:$H$21,$B7,Справочники!$E$4:$E$21) -> 0 | E7: 5.1231734e+09 | F7: 167 | G7: =$K7+$O7 -> 2.0266951e+08 | H7: =$L7+$P7 -> 18 | I7: =IFERROR($G7/$E7,"") -> 0.03955937 | J7: =IFERROR($H7/$F7,"") -> 0.10778443 | K7: 40258501 | L7: 13 | M7: 39046202 | N7: 12 | O7: 1.8764791e+08 | P7: 27 | Q7: 4643386.1 | R7: 3 | S7: 1265879 | T7: 1 | U7: 3762109 | V7: 2 | W7: 5027988 | X7: 3 | Y7: =IFERROR($L7/$H7,"") -> 0 | Z7: =IFERROR($N7/$L7,"") | AA7: =IFERROR($H7/$D7,"") | AB7: =IFERROR($L7/$D7,"") | AE7: =IFERROR($Y7,0)+ROW()/1000000 -> 7e-06
A8: 3 | B8: ЖИЗЗАХ ВИЛОЯТИ | C8: =IFERROR(INDEX(Справочники!$D$4:$D$21,MATCH($B8,Справочники!$B$4:$B$21,0)),"") | D8: =SUMIF(Справочники!$H$4:$H$21,$B8,Справочники!$E$4:$E$21) -> 0 | E8: 1.3904205e+10 | F8: 493 | G8: =$K8+$O8 -> 2.498528e+08 | H8: =$L8+$P8 -> 51 | I8: =IFERROR($G8/$E8,"") -> 0.017969585 | J8: =IFERROR($H8/$F8,"") -> 0.10344828 | K8: 1.1962063e+08 | L8: 31 | M8: 1.0777361e+08 | N8: 22 | O8: 1.5680618e+08 | P8: 40 | Q8: 55296772 | R8: 15 | S8: 11847018 | T8: 9 | U8: 11722636 | V8: 4 | W8: 23569654 | X8: 13 | Y8: =IFERROR($L8/$H8,"") -> 0.39215686 | Z8: =IFERROR($N8/$L8,"") -> 0.95 | AA8: =IFERROR($H8/$D8,"") | AB8: =IFERROR($L8/$D8,"") | AE8: =IFERROR($Y8,0)+ROW()/1000000 -> 0.39216486
A9: 4 | B9: КАШКАДАРЁ ВИЛОЯТИ | C9: =IFERROR(INDEX(Справочники!$D$4:$D$21,MATCH($B9,Справочники!$B$4:$B$21,0)),"") | D9: =SUMIF(Справочники!$H$4:$H$21,$B9,Справочники!$E$4:$E$21) -> 0 | E9: 1.2186569e+10 | F9: 418 | G9: =$K9+$O9 -> 2.0555796e+08 | H9: =$L9+$P9 -> 33 | I9: =IFERROR($G9/$E9,"") -> 0.016867583 | J9: =IFERROR($H9/$F9,"") -> 0.078947368 | K9: 94171739 | L9: 27 | M9: 87135274 | N9: 22 | O9: 2.8220861e+08 | P9: 76 | Q9: 53867850 | R9: 12 | S9: 7036464.7 | T9: 5 | U9: 6953038.8 | V9: 6 | W9: 13989503 | X9: 11 | Y9: =IFERROR($L9/$H9,"") -> 0.87878788 | Z9: =IFERROR($N9/$L9,"") -> 0.62068966 | AA9: =IFERROR($H9/$D9,"") | AB9: =IFERROR($L9/$D9,"") | AE9: =IFERROR($Y9,0)+ROW()/1000000 -> 0.87879688
A10: 5 | B10: КОРАКАЛПОГИСТОН РЕСПУБЛИКАСИ | C10: =IFERROR(INDEX(Справочники!$D$4:$D$21,MATCH($B10,Справочники!$B$4:$B$21,0)),"") | D10: =SUMIF(Справочники!$H$4:$H$21,$B10,Справочники!$E$4:$E$21) -> 0 | E10: 1.1119545e+10 | F10: 269 | G10: =$K10+$O10 -> 2.5963958e+08 | H10: =$L10+$P10 -> 26 | I10: =IFERROR($G10/$E10,"") -> 0.023349839 | J10: =IFERROR($H10/$F10,"") -> 0.096654275 | K10: 1.754022e+08 | L10: 46 | M10: 1.7181797e+08 | N10: 43 | O10: 1.0934341e+08 | P10: 15 | Q10: 35606179 | R10: 8 | S10: 2771230 | T10: 3 | U10: 1767587.4 | V10: 1 | W10: 4538817.4 | X10: 4 | Y10: =IFERROR($L10/$H10,"") -> 0.76923077 | Z10: =IFERROR($N10/$L10,"") -> 0.2 | AA10: =IFERROR($H10/$D10,"") | AB10: =IFERROR($L10/$D10,"") | AE10: =IFERROR($Y10,0)+ROW()/1000000 -> 0.76924077
A11: 6 | B11: НАВОИЙ ВИЛОЯТИ | C11: =IFERROR(INDEX(Справочники!$D$4:$D$21,MATCH($B11,Справочники!$B$4:$B$21,0)),"") | D11: =SUMIF(Справочники!$H$4:$H$21,$B11,Справочники!$E$4:$E$21) -> 0 | E11: 6.476845e+09 | F11: 209 | G11: =$K11+$O11 -> 1.0708535e+08 | H11: =$L11+$P11 -> 18 | I11: =IFERROR($G11/$E11,"") -> 0.016533567 | J11: =IFERROR($H11/$F11,"") -> 0.086124402 | K11: 75426904 | L11: 24 | M11: 27253009 | N11: 8 | O11: 1.2636505e+08 | P11: 33 | Q11: 4302470.6 | R11: 1 | S11: 13858448 | T11: 8 | U11: 0 | V11: 0 | W11: 13858448 | X11: 8 | Y11: =IFERROR($L11/$H11,"") -> 0.055555556 | Z11: =IFERROR($N11/$L11,"") -> 1 | AA11: =IFERROR($H11/$D11,"") | AB11: =IFERROR($L11/$D11,"") | AE11: =IFERROR($Y11,0)+ROW()/1000000 -> 0.055566556
A12: 7 | B12: НАМАНГАН ВИЛОЯТИ | C12: =IFERROR(INDEX(Справочники!$D$4:$D$21,MATCH($B12,Справочники!$B$4:$B$21,0)),"") | D12: =SUMIF(Справочники!$H$4:$H$21,$B12,Справочники!$E$4:$E$21) -> 0 | E12: 1.4729616e+10 | F12: 438 | G12: =$K12+$O12 -> 5.9799851e+08 | H12: =$L12+$P12 -> 62 | I12: =IFERROR($G12/$E12,"") -> 0.040598377 | J12: =IFERROR($H12/$F12,"") -> 0.14155251 | K12: 4.6590436e+08 | L12: 73 | M12: 30120826 | N12: 9 | O12: 4.1608266e+08 | P12: 60 | Q12: 15522112 | R12: 5 | S12: 0 | T12: 0 | U12: 0 | V12: 0 | W12: 0 | X12: 0 | Y12: =IFERROR($L12/$H12,"") -> 0.48387097 | Z12: =IFERROR($N12/$L12,"") -> 1 | AA12: =IFERROR($H12/$D12,"") | AB12: =IFERROR($L12/$D12,"") | AE12: =IFERROR($Y12,0)+ROW()/1000000 -> 0.48388297
A13: 8 | B13: САМАРКАНД ВИЛОЯТИ | C13: =IFERROR(INDEX(Справочники!$D$4:$D$21,MATCH($B13,Справочники!$B$4:$B$21,0)),"") | D13: =SUMIF(Справочники!$H$4:$H$21,$B13,Справочники!$E$4:$E$21) -> 0 | E13: 1.6007859e+10 | F13: 549 | G13: =$K13+$O13 -> 2.6721243e+08 | H13: =$L13+$P13 -> 61 | I13: =IFERROR($G13/$E13,"") -> 0.016692577 | J13: =IFERROR($H13/$F13,"") -> 0.11111111 | K13: 1.3439362e+08 | L13: 35 | M13: 1.121437e+08 | N13: 26 | O13: 3.5827007e+08 | P13: 92 | Q13: 75252986 | R13: 18 | S13: 22249925 | T13: 9 | U13: 11412968 | V13: 5 | W13: 33662893 | X13: 14 | Y13: =IFERROR($L13/$H13,"") -> 0.24590164 | Z13: =IFERROR($N13/$L13,"") -> 1 | AA13: =IFERROR($H13/$D13,"") | AB13: =IFERROR($L13/$D13,"") | AE13: =IFERROR($Y13,0)+ROW()/1000000 -> 0.24591464
A14: 9 | B14: СИРДАРЁ ВИЛОЯТИ | C14: =IFERROR(INDEX(Справочники!$D$4:$D$21,MATCH($B14,Справочники!$B$4:$B$21,0)),"") | D14: =SUMIF(Справочники!$H$4:$H$21,$B14,Справочники!$E$4:$E$21) -> 0 | E14: 7.1897605e+09 | F14: 151 | G14: =$K14+$O14 -> 97690450 | H14: =$L14+$P14 -> 17 | I14: =IFERROR($G14/$E14,"") -> 0.013587441 | J14: =IFERROR($H14/$F14,"") -> 0.11258278 | K14: 0 | L14: 0 | M14: 0 | N14: 0 | O14: 1.8944731e+08 | P14: 46 | Q14: 0 | R14: 0 | S14: 0 | T14: 0 | U14: 0 | V14: 0 | W14: 0 | X14: 0 | Y14: =IFERROR($L14/$H14,"") -> 0.58823529 | Z14: =IFERROR($N14/$L14,"") -> 0.1 | AA14: =IFERROR($H14/$D14,"") | AB14: =IFERROR($L14/$D14,"") | AE14: =IFERROR($Y14,0)+ROW()/1000000 -> 0.58824929
A15: 10 | B15: СУРХОНДАРЁ ВИЛОЯТИ | C15: =IFERROR(INDEX(Справочники!$D$4:$D$21,MATCH($B15,Справочники!$B$4:$B$21,0)),"") | D15: =SUMIF(Справочники!$H$4:$H$21,$B15,Справочники!$E$4:$E$21) -> 0 | E15: 1.6585229e+10 | F15: 558 | G15: =$K15+$O15 -> 1.0837511e+09 | H15: =$L15+$P15 -> 97 | I15: =IFERROR($G15/$E15,"") -> 0.065344354 | J15: =IFERROR($H15/$F15,"") -> 0.17383513 | K15: 9.1438827e+08 | L15: 131 | M15: 9.0575483e+08 | N15: 128 | O15: 5.7548904e+08 | P15: 85 | Q15: 36126179 | R15: 8 | S15: 8633442.8 | T15: 3 | U15: 4139105.1 | V15: 2 | W15: 12772548 | X15: 5 | Y15: =IFERROR($L15/$H15,"") -> 0.18556701 | Z15: =IFERROR($N15/$L15,"") -> 0.11111111 | AA15: =IFERROR($H15/$D15,"") | AB15: =IFERROR($L15/$D15,"") | AE15: =IFERROR($Y15,0)+ROW()/1000000 -> 0.18558201
A16: 11 | B16: ТОШКЕНТ ВИЛОЯТИ | C16: =IFERROR(INDEX(Справочники!$D$4:$D$21,MATCH($B16,Справочники!$B$4:$B$21,0)),"") | D16: =SUMIF(Справочники!$H$4:$H$21,$B16,Справочники!$E$4:$E$21) -> 0 | E16: 3.6871387e+10 | F16: 842 | G16: =$K16+$O16 -> 8.8698663e+08 | H16: =$L16+$P16 -> 93 | I16: =IFERROR($G16/$E16,"") -> 0.024056232 | J16: =IFERROR($H16/$F16,"") -> 0.11045131 | K16: 0 | L16: 0 | M16: 0 | N16: 0 | O16: 1.2813068e+09 | P16: 216 | Q16: 0 | R16: 0 | S16: 0 | T16: 0 | U16: 0 | V16: 0 | W16: 0 | X16: 0 | Y16: =IFERROR($L16/$H16,"") -> 0 | Z16: =IFERROR($N16/$L16,"") | AA16: =IFERROR($H16/$D16,"") | AB16: =IFERROR($L16/$D16,"") | AE16: =IFERROR($Y16,0)+ROW()/1000000 -> 1.6e-05
A17: 12 | B17: ТОШКЕНТ ШАХРИ | C17: =IFERROR(INDEX(Справочники!$D$4:$D$21,MATCH($B17,Справочники!$B$4:$B$21,0)),"") | D17: =SUMIF(Справочники!$H$4:$H$21,$B17,Справочники!$E$4:$E$21) -> 0 | E17: 4.3531855e+10 | F17: 908 | G17: =$K17+$O17 -> 1.6257267e+09 | H17: =$L17+$P17 -> 115 | I17: =IFERROR($G17/$E17,"") -> 0.037345679 | J17: =IFERROR($H17/$F17,"") -> 0.12665198 | K17: 1.326472e+08 | L17: 33 | M17: 1.2627665e+08 | N17: 30 | O17: 1.5459964e+09 | P17: 173 | Q17: 48453884 | R17: 9 | S17: 6370552.4 | T17: 3 | U17: 0 | V17: 0 | W17: 6370552.4 | X17: 3 | Y17: =IFERROR($L17/$H17,"") -> 0 | Z17: =IFERROR($N17/$L17,"") | AA17: =IFERROR($H17/$D17,"") | AB17: =IFERROR($L17/$D17,"") | AE17: =IFERROR($Y17,0)+ROW()/1000000 -> 1.7e-05
... A19: 14 | B19: ХОРАЗМ ВИЛОЯТИ | C19: =IFERROR(INDEX(Справочники!$D$4:$D$21,MATCH($B19,Справочники!$B$4:$B$21,0)),"") | D19: =SUMIF(Справочники!$H$4:$H$21,$B19,Справочники!$E$4:$E$21) -> 0 | E19: 2.0499096e+10 | F19: 504 | G19: =$K19+$O19 -> 2.9345986e+08 | H19: =$L19+$P19 -> 49 | I19: =IFERROR($G19/$E19,"") -> 0.014315746 | J19: =IFERROR($H19/$F19,"") -> 0.097222222 | K19: 1.2207456e+08 | L19: 46 | M19: 1.0797075e+08 | N19: 37 | O19: 4.5230045e+08 | P19: 92 | Q19: 44122728 | R19: 11 | S19: 14103813 | T19: 9 | U19: 7019065.5 | V19: 2 | W19: 21122878 | X19: 11 | Y19: =IFERROR($L19/$H19,"") -> 0.46938776 | Z19: =IFERROR($N19/$L19,"") -> 0.26086957 | AA19: =IFERROR($H19/$D19,"") | AB19: =IFERROR($L19/$D19,"") | AE19: =IFERROR($Y19,0)+ROW()/1000000 -> 0.46940676
B20: ИТОГО | D20: =SUM(D6:D19) -> 0 | E20: =SUM(E6:E19) -> 2.4329876e+11 | F20: =SUM(F6:F19) -> 6312 | G20: =SUM(G6:G19) -> 6.9014395e+09 | H20: =SUM(H6:H19) -> 725 | I20: =IFERROR($G20/$E20,"") -> 0.02836611 | J20: =IFERROR($H20/$F20,"") -> 0.11486058 | K20: =SUM(K6:K19) -> 1.1882477e+09 | L20: =SUM(L6:L19) -> 166 | M20: =SUM(M6:M19) -> 7.4828599e+08 | N20: =SUM(N6:N19) -> 96 | O20: =SUM(O6:O19) -> 0 | P20: =SUM(P6:P19) -> 0 | Q20: =SUM(Q6:Q19) -> 5.7131919e+09 | R20: =SUM(R6:R19) -> 559 | ... X20: =SUM(X6:X19) -> 28 | Y20: =IFERROR($L20/$H20,"") -> 0.22896552 | Z20: =IFERROR($N20/$L20,"") -> 0.57831325 | AA20: =IFERROR($H20/$D20,"") | AB20: =IFERROR($L20/$D20,"")
B23: ОТКРЫТЬ СПИСОК КЛИЕНТОВ
B24: Область | C24: Дозв. | D24: Обещ. | E24: Опл. | F24: Не дозв. | G24: Объезд | H24: Опл. без разг. | I24: Всего
B25: АНДИЖОН ВИЛОЯТИ | C25: ▸ | D25: ▸ | E25: ▸ | F25: ▸ | G25: ▸ | I25: ▸
B26: БУХОРО ВИЛОЯТИ | C26: ▸ | D26: ▸ | E26: ▸ | F26: ▸ | G26: ▸ | I26: ▸
B27: ЖИЗЗАХ ВИЛОЯТИ | C27: ▸ | D27: ▸ | E27: ▸ | F27: ▸ | G27: ▸ | I27: ▸
B28: КАШКАДАРЁ ВИЛОЯТИ | C28: ▸ | D28: ▸ | E28: ▸ | F28: ▸ | G28: ▸ | I28: ▸
B29: КОРАКАЛПОГИСТОН РЕСПУБЛИКАСИ | C29: ▸ | D29: ▸ | E29: ▸ | F29: ▸ | G29: ▸ | I29: ▸
B30: НАВОИЙ ВИЛОЯТИ | C30: ▸ | D30: ▸ | E30: ▸ | F30: ▸ | G30: ▸ | I30: ▸
B31: НАМАНГАН ВИЛОЯТИ | C31: ▸ | D31: ▸ | F31: ▸ | G31: ▸
B32: САМАРКАНД ВИЛОЯТИ | C32: ▸ | D32: ▸ | E32: ▸ | F32: ▸ | G32: ▸ | I32: ▸
B33: СИРДАРЁ ВИЛОЯТИ | F33: ▸
B34: СУРХОНДАРЁ ВИЛОЯТИ | C34: ▸ | D34: ▸ | E34: ▸ | F34: ▸ | G34: ▸ | I34: ▸
B35: ТОШКЕНТ ВИЛОЯТИ | F35: ▸
B36: ТОШКЕНТ ШАХРИ | C36: ▸ | D36: ▸ | E36: ▸ | F36: ▸ | G36: ▸ | I36: ▸
B37: ФАРГОНА ВИЛОЯТИ | C37: ▸ | D37: ▸ | E37: ▸ | F37: ▸ | G37: ▸ | I37: ▸
B38: ХОРАЗМ ВИЛОЯТИ | C38: ▸ | D38: ▸ | E38: ▸ | F38: ▸ | G38: ▸ | I38: ▸

Sheet Отчёт_дня
A3: Дата отчёта: | C3: =Ввод!$C$2 -> 46272
A6: 1. ПОКАЗАТЕЛИ ДНЯ
A7: Портфель, сум | D7: =Ввод!$E$20 -> 2.4329876e+11
A8: Просрочка, сум | D8: =Ввод!$G$20 -> 6.9014395e+09
A9: % просрочки к портфелю | D9: =Ввод!$I$20 -> 0.02836611
A10: Просрочка, шт | D10: =Ввод!$H$20 -> 725
A11: Дозвонились, шт | D11: =Ввод!$L$20 -> 166
A12: % дозвона | D12: =Ввод!$Y$20 -> 0.22896552
A13: Обещали оплату, шт | D13: =Ввод!$N$20 -> 96
A14: Не дозвонились, шт | D14: =Ввод!$P$20 -> 559
A15: Объезд, шт | D15: =Ввод!$R$20 -> 2
A16: Оплачено за день, сум | D16: =Ввод!$W$20 -> 0
A19: 2. ДЕТАЛИЗАЦИЯ ПО ОБЛАСТЯМ
A21: Область | B21: Ответственный | C21: Сотруд- ников | D21: % дозвона | E21: Просрочка на 1 сотр. | F21: Оплачено, сум | G21: Оценка
A22: =Ввод!$B$6 -> АНДИЖОН ВИЛОЯТИ | B22: =Ввод!$C$6 | C22: =Ввод!$D$6 -> 0 | D22: =IFERROR(Ввод!$Y$6,0) -> 0 | E22: =IFERROR(Ввод!$AA$6,0) | F22: =Ввод!$W$6 -> 0 | G22: =IF(Ввод!$H$6=0,"Нет данных",IF($D22>=0.8,"Отлично",IF($D22>=0.5,"Хорошо","Требует внимания"))) -> Требует внимания
A23: =Ввод!$B$7 -> БУХОРО ВИЛОЯТИ | B23: =Ввод!$C$7 | C23: =Ввод!$D$7 -> 0 | D23: =IFERROR(Ввод!$Y$7,0) -> 0 | E23: =IFERROR(Ввод!$AA$7,0) | F23: =Ввод!$W$7 -> 0 | G23: =IF(Ввод!$H$7=0,"Нет данных",IF($D23>=0.8,"Отлично",IF($D23>=0.5,"Хорошо","Требует внимания"))) -> Требует внимания
A24: =Ввод!$B$8 -> ЖИЗЗАХ ВИЛОЯТИ | B24: =Ввод!$C$8 | C24: =Ввод!$D$8 -> 0 | D24: =IFERROR(Ввод!$Y$8,0) -> 0.39215686 | E24: =IFERROR(Ввод!$AA$8,0) | F24: =Ввод!$W$8 -> 0 | G24: =IF(Ввод!$H$8=0,"Нет данных",IF($D24>=0.8,"Отлично",IF($D24>=0.5,"Хорошо","Требует внимания"))) -> Требует внимания
A25: =Ввод!$B$9 -> КАШКАДАРЁ ВИЛОЯТИ | B25: =Ввод!$C$9 | C25: =Ввод!$D$9 -> 0 | D25: =IFERROR(Ввод!$Y$9,0) -> 0.87878788 | E25: =IFERROR(Ввод!$AA$9,0) | F25: =Ввод!$W$9 -> 0 | G25: =IF(Ввод!$H$9=0,"Нет данных",IF($D25>=0.8,"Отлично",IF($D25>=0.5,"Хорошо","Требует внимания"))) -> Отлично
A26: =Ввод!$B$10 -> КОРАКАЛПОГИСТОН РЕСПУБЛИКАСИ | B26: =Ввод!$C$10 | C26: =Ввод!$D$10 -> 0 | D26: =IFERROR(Ввод!$Y$10,0) -> 0.76923077 | E26: =IFERROR(Ввод!$AA$10,0) | F26: =Ввод!$W$10 -> 0 | G26: =IF(Ввод!$H$10=0,"Нет данных",IF($D26>=0.8,"Отлично",IF($D26>=0.5,"Хорошо","Требует внимания"))) -> Хорошо
A27: =Ввод!$B$11 -> НАВОИЙ ВИЛОЯТИ | B27: =Ввод!$C$11 | C27: =Ввод!$D$11 -> 0 | D27: =IFERROR(Ввод!$Y$11,0) -> 0.055555556 | E27: =IFERROR(Ввод!$AA$11,0) | F27: =Ввод!$W$11 -> 0 | G27: =IF(Ввод!$H$11=0,"Нет данных",IF($D27>=0.8,"Отлично",IF($D27>=0.5,"Хорошо","Требует внимания"))) -> Требует внимания
A28: =Ввод!$B$12 -> НАМАНГАН ВИЛОЯТИ | B28: =Ввод!$C$12 | C28: =Ввод!$D$12 -> 0 | D28: =IFERROR(Ввод!$Y$12,0) -> 0.48387097 | E28: =IFERROR(Ввод!$AA$12,0) | F28: =Ввод!$W$12 -> 0 | G28: =IF(Ввод!$H$12=0,"Нет данных",IF($D28>=0.8,"Отлично",IF($D28>=0.5,"Хорошо","Требует внимания"))) -> Требует внимания
A29: =Ввод!$B$13 -> САМАРКАНД ВИЛОЯТИ | B29: =Ввод!$C$13 | C29: =Ввод!$D$13 -> 0 | D29: =IFERROR(Ввод!$Y$13,0) -> 0.24590164 | E29: =IFERROR(Ввод!$AA$13,0) | F29: =Ввод!$W$13 -> 0 | G29: =IF(Ввод!$H$13=0,"Нет данных",IF($D29>=0.8,"Отлично",IF($D29>=0.5,"Хорошо","Требует внимания"))) -> Требует внимания
A30: =Ввод!$B$14 -> СИРДАРЁ ВИЛОЯТИ | B30: =Ввод!$C$14 | C30: =Ввод!$D$14 -> 0 | D30: =IFERROR(Ввод!$Y$14,0) -> 0.58823529 | E30: =IFERROR(Ввод!$AA$14,0) | F30: =Ввод!$W$14 -> 0 | G30: =IF(Ввод!$H$14=0,"Нет данных",IF($D30>=0.8,"Отлично",IF($D30>=0.5,"Хорошо","Требует внимания"))) -> Хорошо
A31: =Ввод!$B$15 -> СУРХОНДАРЁ ВИЛОЯТИ | B31: =Ввод!$C$15 | C31: =Ввод!$D$15 -> 0 | D31: =IFERROR(Ввод!$Y$15,0) -> 0.18556701 | E31: =IFERROR(Ввод!$AA$15,0) | F31: =Ввод!$W$15 -> 0 | G31: =IF(Ввод!$H$15=0,"Нет данных",IF($D31>=0.8,"Отлично",IF($D31>=0.5,"Хорошо","Требует внимания"))) -> Требует внимания
A32: =Ввод!$B$16 -> ТОШКЕНТ ВИЛОЯТИ | B32: =Ввод!$C$16 | C32: =Ввод!$D$16 -> 0 | D32: =IFERROR(Ввод!$Y$16,0) -> 0 | E32: =IFERROR(Ввод!$AA$16,0) | F32: =Ввод!$W$16 -> 0 | G32: =IF(Ввод!$H$16=0,"Нет данных",IF($D32>=0.8,"Отлично",IF($D32>=0.5,"Хорошо","Требует внимания"))) -> Требует внимания
A33: =Ввод!$B$17 -> ТОШКЕНТ ШАХРИ | B33: =Ввод!$C$17 | C33: =Ввод!$D$17 -> 0 | D33: =IFERROR(Ввод!$Y$17,0) -> 0 | E33: =IFERROR(Ввод!$AA$17,0) | F33: =Ввод!$W$17 -> 0 | G33: =IF(Ввод!$H$17=0,"Нет данных",IF($D33>=0.8,"Отлично",IF($D33>=0.5,"Хорошо","Требует внимания"))) -> Требует внимания
A34: =Ввод!$B$18 -> ФАРГОНА ВИЛОЯТИ | B34: =Ввод!$C$18 | C34: =Ввод!$D$18 -> 0 | D34: =IFERROR(Ввод!$Y$18,0) -> 0 | E34: =IFERROR(Ввод!$AA$18,0) | F34: =Ввод!$W$18 -> 0 | G34: =IF(Ввод!$H$18=0,"Нет данных",IF($D34>=0.8,"Отлично",IF($D34>=0.5,"Хорошо","Требует внимания"))) -> Требует внимания
A35: =Ввод!$B$19 -> ХОРАЗМ ВИЛОЯТИ | B35: =Ввод!$C$19 | C35: =Ввод!$D$19 -> 0 | D35: =IFERROR(Ввод!$Y$19,0) -> 0.46938776 | E35: =IFERROR(Ввод!$AA$19,0) | F35: =Ввод!$W$19 -> 0 | G35: =IF(Ввод!$H$19=0,"Нет данных",IF($D35>=0.8,"Отлично",IF($D35>=0.5,"Хорошо","Требует внимания"))) -> Требует внимания
A41: 6. ЛИДЕРЫ И ОТСТАЮЩИЕ ПО % ДОЗВОНА (по областям)
A42: Лидеры | C42: % дозвона | E42: Требуют внимания | H42: % дозвона
A43: =IFERROR(INDEX(Ввод!$B$6:$B$19,MATCH(LARGE(Ввод!$AE$6:$AE$19,1),Ввод!$AE$6:$AE$19,0)),"") -> КАШКАДАРЁ ВИЛОЯТИ | C43: =IFERROR(INDEX(Ввод!$Y$6:$Y$19,MATCH(LARGE(Ввод!$AE$6:$AE$19,1),Ввод!$AE$6:$AE$19,0)),"") -> 0.87878788 | E43: =IFERROR(INDEX(Ввод!$B$6:$B$19,MATCH(SMALL(Ввод!$AE$6:$AE$19,1),Ввод!$AE$6:$AE$19,0)),"") -> АНДИЖОН ВИЛОЯТИ | H43: =IFERROR(INDEX(Ввод!$Y$6:$Y$19,MATCH(SMALL(Ввод!$AE$6:$AE$19,1),Ввод!$AE$6:$AE$19,0)),"") -> 0
A44: =IFERROR(INDEX(Ввод!$B$6:$B$19,MATCH(LARGE(Ввод!$AE$6:$AE$19,2),Ввод!$AE$6:$AE$19,0)),"") -> КОРАКАЛПОГИСТОН РЕСПУБЛИКАСИ | C44: =IFERROR(INDEX(Ввод!$Y$6:$Y$19,MATCH(LARGE(Ввод!$AE$6:$AE$19,2),Ввод!$AE$6:$AE$19,0)),"") -> 0.76923077 | E44: =IFERROR(INDEX(Ввод!$B$6:$B$19,MATCH(SMALL(Ввод!$AE$6:$AE$19,2),Ввод!$AE$6:$AE$19,0)),"") -> БУХОРО ВИЛОЯТИ | H44: =IFERROR(INDEX(Ввод!$Y$6:$Y$19,MATCH(SMALL(Ввод!$AE$6:$AE$19,2),Ввод!$AE$6:$AE$19,0)),"") -> 0
A45: =IFERROR(INDEX(Ввод!$B$6:$B$19,MATCH(LARGE(Ввод!$AE$6:$AE$19,3),Ввод!$AE$6:$AE$19,0)),"") -> СИРДАРЁ ВИЛОЯТИ | C45: =IFERROR(INDEX(Ввод!$Y$6:$Y$19,MATCH(LARGE(Ввод!$AE$6:$AE$19,3),Ввод!$AE$6:$AE$19,0)),"") -> 0.58823529 | E45: =IFERROR(INDEX(Ввод!$B$6:$B$19,MATCH(SMALL(Ввод!$AE$6:$AE$19,3),Ввод!$AE$6:$AE$19,0)),"") -> ТОШКЕНТ ВИЛОЯТИ | H45: =IFERROR(INDEX(Ввод!$Y$6:$Y$19,MATCH(SMALL(Ввод!$AE$6:$AE$19,3),Ввод!$AE$6:$AE$19,0)),"") -> 0

Sheet Дашборд
A3: Дата отчёта: | C3: =Ввод!$C$2 -> 46272 | E3: Просрочка, сум | H3: =Ввод!$G$20 -> 6.9014395e+09
E4: Оплачено за день, сум | H4: =Ввод!$W$20 -> 0
E5: Просрочка на 1 сотрудника, шт | H5: =IFERROR(Ввод!$H$20/Ввод!$D$20,0) -> 0
A7: СВОД ПО ОБЛАСТЯМ
A8: Область | B8: Тип | C8: Сотруд- ников | D8: Портфель, сум | E8: Просрочка, сум | F8: % просрочки | G8: Просрочка, шт | H8: Дозвон, шт | I8: % дозвона | J8: Просрочка на 1 сотр. | K8: Обещали, шт | L8: Оплачено, сум | M8: Оценка | N8: Область
A9: =Ввод!$B$6 -> АНДИЖОН ВИЛОЯТИ | C9: =Ввод!$D$6 -> 0 | D9: =Ввод!$E$6 -> 2.1670184e+10 | E9: =Ввод!$G$6 -> 2.1699731e+08 | F9: =IFERROR($E9/$D9,0) -> 0.010013635 | G9: =Ввод!$H$6 -> 32 | H9: =Ввод!$L$6 -> 0 | I9: =IFERROR($H9/$G9,0) -> 0 | J9: =IFERROR($G9/$C9,0) -> 0 | K9: =Ввод!$N$6 -> 0 | L9: =Ввод!$W$6 -> 0 | M9: =IF($G9=0,"Нет данных",IF($I9>=0.8,"Отлично",IF($I9>=0.5,"Хорошо","Требует внимания"))) -> Требует внимания | N9: =IFERROR(INDEX(Справочники!$H$4:$H$21,MATCH($A9,Справочники!$B$4:$B$21,0)),"")
A10: =Ввод!$B$7 -> БУХОРО ВИЛОЯТИ | C10: =Ввод!$D$7 -> 0 | D10: =Ввод!$E$7 -> 5.1231734e+09 | E10: =Ввод!$G$7 -> 2.0266951e+08 | F10: =IFERROR($E10/$D10,0) -> 0.03955937 | G10: =Ввод!$H$7 -> 18 | H10: =Ввод!$L$7 -> 0 | I10: =IFERROR($H10/$G10,0) -> 0 | J10: =IFERROR($G10/$C10,0) -> 0 | K10: =Ввод!$N$7 -> 0 | L10: =Ввод!$W$7 -> 0 | M10: =IF($G10=0,"Нет данных",IF($I10>=0.8,"Отлично",IF($I10>=0.5,"Хорошо","Требует внимания"))) -> Требует внимания | N10: =IFERROR(INDEX(Справочники!$H$4:$H$21,MATCH($A10,Справочники!$B$4:$B$21,0)),"")
A11: =Ввод!$B$8 -> ЖИЗЗАХ ВИЛОЯТИ | C11: =Ввод!$D$8 -> 0 | D11: =Ввод!$E$8 -> 1.3904205e+10 | E11: =Ввод!$G$8 -> 2.498528e+08 | F11: =IFERROR($E11/$D11,0) -> 0.017969585 | G11: =Ввод!$H$8 -> 51 | H11: =Ввод!$L$8 -> 20 | I11: =IFERROR($H11/$G11,0) -> 0.39215686 | J11: =IFERROR($G11/$C11,0) -> 0 | K11: =Ввод!$N$8 -> 19 | L11: =Ввод!$W$8 -> 0 | M11: =IF($G11=0,"Нет данных",IF($I11>=0.8,"Отлично",IF($I11>=0.5,"Хорошо","Требует внимания"))) -> Требует внимания | N11: =IFERROR(INDEX(Справочники!$H$4:$H$21,MATCH($A11,Справочники!$B$4:$B$21,0)),"")
A12: =Ввод!$B$9 -> КАШКАДАРЁ ВИЛОЯТИ | C12: =Ввод!$D$9 -> 0 | D12: =Ввод!$E$9 -> 1.2186569e+10 | E12: =Ввод!$G$9 -> 2.0555796e+08 | F12: =IFERROR($E12/$D12,0) -> 0.016867583 | G12: =Ввод!$H$9 -> 33 | H12: =Ввод!$L$9 -> 29 | I12: =IFERROR($H12/$G12,0) -> 0.87878788 | J12: =IFERROR($G12/$C12,0) -> 0 | K12: =Ввод!$N$9 -> 18 | L12: =Ввод!$W$9 -> 0 | M12: =IF($G12=0,"Нет данных",IF($I12>=0.8,"Отлично",IF($I12>=0.5,"Хорошо","Требует внимания"))) -> Отлично | N12: =IFERROR(INDEX(Справочники!$H$4:$H$21,MATCH($A12,Справочники!$B$4:$B$21,0)),"")
A13: =Ввод!$B$10 -> КОРАКАЛПОГИСТОН РЕСПУБЛИКАСИ | C13: =Ввод!$D$10 -> 0 | D13: =Ввод!$E$10 -> 1.1119545e+10 | E13: =Ввод!$G$10 -> 2.5963958e+08 | F13: =IFERROR($E13/$D13,0) -> 0.023349839 | G13: =Ввод!$H$10 -> 26 | H13: =Ввод!$L$10 -> 20 | I13: =IFERROR($H13/$G13,0) -> 0.76923077 | J13: =IFERROR($G13/$C13,0) -> 0 | K13: =Ввод!$N$10 -> 4 | L13: =Ввод!$W$10 -> 0 | M13: =IF($G13=0,"Нет данных",IF($I13>=0.8,"Отлично",IF($I13>=0.5,"Хорошо","Требует внимания"))) -> Хорошо | N13: =IFERROR(INDEX(Справочники!$H$4:$H$21,MATCH($A13,Справочники!$B$4:$B$21,0)),"")
A14: =Ввод!$B$11 -> НАВОИЙ ВИЛОЯТИ | C14: =Ввод!$D$11 -> 0 | D14: =Ввод!$E$11 -> 6.476845e+09 | E14: =Ввод!$G$11 -> 1.0708535e+08 | F14: =IFERROR($E14/$D14,0) -> 0.016533567 | G14: =Ввод!$H$11 -> 18 | H14: =Ввод!$L$11 -> 1 | I14: =IFERROR($H14/$G14,0) -> 0.055555556 | J14: =IFERROR($G14/$C14,0) -> 0 | K14: =Ввод!$N$11 -> 1 | L14: =Ввод!$W$11 -> 0 | M14: =IF($G14=0,"Нет данных",IF($I14>=0.8,"Отлично",IF($I14>=0.5,"Хорошо","Требует внимания"))) -> Требует внимания | N14: =IFERROR(INDEX(Справочники!$H$4:$H$21,MATCH($A14,Справочники!$B$4:$B$21,0)),"")
A15: =Ввод!$B$12 -> НАМАНГАН ВИЛОЯТИ | C15: =Ввод!$D$12 -> 0 | D15: =Ввод!$E$12 -> 1.4729616e+10 | E15: =Ввод!$G$12 -> 5.9799851e+08 | F15: =IFERROR($E15/$D15,0) -> 0.040598377 | G15: =Ввод!$H$12 -> 62 | H15: =Ввод!$L$12 -> 30 | I15: =IFERROR($H15/$G15,0) -> 0.48387097 | J15: =IFERROR($G15/$C15,0) -> 0 | K15: =Ввод!$N$12 -> 30 | L15: =Ввод!$W$12 -> 0 | M15: =IF($G15=0,"Нет данных",IF($I15>=0.8,"Отлично",IF($I15>=0.5,"Хорошо","Требует внимания"))) -> Требует внимания | N15: =IFERROR(INDEX(Справочники!$H$4:$H$21,MATCH($A15,Справочники!$B$4:$B$21,0)),"")
A16: =Ввод!$B$13 -> САМАРКАНД ВИЛОЯТИ | C16: =Ввод!$D$13 -> 0 | D16: =Ввод!$E$13 -> 1.6007859e+10 | E16: =Ввод!$G$13 -> 2.6721243e+08 | F16: =IFERROR($E16/$D16,0) -> 0.016692577 | G16: =Ввод!$H$13 -> 61 | H16: =Ввод!$L$13 -> 15 | I16: =IFERROR($H16/$G16,0) -> 0.24590164 | J16: =IFERROR($G16/$C16,0) -> 0 | K16: =Ввод!$N$13 -> 15 | L16: =Ввод!$W$13 -> 0 | M16: =IF($G16=0,"Нет данных",IF($I16>=0.8,"Отлично",IF($I16>=0.5,"Хорошо","Требует внимания"))) -> Требует внимания | N16: =IFERROR(INDEX(Справочники!$H$4:$H$21,MATCH($A16,Справочники!$B$4:$B$21,0)),"")
A17: =Ввод!$B$14 -> СИРДАРЁ ВИЛОЯТИ | C17: =Ввод!$D$14 -> 0 | D17: =Ввод!$E$14 -> 7.1897605e+09 | E17: =Ввод!$G$14 -> 97690450 | F17: =IFERROR($E17/$D17,0) -> 0.013587441 | G17: =Ввод!$H$14 -> 17 | H17: =Ввод!$L$14 -> 10 | I17: =IFERROR($H17/$G17,0) -> 0.58823529 | J17: =IFERROR($G17/$C17,0) -> 0 | K17: =Ввод!$N$14 -> 1 | L17: =Ввод!$W$14 -> 0 | M17: =IF($G17=0,"Нет данных",IF($I17>=0.8,"Отлично",IF($I17>=0.5,"Хорошо","Требует внимания"))) -> Хорошо | N17: =IFERROR(INDEX(Справочники!$H$4:$H$21,MATCH($A17,Справочники!$B$4:$B$21,0)),"")
A18: =Ввод!$B$15 -> СУРХОНДАРЁ ВИЛОЯТИ | C18: =Ввод!$D$15 -> 0 | D18: =Ввод!$E$15 -> 1.6585229e+10 | E18: =Ввод!$G$15 -> 1.0837511e+09 | F18: =IFERROR($E18/$D18,0) -> 0.065344354 | G18: =Ввод!$H$15 -> 97 | H18: =Ввод!$L$15 -> 18 | I18: =IFERROR($H18/$G18,0) -> 0.18556701 | J18: =IFERROR($G18/$C18,0) -> 0 | K18: =Ввод!$N$15 -> 2 | L18: =Ввод!$W$15 -> 0 | M18: =IF($G18=0,"Нет данных",IF($I18>=0.8,"Отлично",IF($I18>=0.5,"Хорошо","Требует внимания"))) -> Требует внимания | N18: =IFERROR(INDEX(Справочники!$H$4:$H$21,MATCH($A18,Справочники!$B$4:$B$21,0)),"")
A19: =Ввод!$B$16 -> ТОШКЕНТ ВИЛОЯТИ | C19: =Ввод!$D$16 -> 0 | D19: =Ввод!$E$16 -> 3.6871387e+10 | E19: =Ввод!$G$16 -> 8.8698663e+08 | F19: =IFERROR($E19/$D19,0) -> 0.024056232 | G19: =Ввод!$H$16 -> 93 | H19: =Ввод!$L$16 -> 0 | I19: =IFERROR($H19/$G19,0) -> 0 | J19: =IFERROR($G19/$C19,0) -> 0 | K19: =Ввод!$N$16 -> 0 | L19: =Ввод!$W$16 -> 0 | M19: =IF($G19=0,"Нет данных",IF($I19>=0.8,"Отлично",IF($I19>=0.5,"Хорошо","Требует внимания"))) -> Требует внимания | N19: =IFERROR(INDEX(Справочники!$H$4:$H$21,MATCH($A19,Справочники!$B$4:$B$21,0)),"")
A20: =Ввод!$B$17 -> ТОШКЕНТ ШАХРИ | C20: =Ввод!$D$17 -> 0 | D20: =Ввод!$E$17 -> 4.3531855e+10 | E20: =Ввод!$G$17 -> 1.6257267e+09 | F20: =IFERROR($E20/$D20,0) -> 0.037345679 | G20: =Ввод!$H$17 -> 115 | H20: =Ввод!$L$17 -> 0 | I20: =IFERROR($H20/$G20,0) -> 0 | J20: =IFERROR($G20/$C20,0) -> 0 | K20: =Ввод!$N$17 -> 0 | L20: =Ввод!$W$17 -> 0 | M20: =IF($G20=0,"Нет данных",IF($I20>=0.8,"Отлично",IF($I20>=0.5,"Хорошо","Требует внимания"))) -> Требует внимания | N20: =IFERROR(INDEX(Справочники!$H$4:$H$21,MATCH($A20,Справочники!$B$4:$B$21,0)),"")
A21: =Ввод!$B$18 -> ФАРГОНА ВИЛОЯТИ | C21: =Ввод!$D$18 -> 0 | D21: =Ввод!$E$18 -> 1.7403439e+10 | E21: =Ввод!$G$18 -> 806811380 | F21: =IFERROR($E21/$D21,0) -> 0.046359308 | G21: =Ввод!$H$18 -> 53 | H21: =Ввод!$L$18 -> 0 | I21: =IFERROR($H21/$G21,0) -> 0 | J21: =IFERROR($G21/$C21,0) -> 0 | K21: =Ввод!$N$18 -> 0 | L21: =Ввод!$W$18 -> 0 | M21: =IF($G21=0,"Нет данных",IF($I21>=0.8,"Отлично",IF($I21>=0.5,"Хорошо","Требует внимания"))) -> Требует внимания | N21: =IFERROR(INDEX(Справочники!$H$4:$H$21,MATCH($A21,Справочники!$B$4:$B$21,0)),"")
A22: =Ввод!$B$19 -> ХОРАЗМ ВИЛОЯТИ | C22: =Ввод!$D$19 -> 0 | D22: =Ввод!$E$19 -> 2.0499096e+10 | E22: =Ввод!$G$19 -> 2.9345986e+08 | F22: =IFERROR($E22/$D22,0) -> 0.014315746 | G22: =Ввод!$H$19 -> 49 | H22: =Ввод!$L$19 -> 23 | I22: =IFERROR($H22/$G22,0) -> 0.46938776 | J22: =IFERROR($G22/$C22,0) -> 0 | K22: =Ввод!$N$19 -> 6 | L22: =Ввод!$W$19 -> 0 | M22: =IF($G22=0,"Нет данных",IF($I22>=0.8,"Отлично",IF($I22>=0.5,"Хорошо","Требует внимания"))) -> Требует внимания | N22: =IFERROR(INDEX(Справочники!$H$4:$H$21,MATCH($A22,Справочники!$B$4:$B$21,0)),"")
A27: ИТОГО | C27: =SUM(C9:C26) -> 0 | D27: =SUM(D9:D26) -> 2.4329876e+11 | E27: =SUM(E9:E26) -> 6.9014395e+09 | F27: =IFERROR($E27/$D27,0) -> 0.02836611 | G27: =SUM(G9:G26) -> 725 | H27: =SUM(H9:H26) -> 166 | I27: =IFERROR($H27/$G27,0) -> 0.22896552 | J27: =IFERROR($G27/$C27,0) -> 0 | K27: =SUM(K9:K26) -> 96 | L27: =SUM(L9:L26) -> 0 | M27: =IF($I27>=0.8,"Отлично",IF($I27>=0.5,"Хорошо","Требует внимания")) -> Требует внимания

Sheet Справочники
A3: № | B3: Филиал (точно как в файлах) | C3: Тип | D3: Ответственный (Ф.И.О.) | E3: Кол-во сотрудников | F3: Телефон | G3: Норматив % просрочки | H3: Область | K3: Оценка эффективности | N3: Статус проверки
A4: 1 | B4: Урганч филиали | C4: Регион | D4: — впишите — | E4: 0 | F4: +998 __ ___ __ __ | G4: 0.05 | H4: ХОРАЗМ ВИЛОЯТИ | K4: Отлично (≥80% дозвона) | N4: Не проверено
A5: 2 | B5: Самарқанд филиали | C5: Регион | D5: — впишите — | E5: 0 | F5: +998 __ ___ __ __ | G5: 0.05 | H5: САМАРКАНД ВИЛОЯТИ | K5: Хорошо (50–79%) | N5: Проверено куратором
A6: 3 | B6: Денов филиали | C6: Регион | D6: — впишите — | E6: 0 | F6: +998 __ ___ __ __ | G6: 0.05 | H6: СУРХОНДАРЁ ВИЛОЯТИ | K6: Требует внимания (<50%)
A7: 4 | B7: Жиззах филиали | C7: Регион | D7: — впишите — | E7: 0 | F7: +998 __ ___ __ __ | G7: 0.05 | H7: ЖИЗЗАХ ВИЛОЯТИ | K7: Нет данных
A8: 5 | B8: Андижон филиали | C8: Регион | D8: — впишите — | E8: 0 | F8: +998 __ ___ __ __ | G8: 0.05 | H8: АНДИЖОН ВИЛОЯТИ
A9: 6 | B9: Наманган филиали | C9: Регион | D9: — впишите — | E9: 0 | F9: +998 __ ___ __ __ | G9: 0.05 | H9: НАМАНГАН ВИЛОЯТИ
A10: 7 | B10: Фарғона филиали | C10: Регион | D10: — впишите — | E10: 0 | F10: +998 __ ___ __ __ | G10: 0.05 | H10: ФАРГОНА ВИЛОЯТИ
A11: 8 | B11: Қарши филиали | C11: Регион | D11: — впишите — | E11: 0 | F11: +998 __ ___ __ __ | G11: 0.05 | H11: КАШКАДАРЁ ВИЛОЯТИ
A12: 9 | B12: Нукус филиали | C12: Регион | D12: — впишите — | E12: 0 | F12: +998 __ ___ __ __ | G12: 0.05 | H12: КОРАКАЛПОГИСТОН РЕСПУБЛИКАСИ
A13: 10 | B13: Навоий филиали | C13: Регион | D13: — впишите — | E13: 0 | F13: +998 __ ___ __ __ | G13: 0.05 | H13: НАВОИЙ ВИЛОЯТИ
A14: 11 | B14: Бухоро филиали | C14: Регион | D14: — впишите — | E14: 0 | F14: +998 __ ___ __ __ | G14: 0.05 | H14: БУХОРО ВИЛОЯТИ
A15: 12 | B15: Термиз филиали | C15: Регион | D15: — впишите — | E15: 0 | F15: +998 __ ___ __ __ | G15: 0.05 | H15: СУРХОНДАРЁ ВИЛОЯТИ
A16: 13 | B16: Гулистон филиали | C16: Регион | D16: — впишите — | E16: 0 | F16: +998 __ ___ __ __ | G16: 0.05 | H16: СИРДАРЁ ВИЛОЯТИ
A17: 14 | B17: Олмалиқ филиали | C17: Регион | D17: — впишите — | E17: 0 | F17: +998 __ ___ __ __ | G17: 0.05 | H17: ТОШКЕНТ ВИЛОЯТИ
A18: 15 | B18: Чирчик филиали | C18: Регион | D18: — впишите — | E18: 0 | F18: +998 __ ___ __ __ | G18: 0.05 | H18: ТОШКЕНТ ВИЛОЯТИ
A19: 16 | B19: Янги Йул филиали | C19: Регион | D19: — впишите — | E19: 0 | F19: +998 __ ___ __ __ | G19: 0.05 | H19: ТОШКЕНТ ВИЛОЯТИ
... A21: 18 | B21: BOSH OFIS | C21: Центральное | D21: — впишите — | E21: 0 | F21: +998 __ ___ __ __ | G21: 0.05 | H21: ТОШКЕНТ ШАХРИ
B22: ИТОГО | E22: =SUM(E4:E21) -> 0

Sheet Дозвонились
A1: ← Вернуться в отчёт
A2: Область | B2: Филиал | C2: Группа | D2: Код клиента | E2: Клиент | F2: Номер телефона | G2: Адрес | H2: Кол-во просроченных дней | I2: Итого просрочка | J2: Оплата | K2: Izoh
A3: АНДИЖОН ВИЛОЯТИ | C3: Обещал | D3: Кр-99062885-1 | E3: KASIMXODJAYEV ABDUXALIL ABDUMAJITOVICH | F3: +998916208060 SMS O’ZI, 998914781293 SMS AYOLI, 998916028060 SMS UY, 998976208060 SMS O’ZI2, | G3: ANDIJON VILOYATI ANDIJON SHAHAR MAYDONBOZOR MFY YAXSHI KO’CHASI 61/59-UY | H3: 10 | I3: 14507308 | K3: Va'da berdi | 1-2 kunda hal qiladi | 4383561.643835616 | 10123746.15
A4: АНДИЖОН ВИЛОЯТИ | C4: Обещал | D4: Кр-99058759-1 | E4: RAXMANOV DILSHODBEK TO’XTASINOVICH | F4: 998889930005 SMS OZI, 998955173700 SMS AYOLI, 998979970184 SMS UKASI, 998949300052 SMS OZI 2, | G4: ANDIJON VILOYATI QO’RG’ONTEPA TUMANI DEXQONCHEK MFY ERKIN IJOD KO’CHASI 74-UY | H4: 13 | I4: 13767147 | K4: Va'da berdi | 25 kunga hal qiladi | 5342465.7534246575 | 8424681.47
A5: АНДИЖОН ВИЛОЯТИ | C5: Обещал | D5: Кр-99047889-1 | E5: SHIRMATOV MUXAMMADOZOD QODIRALI O’G’LI | F5: +998911715500 SMS O’ZI, 998772495500 SMS OG’LI, 998972225500 SMS UY, 998998173300 SMS NEVARASI, | G5: ANDIJON VILOYATI ANDIJON SHAHAR ISTIQLOL MFY OBOD 1-TOR KO’CHASI 5-UY | H5: 13 | I5: 12856969 | K5: Va'da berdi | 25 kunga hal qiladi | 4630136.98630137 | 8226832.27
A6: АНДИЖОН ВИЛОЯТИ | C6: Обещал | D6: Кр-99060389-1 | E6: SULTANOVA XAMIDA ULJABEKOVNA | F6: +998934141584 SMS O’ZI, 998973243443 SMS KELINI, 998979753443 SMS O’G’LI, 998993200858 SMS XO’JAYNI, | G6: Andijon viloyati Andijon shahar Sadoqat MFY Fuzuliy ko’chasi 49-uy | H6: 10 | I6: 12724541 | K6: Va'da berdi | dushanba seshanba kuni | 3835616.438356164 | 8888924.39
A7: АНДИЖОН ВИЛОЯТИ | C7: Обещал | D7: Кр-99061048-1 | E7: ORIFJANOV NODIRBEK OMANJANOVICH | F7: 998916841884 uzi, 998335177797 ayoli, 998944870903 onasi, | G7: ANDIJON VILOYATI QO’RG’ONTEPA TUMANI SAVAY YANGI BO’STON MFY BARKAMOL KO’CHASI 58-UY | H7: 13 | I7: 11960620 | K7: Va'da berdi | shu hafta hal qilib berdi | 4273972.602739726 | 7686647.26
A8: АНДИЖОН ВИЛОЯТИ | C8: Обещал | D8: Кр-99061572-1 | E8: AXMEDOV JAVOHIRBEK TOJIDIN O’G’LI | F8: 998907726810 узи, 998910676800 аели, 998882357585 укаси, 998974054333 укаси, | G8: ANDIJON VILOYATI ANDIJON TUMANI NURAFSHON MFY YANGI TURMUSH KO’CHASI 69A-UY | H8: 13 | I8: 11959423 | K8: Va'da berdi | 25 kunga hal qiladi | 4273972.602739726 | 7685450.86
A9: АНДИЖОН ВИЛОЯТИ | C9: Обещал | D9: Кр-99024542-1 | E9: XALMATOV ADIL PAZILOVICH | F9: 77-123-13-10 SMS OZI, 98-707-22-92 SMS OZI, 90-541-13-18 SMS OZI, 998880072292 УГЛИ шохрух, | G9: ANDIJON VILOYATI ANDIJON SHAHAR ISLOMOBOD MFY 7-TOR MUXITDINOV 21-UY | H9: 8 | I9: 11534220 | K9: Va'da berdi | 25 kuni tolaydi | 5041095.890410959 | 6493123.81
A10: АНДИЖОН ВИЛОЯТИ | C10: Обещал | D10: Кр-99063922-3 | E10: RUZIYEVA RANO KABILOVNA | F10: +998905437075 SMS O’ZI, 998902597075 SMS UY, 998906257691 SMS OPASI, 998921519222 SMS QIZI, | G10: ANDIJON VILOYATI ANDIJON SHAHAR O’ZBEGIM MFY, A. MUSAYE KO’CHASI 4-UY 31-XONADON | H10: 10 | I10: 11102362 | K10: Va'da berdi | dushanba kuni tolaydi | 3835616.438356164 | 7266745.79
A11: АНДИЖОН ВИЛОЯТИ | C11: Обещал | D11: Кр-99063424-2 | E11: TURSUNOV RAXMATILLO IKRAMJANOVICH | F11: 998702250075 SMS OZI, 998886020075 SMS UKASI2, 998889248080 SMS AYOLI, 998970711009 SMS UKASI, | G11: ANDIJON VILOYATI QO’RG’ONTEPA TUMANI | H11: 10 | I11: 10783206 | K11: Va'da berdi | 25 kuni tolaydi | 3013698.6301369863 | 7769507.51
A12: АНДИЖОН ВИЛОЯТИ | C12: Обещал | D12: Кр-99033455-2 | E12: ABDULAZIZOV NOZIMJON NASIBJONOVICH | F12: 998934104844 SMS O’ZI, 998000048002 SMS O’ZI 2, 998932544648 SMS AYOLI, 998936913859 SMS XAMKASBI, 998948770475 SMS otasi new , | G12: ANDIJON VILOYATI PAXTAOBOD TUMANI MA’RIFAT MFY,MA’RIFAT KO’CHASI 47-UY | H12: 6 | I12: 10697383 | K12: Va'da berdi | 1-2 kunda hal qiladi | 2465753.4246575343 | 8231629.93
A13: АНДИЖОН ВИЛОЯТИ | C13: Дозвон | D13: Кр-99039306-1 | E13: ODILJONOV ABDULAZIZ UMIDJON O’G’LI | F13: 998934153932 SMS OZI, 998937810042 SMS ONASI, 998937810094 SMS OTASI, 998941051030 SMS AKASI, | G13: ANDIJON VILOYATI ANDIJON SHAHAR DALVARZIN MFY A.ASHUROV 3-TOR KO’CHASI 4-UY | H13: 14 | I13: 10688765 | J13: 3835616 | K13: To'ladi | 3835616.4383561644 | 6853149.05
A14: АНДИЖОН ВИЛОЯТИ | C14: Обещал | D14: Кр-99062998-1 | E14: TURDIMAMATOV ERKINJON ABDUMANNABOVICH | F14: +998880040107 SMS O’ZI, 998884772717 SMS O’G’LI, 998914870066 SMS AYOLI, 998941068585 SMS QIZI, | G14: ANDIJON VILOYATI BO’STON TUMANI MADANIYAT MFY, TINCHLIK KO’CHASI 3-UY | H14: 10 | I14: 10186881 | K14: Va'da berdi | dushanba kuni tolaydi | 3287671.2328767125 | 6899210.02
A15: АНДИЖОН ВИЛОЯТИ | C15: Обещал | D15: Кр-99057627-1 | E15: ABDUGANIYEVA MATLUBAXON XXX | F15: 998911757604 SMS OZI, 998902011084 SMS OGLI, 998910611084 SMS KELIMI, 998907620065 SMS QUDASI, | G15: ANDIJON VILOYATI ANDIJON SHAHAR QORATUT MFY 5-KICHIK NOXIYA KO’CHASI 17-UY, 78-XONADON | H15: 13 | I15: 9732853.8 | K15: Va'da berdi | shu hafta hal qilib berdi | 4630136.98630137 | 5102716.8
A16: АНДИЖОН ВИЛОЯТИ | C16: Обещал | D16: Кр-99063505-1 | E16: QORABOYEV XURSANBEK XXX | F16: +998950760759 SMS O’ZI, 998937805535 SMS QIZI, 998947861300 SMS O’G’LI, 998948630360 SMS AYOLI, 998932428771 SMS Tolovchi Azamat , | G16: ANDIJON VILOYATI ASAKA TUMANI NAMUNA BO’STON MFY QIPCHOQ KO’CHASI 53-UY | H16: 10 | I16: 9187621.6 | K16: Va'da berdi | 18-19 kuni tolaydi | 3835616.438356164 | 5352005.14
A17: АНДИЖОН ВИЛОЯТИ | C17: Обещал | D17: Кр-99033808-2 | E17: NASIRDINOV MANOPJON PATTAYEVICH | F17: 998931053080 SMS O’ZI meva sotadi , 998900000000 SMS, +998916126328 SMS O’ZI, 998916031864 SMS O’ZI2, 998943877760 SMS O’G’LI, | G17: ANDIJON VILOYATI ANDIJON TUMANI GUMBAZ MFY SHODIYONA KO’CHASI 65-UY | H17: 10 | I17: 9130923.9 | K17: Va'da berdi | 25 gacha hal qiladi | 2739726.02739726 | 6391197.88
A18: АНДИЖОН ВИЛОЯТИ | C18: Обещал | D18: Кр-99057460-1 | E18: ONORBOY O’G’LI PULATJON XXX | F18: 998953135155 SMS UZI, 998954616995 SMS AYOLI, 998902025254 SMS AKASI, 998772639874 SMS OPASI, | G18: ANDIJON VILOYATI QO’RG’ONTEPA TUMANI DARDOK, NAVOIY MFY YANGI OBOD KO’CHASI 334-UY | H18: 10 | I18: 9110715.3 | K18: Va'da berdi | oyni oxirigacha hal qiladi | 2739726.02739726 | 6370989.29
A19: АНДИЖОН ВИЛОЯТИ | C19: Обещал | D19: Кр-99062903-1 | E19: BAZARBAYEV ISMOILJON IBRAXIMOVICH | F19: +998902581505 SMS O’ZI, 998774300260 SMS AYOLI, 998932477040 SMS UY, 998943338444 SMS O’ZI 2, | G19: ANDIJON VILOYATI ANDIJON SHAHAR XAMDO’STLIK MFY IFTIXOR KO’CHASI 64-UY | H19: 10 | I19: 9070252.6 | K19: Va'da berdi | 19-20 kuni hal qiladi | 3287671.2328767125 | 5782581.32
A20: АНДИЖОН ВИЛОЯТИ | C20: Обещал | D20: Кр-99061829-1 | E20: JO’RAYEV BAXTIYAR BAZAROVICH | F20: 998994380553 ozi, 998944172190 ayoli, 998500450753 ogli, | G20: Манзил: ANDIJON VILOYATI ASAKA TUMANI FAROVON MFY UZUN KO’CHASI 64-UY | H20: 10 | I20: 9054359.3 | K20: Va'da berdi | dushanba kuni tolaydi | 2739726.02739726 | 6314633.3
A21: АНДИЖОН ВИЛОЯТИ | C21: Обещал | D21: Кр-99050885-1 | E21: TAYLAKOVA MA’MURAXON NEMATJANOVNA | F21: 998501951880 SMS OZI, 998941173187 SMS UAKSI, 998936318477 SMS SINGLISI, 998970174417 SMS KELINI, | G21: ANDIJON VILOYATI ANDIJON SHAHAR BUNYODKOR MFY QO’SH ARIQ DAXASI 46-UY 31-XONADON | H21: 10 | I21: 9000036.9 | K21: Va'da berdi | dushanba seshanba kuni | 2739726.02739726 | 6260310.86
A22: АНДИЖОН ВИЛОЯТИ | C22: Обещал | D22: Кр-99044950-1 | E22: MAMAYUNUSOV SOBIRJON YUSUPOVICH | F22: +998903831002 SMS O’ZI, 998500448004 SMS O’ZI2, 998902202308 SMS QIZI, 998910697782 SMS XO’JAYNI, | G22: АНДИЖОН ВИЛОЯТИ МАРХАМАТ ТУМАНИ ГУЛИСТОН МФЙ, ФИДОКОР КЎЧАСИ, uy:Р/С | H22: 13 | I22: 8994448.5 | K22: Va'da berdi | shu hafta hal qilib berdi | 3205479.452054795 | 5788969.04
A23: АНДИЖОН ВИЛОЯТИ | C23: Обещал | D23: Кр-99063433-1 | E23: MAMIROV SHAVKATBEK BURIBAYEVICH | F23: +998914753616 SMS O’ZI, 998774111767 SMS AYOLI, 998902076067 SMS KELINI, 998905536067 SMS O’G’LI, | G23: ANDIJON VILOYATI ANDIJON TUMANI TOSHLOQ MFY, MIRZA KO’CHASI 798-UY | H23: 10 | I23: 8973303.2 | K23: Va'da berdi | oyni oxirigacha hal qiladi | 2739726.02739726 | 6233577.22
A24: АНДИЖОН ВИЛОЯТИ | C24: Обещал | D24: Кр-99033504-1 | E24: NIYAZOV XAYBATULLA BURXANOVICH | F24: 998979926505 SMS OZI, 998501881794 SMS O'G'LI, 998951679511 SMS KELINI, 998507199794 SMS QIZI, | G24: ANDIJON VILOYATI ASAKA TUMANI QADRIYAT MFY HUMO KO’CHASI 39-UY 28- XONADON | H24: 10 | I24: 8118559.8 | K24: Va'da berdi | 25 gacha hal qiladi | 2465753.4246575343 | 5652806.42
A25: АНДИЖОН ВИЛОЯТИ | C25: Обещал | D25: Кр-99039487-1 | E25: USMANOV RAXMANALI XXX | F25: 998507778257 SMS OZI, 998949595701 SMS AYOLI, 998330880202 SMS OGLI, 998505081800 SMS KELINI, | G25: ANDIJON VILOYATI JALOLQUDUQ TUMANI OLMAZOR MFY OTASHKALB KO’CHASI 26-UY | H25: 7 | I25: 7796182.4 | K25: Va'da berdi | oyni oxirigacha hal qiladi | 1917808.2191780822 | 5878374.15
... A68: АНДИЖОН ВИЛОЯТИ | C68: Обещал | D68: Кр-99063829-1 | E68: MIRZAYEV ABDULAZIZ RUSTAMOVICH | F68: 998773674777 SMS ONASI, 998940207105 SMS UZI, 998970610099 SSM AKASI, 998990723095 SMS DOSTI, | G68: Quvvatmurod MFY, Dilkushod ko’chasi, 139-uy | H68: 3 | I68: 3406936.5 | K68: Va'da berdi | akasi oldi aytib qoyadi ekan | 205479.45205479453 | 3201457
A69: АНДИЖОН ВИЛОЯТИ | C69: Дозвон | D69: Кр-99039609-1 | E69: TOJIDINOVA MUXARRAMXON KOBULOVNA | F69: 998940331487 SMS OZI, 998950978615 SMS XOJAYINI, 998903870911 SMS OGLI, 998934168183 SMS AKASI, | G69: ANDIJON VILOYATI MARXAMAT TUMANI MIRISHKOLAR MFY, DORBOZ KO’CHASI 45-UY | H69: 3 | I69: 3360170 | J69: 410958 | K69: To'ladi | 410958.90410958906 | 2949211.13
A70: АНДИЖОН ВИЛОЯТИ | C70: Обещал | D70: Кр-99040988-1 | E70: ISAQJONOV PAXLAVONJON XUSNIDDIN O’G’LI | F70: +998888008486 SMS O’ZI, 998770009233 SMS UKASI, 998991498699 SMS AYOLI, | G70: ТОПТИҚ МФЙ, ТОПТИҚ КЎЧАСИ, uy:Р/С | H70: 15 | I70: 3315627.6 | K70: Va'da berdi | 25 kunga hal qiladi | 1232876.7123287672 | 2082750.87
A71: АНДИЖОН ВИЛОЯТИ | C71: Обещал | D71: Кр-99037428-1 | E71: TOLIPOV MUHIDDIN AVAZJON O’G’LI | F71: 998505111153 SMS UZI , 998995001004 SMS OZI 2, 998911717258 SMS ISHXONASI, 998998677258 SMS AYOLI, | G71: ANDIJON VILOYATI BULOQBOSHI TUMANI FAROVON MFY OXANGARON KO’CHASI 46-UY | H71: 1 | I71: 3247405.4 | K71: Va'da berdi | shu hafta hal qiladi | 136986.301369863 | 3110419.08
A72: АНДИЖОН ВИЛОЯТИ | C72: Обещал | D72: Кр-99046070-1 | E72: MADAMINOV UMIDILLO MANSURJON O’G’LI | F72: +998993039777 SMS O’ZI, 998950549306 SMS AYOLI, 998979959266 SMS UKASI, 998994069576 SMS ONASI, | G72: Andijon viloyati Paxtaobod tumani Soybo’yi MFY Soybo’yi ko’chasi, 40-yu | H72: 10 | I72: 3192409.6 | K72: Va'da berdi | dushanba seshanba kuni | 2191780.821917808 | 1000628.83
A73: АНДИЖОН ВИЛОЯТИ | C73: Обещал | D73: Кр-99040884-2 | E73: ABDILAJONOV LATIPJON XXX | F73: +998950121049 SMS O’ZI, 998871087272 SMS O’G’LI, 998936770060 SMS NABIRASI, 998955801953 SMS AYOLI, | G73: ХЎЖАТЕПА МФЙ, МАШИНАСОЗЛАР КЎЧАСИ, uy:Р/С | H73: 14 | I73: 3101599 | K73: Va'da berdi | shu hafta hal qilib berdi | 2684931.506849315 | 416667.49
A74: АНДИЖОН ВИЛОЯТИ | C74: Обещал | D74: Кр-99063829-2 | E74: MIRZAYEV ABDULAZIZ RUSTAMOVICH | F74: 998773674777 SMS ONASI, 998940207105 SMS UZI, 998970610099 SSM AKASI, 998990723095 SMS DOSTI, | G74: Quvvatmurod MFY, Dilkushod ko’chasi, 139-uy | H74: 3 | I74: 2725548.6 | K74: Va'da berdi | akasi oldi aytib qoyadi ekan | 164383.56164383562 | 2561165
A75: АНДИЖОН ВИЛОЯТИ | C75: Обещал | D75: Кр-99027758-1 | E75: TO’LANBOYEV DONIYORBEK BAXTIYORJON O’G’LI | F75: 91-137-25-32 SMS O'ZI, 93-413-04-41 SMS AKASI бегона, 93-436-04-41 SMS OWNASI, 33-711-02-00 SMS BOLLARI, 998882341189 SMS onasi new, 998934364004 SMS new ozi , 998937891414 SMS ayoli (begona tek qlinmasin!!!!), 998934360440 SMS ozi new, 998882341189 SMS onasi new, | G75: ANDIJON VILOYATI ANDIJON SHAHAR BOG’ISHAMOL MFY K. DJABBAROV KO’CHASI 5-UY | H75: 3 | I75: 2683298 | K75: Va'da berdi | 20 kunga hal qiladi | 410958.90410958906 | 2272339.07
A76: АНДИЖОН ВИЛОЯТИ | C76: Обещал | D76: Кр-99038903-1 | E76: G’OFUROVA SANTALATXON TOXIRJON QIZI | F76: 998942572820 SMS OZI , 998931161001 SMS OZI 2 begona , 998935511000 SMS QAYNI SINGLISI, 998939856162 SMS QAYSINI, | G76: ANDIJON VILOYATI ANDIJON TUMANI DARXON MFY, ZAROBOD KO’CHASI 91-UY | H76: 1 | I76: 2622309.2 | K76: Va'da berdi | shu hafta hal qiladi | 109589.04109589041 | 2512720.12
A77: АНДИЖОН ВИЛОЯТИ | C77: Обещал | D77: Кр-99039608-1 | E77: FAXRUTDINOV FAZLITDIN XAYBATULLAYEVICH | F77: 998936926077 SMS OZI, 998951175010 SMS OGLI, 998977712560 SMS OGLI2, | G77: ANDIJON VILOYATI SHAXRIXON TUMANI MULLABOY MFY, AXMAD YASSAVIY KO’CHASI 28-UY | H77: 3 | I77: 2588011.7 | K77: Va'da berdi | bugun hal qiladi | 1643835.6164383562 | 944176.12
A78: АНДИЖОН ВИЛОЯТИ | C78: Обещал | D78: Кр-99062971-1 | E78: ABDULLAYEV O’TKIRBEK MAMASIDIKOVICH | F78: +998932333213 SMS O’ZI, 998507033213 SMS UY, 998931033213 SMS O’G’LI, 998946107010 SMS O’G’LI, | G78: ANDIJON VILOYATI ANDIJON TUMANI CHEM MFY, GULSHAN KO’CHASI 88-UY | H78: 10 | I78: 2448077.5 | K78: Va'da berdi | 25 gacha hal qiladi | 1095890.410958904 | 1352187.12
A79: АНДИЖОН ВИЛОЯТИ | C79: Обещал | D79: Кр-99041191-1 | E79: SHOXINAZAROV ABDULLOH AZIZBEK O’G’LI | F79: +998880662277 SMS O’ZI, 998881005751 SMS ONASI, 998931005751 SMS DADASI, 998970272127 SMS DO’STI MUXAMMADSOLIQ, | G79: Экин тикин МФЙ, Шафтолизор кучаси, 252-уй | H79: 10 | I79: 2283916 | K79: Va'da berdi | bugun erta hal qiladi | 684931.506849315 | 1598984.53
A80: АНДИЖОН ВИЛОЯТИ | C80: Дозвон | D80: Кр-99004621-4 | E80: NADIROV MURODJON BAXRAMJON O’G’LI | F80: 90-543-11-01 SMS, 99-327-66-67 sms танимийди, 90-528-19-14 SMS TANIMASAKAN , 91-175-12-12 SMS ortogi, +998905431101 SMS O’ZI, 998887838780 SMS AKASI, 998946398780 SMS JIYANI ASADBEK, 998977268780 SMS UKASI, | G80: Саноат МФЙ, А.Йулдошев 1 тор кучаси, 37-уй | H80: 10 | I80: 2150272.7 | J80: 410958 | K80: To'ladi | 410958.90410958906 | 1739313.84
A81: АНДИЖОН ВИЛОЯТИ | C81: Обещал | D81: Кр-99038983-2 | E81: REJABOVA GULNOZA MAXAMMADJON QIZI | F81: 998331132300 SMS OZI olmaliqda kambinatda ishlid , 998931632300 SMS AKASI, 998987882323 SMS UKASI, 998944009532 SMS ONASI, | G81: ANDIJON VILOYATI QO’RG’ONTEPA TUMANI DEXQONCHEK MFY SAJDAGOX KO’CHASI 30-UY | H81: 10 | I81: 1986455.7 | K81: Va'da berdi | bugun erta hal qiladi | 364383.5616438356 | 1622072.12
A82: АНДИЖОН ВИЛОЯТИ | C82: Обещал | D82: Кр-99029531-1 | E82: TOLIBJONOVA MAFTUNAXON OYBEK QIZI | F82: 77-039-54-54 SMS OZI, 90-220-91-91 SMS ZALOGADATEL, 94-385-88-88 SMS TOLOVCHI ABDULLOX, 90-542-32-22 SMS UKASI, 998902043130 ozi, 998902004000 SMS TO'LOVCHI, 998905445400 qaynotasi , | G82: ANDIJON VILOYATI ANDIJON TUMANI ISTIQLOL MFY OQ YOR KO’CHASI 163-UY | H82: 3 | I82: 1957283.7 | K82: Va'da berdi | bugun erta hal qiladi | 287671.23287671234 | 1669612.43
...

Sheet Обещали
A1: ← Вернуться в отчёт
A2: Область | B2: Филиал | C2: Группа | D2: Код клиента | E2: Клиент | F2: Номер телефона | G2: Адрес | H2: Кол-во просроченных дней | I2: Итого просрочка | J2: Оплата | K2: Izoh
A3: АНДИЖОН ВИЛОЯТИ | C3: Обещал | D3: Кр-99062885-1 | E3: KASIMXODJAYEV ABDUXALIL ABDUMAJITOVICH | F3: +998916208060 SMS O’ZI, 998914781293 SMS AYOLI, 998916028060 SMS UY, 998976208060 SMS O’ZI2, | G3: ANDIJON VILOYATI ANDIJON SHAHAR MAYDONBOZOR MFY YAXSHI KO’CHASI 61/59-UY | H3: 10 | I3: 14507308 | K3: Va'da berdi | 1-2 kunda hal qiladi | 4383561.643835616 | 10123746.15
A4: АНДИЖОН ВИЛОЯТИ | C4: Обещал | D4: Кр-99058759-1 | E4: RAXMANOV DILSHODBEK TO’XTASINOVICH | F4: 998889930005 SMS OZI, 998955173700 SMS AYOLI, 998979970184 SMS UKASI, 998949300052 SMS OZI 2, | G4: ANDIJON VILOYATI QO’RG’ONTEPA TUMANI DEXQONCHEK MFY ERKIN IJOD KO’CHASI 74-UY | H4: 13 | I4: 13767147 | K4: Va'da berdi | 25 kunga hal qiladi | 5342465.7534246575 | 8424681.47
A5: АНДИЖОН ВИЛОЯТИ | C5: Обещал | D5: Кр-99047889-1 | E5: SHIRMATOV MUXAMMADOZOD QODIRALI O’G’LI | F5: +998911715500 SMS O’ZI, 998772495500 SMS OG’LI, 998972225500 SMS UY, 998998173300 SMS NEVARASI, | G5: ANDIJON VILOYATI ANDIJON SHAHAR ISTIQLOL MFY OBOD 1-TOR KO’CHASI 5-UY | H5: 13 | I5: 12856969 | K5: Va'da berdi | 25 kunga hal qiladi | 4630136.98630137 | 8226832.27
A6: АНДИЖОН ВИЛОЯТИ | C6: Обещал | D6: Кр-99060389-1 | E6: SULTANOVA XAMIDA ULJABEKOVNA | F6: +998934141584 SMS O’ZI, 998973243443 SMS KELINI, 998979753443 SMS O’G’LI, 998993200858 SMS XO’JAYNI, | G6: Andijon viloyati Andijon shahar Sadoqat MFY Fuzuliy ko’chasi 49-uy | H6: 10 | I6: 12724541 | K6: Va'da berdi | dushanba seshanba kuni | 3835616.438356164 | 8888924.39
A7: АНДИЖОН ВИЛОЯТИ | C7: Обещал | D7: Кр-99061048-1 | E7: ORIFJANOV NODIRBEK OMANJANOVICH | F7: 998916841884 uzi, 998335177797 ayoli, 998944870903 onasi, | G7: ANDIJON VILOYATI QO’RG’ONTEPA TUMANI SAVAY YANGI BO’STON MFY BARKAMOL KO’CHASI 58-UY | H7: 13 | I7: 11960620 | K7: Va'da berdi | shu hafta hal qilib berdi | 4273972.602739726 | 7686647.26
A8: АНДИЖОН ВИЛОЯТИ | C8: Обещал | D8: Кр-99061572-1 | E8: AXMEDOV JAVOHIRBEK TOJIDIN O’G’LI | F8: 998907726810 узи, 998910676800 аели, 998882357585 укаси, 998974054333 укаси, | G8: ANDIJON VILOYATI ANDIJON TUMANI NURAFSHON MFY YANGI TURMUSH KO’CHASI 69A-UY | H8: 13 | I8: 11959423 | K8: Va'da berdi | 25 kunga hal qiladi | 4273972.602739726 | 7685450.86
A9: АНДИЖОН ВИЛОЯТИ | C9: Обещал | D9: Кр-99024542-1 | E9: XALMATOV ADIL PAZILOVICH | F9: 77-123-13-10 SMS OZI, 98-707-22-92 SMS OZI, 90-541-13-18 SMS OZI, 998880072292 УГЛИ шохрух, | G9: ANDIJON VILOYATI ANDIJON SHAHAR ISLOMOBOD MFY 7-TOR MUXITDINOV 21-UY | H9: 8 | I9: 11534220 | K9: Va'da berdi | 25 kuni tolaydi | 5041095.890410959 | 6493123.81
A10: АНДИЖОН ВИЛОЯТИ | C10: Обещал | D10: Кр-99063922-3 | E10: RUZIYEVA RANO KABILOVNA | F10: +998905437075 SMS O’ZI, 998902597075 SMS UY, 998906257691 SMS OPASI, 998921519222 SMS QIZI, | G10: ANDIJON VILOYATI ANDIJON SHAHAR O’ZBEGIM MFY, A. MUSAYE KO’CHASI 4-UY 31-XONADON | H10: 10 | I10: 11102362 | K10: Va'da berdi | dushanba kuni tolaydi | 3835616.438356164 | 7266745.79
A11: АНДИЖОН ВИЛОЯТИ | C11: Обещал | D11: Кр-99063424-2 | E11: TURSUNOV RAXMATILLO IKRAMJANOVICH | F11: 998702250075 SMS OZI, 998886020075 SMS UKASI2, 998889248080 SMS AYOLI, 998970711009 SMS UKASI, | G11: ANDIJON VILOYATI QO’RG’ONTEPA TUMANI | H11: 10 | I11: 10783206 | K11: Va'da berdi | 25 kuni tolaydi | 3013698.6301369863 | 7769507.51
A12: АНДИЖОН ВИЛОЯТИ | C12: Обещал | D12: Кр-99033455-2 | E12: ABDULAZIZOV NOZIMJON NASIBJONOVICH | F12: 998934104844 SMS O’ZI, 998000048002 SMS O’ZI 2, 998932544648 SMS AYOLI, 998936913859 SMS XAMKASBI, 998948770475 SMS otasi new , | G12: ANDIJON VILOYATI PAXTAOBOD TUMANI MA’RIFAT MFY,MA’RIFAT KO’CHASI 47-UY | H12: 6 | I12: 10697383 | K12: Va'da berdi | 1-2 kunda hal qiladi | 2465753.4246575343 | 8231629.93
A13: АНДИЖОН ВИЛОЯТИ | C13: Обещал | D13: Кр-99062998-1 | E13: TURDIMAMATOV ERKINJON ABDUMANNABOVICH | F13: +998880040107 SMS O’ZI, 998884772717 SMS O’G’LI, 998914870066 SMS AYOLI, 998941068585 SMS QIZI, | G13: ANDIJON VILOYATI BO’STON TUMANI MADANIYAT MFY, TINCHLIK KO’CHASI 3-UY | H13: 10 | I13: 10186881 | K13: Va'da berdi | dushanba kuni tolaydi | 3287671.2328767125 | 6899210.02
A14: АНДИЖОН ВИЛОЯТИ | C14: Обещал | D14: Кр-99057627-1 | E14: ABDUGANIYEVA MATLUBAXON XXX | F14: 998911757604 SMS OZI, 998902011084 SMS OGLI, 998910611084 SMS KELIMI, 998907620065 SMS QUDASI, | G14: ANDIJON VILOYATI ANDIJON SHAHAR QORATUT MFY 5-KICHIK NOXIYA KO’CHASI 17-UY, 78-XONADON | H14: 13 | I14: 9732853.8 | K14: Va'da berdi | shu hafta hal qilib berdi | 4630136.98630137 | 5102716.8
... A86: АНДИЖОН ВИЛОЯТИ | C86: Обещал | D86: Кр-99038275-3 | E86: KARIMOVA XAMROXON MO’YDINOVNA | F86: 998508831410 SMS OZI, 998948881410 SMS OGLI, 998916012492 SMS KELINI, 998937359892 SMS AKASI, | G86: ANDIJON VILOYATI SHAXRIXON TUMANI YANGIMAXALLA MFY, OBOD KO’CHASI 75/1-UY | H86: 10 | I86: 913144.31 | K86: Va'da berdi | shu hafta hal qiladi | 246575.34246575343 | 666568.97
A87: БУХОРО ВИЛОЯТИ | B87: SUPER BRANCH | C87: Обещал | D87: Кр-99063363-1 | E87: KOMILOVA ZEBO NURIDDINOVNA | F87: 998995031288 OZI, 998773127040 JIYANI, 998998621288 ONASI, 998770900005 DOSTI, | G87: BUXORO VILOYATI QORAKUL TUMANI XOJAKON MFY XUNARMANDLAR KO’CHASI 86-UY | H87: 9 | I87: 9248185.5 | K87: Va'da berdi | 39 | 12614632.016630135
A88: БУХОРО ВИЛОЯТИ | B88: SUPER BRANCH | C88: Обещал | D88: Кр-99033006-2 | E88: AMIRQULOV AZIZBEK FARXOD O’G’LI | F88: 998943206655 SMS O’ZI , 998930065166 SMS AKASI, 998940514494 SMS UKASI, | G88: BUXORO VILOYATI KORAKO’L TUMANI DARG’ALI MFY OQG’UN QISHLOG’I 22-UY | H88: 12 | I88: 2230158.7 | K88: Va'da berdi | 10 | 2423559.9516438358
A89: БУХОРО ВИЛОЯТИ | B89: SUPER BRANCH | C89: Обещал | D89: Кр-99057620-1 | E89: SADRIDDINOV SAVRIDDIN HUSNIDDIN O’G’LI | F89: 998997027515 SMS UZI, 998906367515 SMS OTASI, 998997077515 SMS ONASI, 998918087515 SMS AKASI, | G89: BUXORO VILOYATI VOBKENT TUMANI KO'LXATIB MFY, NAVOIY KO'CHASI, 4-UY | H89: 7 | I89: 1850061.8 | K89: Va'da berdi | 34 | 2387048.071369863
A90: БУХОРО ВИЛОЯТИ | B90: SUPER BRANCH | C90: Обещал | D90: Кр-99033006-3 | E90: AMIRQULOV AZIZBEK FARXOD O’G’LI | F90: 998943206655 SMS O’ZI , 998930065166 SMS AKASI, 998940514494 SMS UKASI, | G90: BUXORO VILOYATI KORAKO’L TUMANI DARG’ALI MFY OQG’UN QISHLOG’I 22-UY | H90: 0 | I90: 1673796.4 | K90: Va'da berdi | 11 | 1673796.38
A91: БУХОРО ВИЛОЯТИ | B91: SUPER BRANCH | C91: Обещал | D91: Кр-99039939-1 | E91: TUXTAYEVA NARGIZA JURAYEVNA | F91: 998918365488 SMS OZI, 998903407973 SMS ONASI, 998331951802 SMS ERI, 998994452534 SMS UY, | G91: BUXORO VILOYATI BUXORO SHAHAR FOSHUN MFY ALPOMISH KO'CHASI, 17/3 UY, 10-XONADON | H91: 7 | I91: 1602703.8 | K91: Va'da berdi | 24 | 2358394.8329041097
A92: БУХОРО ВИЛОЯТИ | B92: SUPER BRANCH | C92: Обещал | D92: Кр-99036367-2 | E92: BEHBUDOV ASLBEK RIZAMATOVICH | F92: +998947812907 SMS O’ZI, 998914462869 SMS OTASI, 998948795777 SMS JIYANI, 998997034797 SMS ONASI, | G92: BUXORO VILOYATI QORAKO’L TUMANI KUYI JANPAR 101-UY | H92: 7 | I92: 1095014.7 | K92: Va'da berdi | 16 | 1460127.68369863
A93: БУХОРО ВИЛОЯТИ | B93: Бухоро филиали | C93: Обещал | D93: Кр-99062884-1 | E93: MADIYEVA ISTAT RAVSHANOVNA | F93: +998997320621 SMS O’ZI, 998505742858 SMS O’G’LI, 998933080621 SMS KELINI, 998943960868 SMS QIZI, | G93: BUXORO VILOYATI JONDOR TUMANI ZARAFSHON MFY ZARAFSHON KO’CHASI 406-UY | H93: 7 | I93: 6933746 | K93: Va'da berdi | 37 | 8771645.565780822
A94: БУХОРО ВИЛОЯТИ | B94: Бухоро филиали | C94: Обещал | D94: Кр-99062677-2 | E94: POCHCHOYEVA ZULAYXO TOLIBJONOVNA | F94: +998932594485 SMS O’ZI, 998952224447 SMS ERI, 998992304600 SMS QAYNONASI, 998995554600 SMS QAYNOTA, 998939564485 узи 2, | G94: BUXORO VILOYAT JONDOR TUMAN IBN SINO MFY ASBOBSOZ KO’CHA 130-UY | H94: 7 | I94: 4279787.4 | K94: Va'da berdi | 35 | 5555825.088054795
A95: БУХОРО ВИЛОЯТИ | B95: Бухоро филиали | C95: Обещал | D95: Кр-99035221-3 | E95: SHUKUROV YUNUS UMAROVICH | F95: 998990297718 SMS O’ZI, 998996751234 SMS AYOLI, 998992231806 SMS QAYNONASI, 998992947718 SMS ONASI, | G95: Хужа Мушкин МФЙ, Алпомиш кучаси, 13/2-уй, 7-хонадон | H95: 7 | I95: 3797288.2 | K95: Va'da berdi | 15 | 4756192.459671233
A96: БУХОРО ВИЛОЯТИ | B96: Бухоро филиали | C96: Обещал | D96: Кр-99027572-1 | E96: TO’YBOYEV BEHRUZ LUQMON O’G’LI | F96: 99-262-34-44 SMS O'ZI хоразимда харбий , 95-571-45-41 SMS XOTINI, 97-452-30-33 SMS DADASI, | G96: BUXORO VILOYATI G’IJDUVON TUMANI POZAGARI MAXALLASI XARCHXONA KUCHASI 133 UY | H96: 11 | I96: 2921973.6 | K96: Va'da berdi | 4 | 3663423.4540547943
A97: БУХОРО ВИЛОЯТИ | B97: Бухоро филиали | C97: Обещал | D97: Кр-99037180-2 | E97: YULDASHEVA DILNOZA FAXRIDINOVNA | F97: 998914076943 SMS OZI, 998907441349 SMS ERI , 998941250707 SMS JIYANI, 998507056161 SMS AMAKISI, +998914076943 SMS O’ZI, | G97: ИСТИКБОЛ МФЙ, ШУРОБОД, 67-УЙ | H97: 5 | I97: 2742706.8 | K97: Va'da berdi | 18 | 3349626.5284931506
A98: БУХОРО ВИЛОЯТИ | B98: Бухоро филиали | C98: Обещал | D98: Кр-99027688-2 | E98: HUSENOV BARNO HASANOVICH | F98: 94-003-53-53 sms O'ZI begana, 93-211-44-49 sms AYOLI, 93-558-53-33 sms O'G'LI, 50-720-12-44 sms QIZI, +998949965353 SMS O’ZI, 998507201244 SMS QIZI, 998932114449 SMS AYOLI, | G98: АРАБХОНА МФЙ, АРАБХОНА, | H98: 7 | I98: 670779.48 | K98: Va'da berdi | 5 | 1302705.5112054795
A99: ЖИЗЗАХ ВИЛОЯТИ | C99: Обещал | D99: Кр-99047637-1 | E99: AZIMOV ASADBEK OTABEK O’G’LI | F99: +998905382222 SMS NOMER, 998971120007 SMS O’ZI, 998991937773 begonA EKAN, | G99: JIZZAX VILOYATI JIZZAX SHAHRI TURON MFY SAYILJOYI KUCHASI 21-UY | H99: 73 | I99: 20202260 | K99: Va'da berdi | filyal keliwi kerak
A100: ЖИЗЗАХ ВИЛОЯТИ | C100: Обещал | D100: Кр-99056937-2 | E100: RASHIDOVA NASIBA YAKUBOVNA | F100: 998889541771 SMS OZI, 998843817712 SMS OZI2, 998974390219 SMS KELINI, | G100: JIZZAX VILOYATI JIZZAX SHAHAR MIRZO ULUG'BEK MAHALLASI 2-UY 10-XONADON | H100: 13 | I100: 8261002.2 | K100: Va'da berdi | kecgaca tolaydi
A101: ЖИЗЗАХ ВИЛОЯТИ | C101: Обещал | D101: Кр-99040635-1 | E101: JURAYEVA ZULAYXA LUTFULLAYEVNA | F101: 998915641958 SMS begona, 998938592525 SMS O`G`LI tolovchisi, 998943543086 SMS O`G`LI 2, 998931940082 SMS O`G`LI 3, 998943174556 SMS ONASI, 998932926008 Tolovchisini xotini, | G101: JIZZAX VILOYATI, DO’STLIK TUMANI, NAVRUZ MFY, IFTIXOR KUCHASI, 11-2 UY | H101: 43 | I101: 8146268.7 | K101: Va'da berdi | bugun tolaydi
A102: ЖИЗЗАХ ВИЛОЯТИ | C102: Обещал | D102: Кр-99036112-1 | E102: O’TASHEV RAVSHAN BOXTIYOR O’G’LI | F102: 998991037766 SMS OZI, 998946525295 SMS AKA TOLOVCHI, 998946738436 SMS AYOLI TOLOVCHI, 998944973835 SMS AYOLI, 998958735995 SMS TOLOVCHI, | G102: JIZZAX VILOYATI MIRZACHUL TUMANI PAXTAZOR SHFY BUNYODKOR KUCHASI 38-UY 2-XONADON | H102: 44 | I102: 6856165.8 | K102: Va'da berdi | mowin olingan
A103: ЖИЗЗАХ ВИЛОЯТИ | C103: Обещал | D103: Кр-99033328-1 | E103: XOLBUTAYEV DILMUROD ABDUMALIKOVICH | F103: 998915680048 SMS O’ZI, 998994280048 SMS UKASI, 998990280048 SMS AYOLI BEGONA, 998900265356 SMS ONASI, | G103: JIZZAX VILOYATI ZOMIN TUMANI DASHTOBOD SHAXAR QORATEPA MFY SHIRIN KUCHASI | H103: 13 | I103: 6506790.9 | K103: Va'da berdi | 5 6 gaca tulaydi
A104: ЖИЗЗАХ ВИЛОЯТИ | C104: Обещал | D104: Кр-99028038-1 | E104: XAZRATKULOVA RAYXON TURSUNBAYEVNA | F104: 998772725500 SMS OZI, 998951307770 SMS UKASI, 998904928594 SMS ZOLOGATEL, | G104: JIZZAX VILOYATI JIZZAX SHAHRI OBOD MFY XALQLAR DUSTLIGI KUCHASI 101-A UY 23-XONADON | H104: 8 | I104: 5917963.6 | K104: Va'da berdi | wu hafta ohirgaca yopadi timur aka bilan gaplawgan ekan
A105: ЖИЗЗАХ ВИЛОЯТИ | C105: Обещал | D105: Кр-99005110-6 | E105: TURSUNOVA MAXBUBA OLIMJON KIZI | F105: 91-567-08-58 sms ukas tolovchi, 99-563-24-48 sms HO’JAYNI, 91-188-00-88 sms UKASI, 90-229-18-51 DADASI , 90-229-18-54 SMS UY, 90-025-93-95 SMS ONASI MAQSUDA, 998882955757 SMS TO’LOVCHI, 998880890111 uzi new, | G105: JIZZAX VILOYATI JIZZAX SHAHAR BUNYODKOR .M.F.Y YORQIN KO’CHASI 16-UY | H105: 14 | I105: 5523834.8 | K105: Va'da berdi | bugun tolaydi kecgaca
A106: ЖИЗЗАХ ВИЛОЯТИ | C106: Обещал | D106: Кр-99038849-1 | E106: XASANOV INOMJON USMONOVICH | F106: 998977931100 SMS SINGLISI, 998916262046 SMS OZI, 998976831100 SMS SINGLISI 2, 998915665348 SMS AYOLI, | G106: ДУСТЛИК, ДУСТЛИК, Э.АШИРМАТОВ, uy:Р/С | H106: 2 | I106: 5384444 | K106: Va'da berdi | kecgaca tolaydi
A107: ЖИЗЗАХ ВИЛОЯТИ | C107: Обещал | D107: Кр-99042115-1 | E107: MIRZAYEV OYBEK SUNATILLAYEVICH | F107: +998902659695 SMS, 998915909006 SMS, 998974559695 SMS, | G107: JIZZAX VILOYATI SH.RASHIDOV TUMANI TOKCHILIK MFY ZARGARLIK KUCHASI 2-UY | H107: 10 | I107: 4457135.3 | K107: Va'da berdi | ertaga aniq yopad kecgaca
A108: ЖИЗЗАХ ВИЛОЯТИ | C108: Обещал | D108: Кр-99063504-1 | E108: MIRZAYEVA LOBARXON ERGASHEVNA | F108: 998933556974 UZI, 998934026974 ERI, 998958832266 TO’LOVCHI, | G108: ТОШКЕСГАН КФЙ, ЛОЙИХАДАГИ КЎЧА, uy:РАКАМСИЗ | H108: 10 | I108: 4425062.2 | K108: Va'da berdi | duwanba tulaydi
A109: ЖИЗЗАХ ВИЛОЯТИ | C109: Обещал | D109: Кр-99057340-1 | E109: SUYUNOVA UMIDA ILHOM QIZI | F109: 998995542023 SMS ERI, 998930913798 SMS UZI, 998943461045 SMS UY, 998901020807 SMS Akasi, | G109: JIZZAX VILOYATI MIRZACHO'L TUMANI IPAK YULI QFY YANGI XAYOT KUCHASI 29-UY | H109: 10 | I109: 3800442.9 | K109: Va'da berdi | 12da tel qiliw kerak
A110: ЖИЗЗАХ ВИЛОЯТИ | C110: Обещал | D110: Кр-99011601-4 | E110: JO’RAQULOV JAVLONJON QAHRAMON O’G’LI | F110: 88-126-00-25 SMS UZI, 97-482-53-53 SMS AYOLI, 88-437-53-53 SMS OTASI, 97-127-53-53 SMS AYOLI, 998776406865 SMS Ukasi tolovchi, | G110: JIZZAX VILOYATI JIZZAX TUMANI OLMACHI MAHALLASI OLMACHI KUCHASI 9/9 UY | H110: 14 | I110: 3593058.5 | K110: Va'da berdi | kecga iwdan ciqib filyalga oborb beradi
... A182: КОРАКАЛПОГИСТОН РЕСПУБЛИКАСИ | C182: Обещал | D182: Кр-99019952-8 | E182: URAZIMBETOVA SHOHISTA GULIMBAYEVNA | F182: 99-186-59-19 SMS UZI, 998995033939 SMS ERI, 998940910907 SMS UZI, 998771152010 OGLI, | G182: QORAQALPOG’ISTON RESPUBLIKASI BERUNIY TUMANI BERUNIY OFY GULZOR KO’CHA | H182: 14 | I182: 736259.75 | K182: Va'da berdi | SMS YOZDIM | 86
...

Sheet Оплатили
A1: ← Вернуться в отчёт
A2: Область | B2: Филиал | C2: Группа | D2: Код клиента | E2: Клиент | F2: Номер телефона | G2: Адрес | H2: Кол-во просроченных дней | I2: Итого просрочка | J2: Оплата | K2: Izoh
A3: АНДИЖОН ВИЛОЯТИ | C3: Объезд | D3: Кр-99057085-1 | E3: YULDASHEVA NILUFAR KAMILOVNA | F3: 998872557757 SMS OZI, 998982700122 SMS OGLI, 998772581112 SMS QIZI, 998882331807 SMS JIYANI, | G3: ANDIJON VILOYATI ANDIJON TUMANI ZANGIBOBO MFY PORLOQ KO’CHASI 306-UY | H3: 13 | I3: 15030583 | J3: 5342465 | K3: Uyiga borildi - to'ladi | 5342465.7534246575 | 9688117.5
A4: АНДИЖОН ВИЛОЯТИ | C4: Дозвон | D4: Кр-99039306-1 | E4: ODILJONOV ABDULAZIZ UMIDJON O’G’LI | F4: 998934153932 SMS OZI, 998937810042 SMS ONASI, 998937810094 SMS OTASI, 998941051030 SMS AKASI, | G4: ANDIJON VILOYATI ANDIJON SHAHAR DALVARZIN MFY A.ASHUROV 3-TOR KO’CHASI 4-UY | H4: 14 | I4: 10688765 | J4: 3835616 | K4: To'ladi | 3835616.4383561644 | 6853149.05
A5: АНДИЖОН ВИЛОЯТИ | C5: Дозвон | D5: Кр-99039609-1 | E5: TOJIDINOVA MUXARRAMXON KOBULOVNA | F5: 998940331487 SMS OZI, 998950978615 SMS XOJAYINI, 998903870911 SMS OGLI, 998934168183 SMS AKASI, | G5: ANDIJON VILOYATI MARXAMAT TUMANI MIRISHKOLAR MFY, DORBOZ KO’CHASI 45-UY | H5: 3 | I5: 3360170 | J5: 410958 | K5: To'ladi | 410958.90410958906 | 2949211.13
